Workbook

Sheet DASHBOARD_KIEMDO
A1: DASHBOARD KIỂM DÒ ĐỐI SOÁT THUẾ GTGT - CÔNG TY ĐIỆN LỰC VŨNG TÀU
A2: Kỳ tính thuế: Tháng 09/2026 | Hệ Thống Tự Động Đồng Bộ & Đối Soát Dữ Liệu ERP
A4: THUẾ ĐẦU VÀO KHẤU TRỪ [25] | C4: THUẾ ĐẦU RA PHÁT SINH [28] | E4: THUẾ PHẢI NỘP / KHẤU TRỪ [36] | G4: TRẠNG THÁI KIỂM DÒ TỔNG THỂ
A5: ='TAXVTA'!F63 | C5: ='TAXVTA'!L63 | E5: ='TAXVTA'!F70 | G5: =IF(AND('TAXVTA'!K6=0,'TAXVTA'!C21=0,'TAXVTA'!G21=0,'TAXVTA'!K21=0,'TAXVTA'!C24=0,'TAXVTA'!G24=0,'TAXVTA'!K24=0,'TAXVTA'!K34=0),"KHỚP DỮ LIỆU (PASS)","LỆCH SỐ LIỆU (CẦN KIỂM TRA)")
A7: =IF('TAXVTA'!K74=60549888887, "✅ SỐ DƯ NỢ SPC CỐ ĐỊNH: 60.549.888.887 Đ (KHỚP CHUẨN - KHÔNG ĐƯỢC SAI LỆCH)", "🚨 CẢNH BÁO: SAI LỆCH SỐ DƯ NỢ SPC CỦA ĐƠN VỊ CŨ (YÊU CẦU CỐ ĐỊNH: 60.549.888.887 Đ)!")
A9: KHỐI 2: ĐỐI SOÁT DOANH SỐ & THUẾ ĐẦU VÀO (BẢNG KÊ TA36 vs SỔ CÁI 13311)
A10: STT | B10: Mã TK | C10: Nội Dung Diễn Giải | D10: Doanh Số TA36 | E10: Tiền Thuế TA36 | F10: Tiền Thuế Sổ Cái (13311) | G10: Chênh Lệch (TA36 - Sổ Cái) | H10: Trạng Thái
A11: 1 | B11: 13311 | C11: Thuế GTGT HHDV dùng chung SXKD | D11: ='TAXVTA'!D4 | E11: ='TAXVTA'!F4 | F11: ='TAXVTA'!J4 | G11: =E11-F11 | H11: =IF(G11=0,"OK","LỆCH")
A12: 2 | B12: 13313 | C12: Thuế GTGT hàng hóa TSCĐ / XDCB | D12: ='TAXVTA'!D5 | E12: ='TAXVTA'!F5 | F12: ='TAXVTA'!J5 | G12: =E12-F12 | H12: =IF(G12=0,"OK","LỆCH")
A13: Cộng | C13: TỔNG CỘNG ĐẦU VÀO | D13: =SUM(D11:D12) | E13: =SUM(E11:E12) | F13: =SUM(F11:F12) | G13: =SUM(G11:G12) | H13: =IF(G13=0,"OK","LỆCH")
A15: KHỐI 3: ĐỐI SOÁT DOANH SỐ & THUẾ ĐẦU RA (BẢNG KÊ TA35 vs SỔ CÁI 3331)
A16: STT | B16: Mã TK | C16: Nội Dung Diễn Giải | D16: Doanh Số TA35 | E16: Tiền Thuế TA35 | F16: Tiền Thuế Sổ Cái (3331) | G16: Chênh Lệch (TA35 - Sổ Cái) | H16: Trạng Thái
A17: 1 | B17: 333111 | C17: Thuế GTGT tiền điện & CSPK | D17: ='TAXVTA'!J4+'TAXVTA'!J6+'TAXVTA'!J7 | E17: ='TAXVTA'!L4+'TAXVTA'!L6+'TAXVTA'!L7 | F17: ='333111'!E29 | G17: =E17-F17 | H17: =IF(ABS(G17)<50000,"OK","LỆCH")
A18: 2 | B18: 333113 | C18: Thuế GTGT điều động VTTB (1388ĐĐ) | D18: ='TAXVTA'!J8 | E18: ='TAXVTA'!L8 | F18: ='333111'!E42 | G18: =E18-F18 | H18: =IF(ABS(G18)<50000,"OK","LỆCH")
A19: 3 | B19: 333114 | C19: Thuế GTGT cho thuê cột điện treo cáp (4500TT) | D19: ='TAXVTA'!J9 | E19: ='TAXVTA'!L9 | F19: ='333111'!E51 | G19: =E19-F19 | H19: =IF(ABS(G19)<50000,"OK","LỆCH")
A20: Cộng | C20: TỔNG CỘNG ĐẦU RA | D20: =SUM(D17:D19) | E20: =SUM(E17:E19) | F20: =SUM(F17:F19) | G20: =SUM(G17:G19) | H20: =IF(ABS(G20)<50000,"OK","LỆCH")
A22: KHỐI 4: MA TRẬN KIỂM DÒ DOANH THU ĐẦU RA 3 CHIỀU (GCS vs BÁO CÁO 4A vs SỔ GL 0903)
A23: Hạng Mục Doanh Thu | B23: Mã DFF | C23: Doanh Số GCS | D23: Doanh Số 4A | E23: Doanh Số GL 0903 | F23: Lệch (GCS - 4A) | G23: Lệch (4A - GL0903) | H23: Đánh Giá
A24: Tiền điện sinh hoạt & SX | B24: DIEN01 | C24: ='TAXVTA'!C19 | D24: ='TAXVTA'!C20 | E24: ='TAXVTA'!C23 | F24: =C24-D24 | G24: =D24-E24 | H24: =IF(AND(F24=0,G24=0),"KHỚP","LỆCH")
A25: Công suất phản kháng | B25: CSPK02 | C25: ='TAXVTA'!G19 | D25: ='TAXVTA'!G20 | E25: ='TAXVTA'!G23 | F25: =C25-D25 | G25: =D25-E25 | H25: =IF(AND(F25=0,G25=0),"KHỚP","LỆCH")
A26: Tiền điện thu khác (Nhôm TC) | B26: DIEN00 | C26: ='TAXVTA'!K19 | D26: ='TAXVTA'!K20 | E26: ='TAXVTA'!K23 | F26: =C26-D26 | G26: =D26-E26 | H26: =IF(AND(F26=0,G26=0),"KHỚP","LỆCH")
A27: TỔNG CỘNG ĐẦU RA | C27: =SUM(C24:C26) | D27: =SUM(D24:D26) | E27: =SUM(E24:E26) | F27: =SUM(F24:F26) | G27: =SUM(G24:G26) | H27: =IF(AND(F27=0,G27=0),"KHỚP","LỆCH")

Sheet TAXVTA
A1: THUẾ ĐẦU VÀO
K2: C/LECH
A3: TA36 | C3: Tài khoản | D3: Doanh số | E3: thuế suất | F3: Tiền thuế | G3: Sau thuế | I3: TA30 | J3: Tiền thuế | K3: TA36-TA30
A4: TA36 | C4: 13311 | D4: =SUMIF('TA36'!$V:$V,TAXVTA!C4,'TA36'!$H:$H) | F4: =SUMIF('TA36'!$V:$V,TAXVTA!C4,'TA36'!$J:$J) | G4: =+D4+F4 | I4: TA30 | J4: ='13311'!L2 | K4: =+F4-J4
A5: TA36 | C5: 13313 | D5: =SUMIF('TA36'!$V:$V,TAXVTA!C5,'TA36'!$H:$H) | F5: =SUMIF('TA36'!$V:$V,TAXVTA!C5,'TA36'!$J:$J) | G5: =+D5+F5 | I5: TA30 | J5: ='13311'!L3 | K5: =+F5-J5
D6: =SUM(D4:D5) | F6: =SUM(F4:F5) | G6: =SUM(G4:G5) | J6: =SUM(J4:J5) | K6: =SUM(K4:K5)
C8: thuế đầu vào lên tờ khai | D8: Doanh số | E8: thuế suất | F8: Tiền thuế | G8: Sau thuế | O8: Tên hàng hóa, dịch vụ | P8: Giá trị hàng hóa, dịch vụ mua vào chưa có thuế GTGT được khấu trừ trong kỳ | Q8: Thuế GTGT của hàng hóa, dịch vụ mua vào được khấu trừ trong kỳ
D9: =SUMIFS('TA36'!$H:$H,'TA36'!$I:$I,TAXVTA!$E9) | E9: 5 | F9: =SUMIFS('TA36'!$J:$J,'TA36'!$I:$I,TAXVTA!$E$9) | G9: =D9+F9 | O9: Hàng hóa dịnh vụ mua vào áp thuế suất 8% | P9: =D10 | Q9: =F10
D10: =SUMIFS('TA36'!$H:$H,'TA36'!$I:$I,TAXVTA!$E10) | E10: 8 | F10: =SUMIFS('TA36'!$J:$J,'TA36'!$I:$I,TAXVTA!$E10) | G10: =D10+F10
D11: =SUMIFS('TA36'!$H:$H,'TA36'!$I:$I,TAXVTA!$E11) | E11: 10 | F11: =SUMIFS('TA36'!$J:$J,'TA36'!$I:$I,TAXVTA!$E11) | G11: =D11+F11
D12: =SUM(D9:D11) | F12: =SUM(F9:F11) | G12: =SUM(G9:G11)
D13: ='TA36'!X15 | F13: ='TA36'!Y15
A14: THUẾ,ĐẦU,RA | D14: =+D12-D13 | F14: =+F12-F13
C15: DIEN01 | D15: DIEN01 | E15: DIEN01 | F15: DIEN01 | G15: CSPK02 | H15: CSPK02 | I15: CSPK02 | J15: CSPK02 | K15: DIEN00 | L15: DIEN00 | M15: DIEN00 | N15: DIEN00 | O15: CỘNG | P15: CỘNG | Q15: CỘNG | R15: CỘNG
C16: Doanh,số | D16: thuế,suất | E16: Tiền,thuế | F16: Sau,thuế | G16: Doanh,số | H16: thuế,suất | I16: Tiền,thuế | J16: Sau,thuế | K16: Doanh,số | L16: thuế,suất | M16: Tiền,thuế | N16: Sau,thuế | O16: Doanh,số | P16: thuế,suất | Q16: Tiền,thuế | R16: Sau,thuế
A17: KDGCS | B17: TRONGTHANG | C17: =GCS!H38 | E17: =GCS!I38 | F17: =GCS!J38 | G17: =+GCS!K33 | I17: =GCS!L33 | J17: =GCS!M33 | K17: =GCS!H39 | M17: 0 | N17: =GCS!J39 | O17: =C17+G17+K17 | Q17: =+E17+I17 | R17: =+O17+Q17
A18: KDGCS | B18: CUOITHANG | C18: =+GCS!H45 | E18: =+GCS!I45 | F18: =GCS!J45 | G18: =+GCS!K34 | I18: =GCS!L34 | J18: =GCS!M34 | K18: =GCS!H46 | N18: =GCS!J46 | O18: =+C18+G18+K18 | Q18: =+E18+I18 | R18: =+O18+Q18
C19: =SUM(C17:C18) | E19: =SUM(E17:E18) | F19: =SUM(F17:F18) | G19: =SUM(G17:G18) | I19: =SUM(I17:I18) | J19: =SUM(J17:J18) | K19: =SUM(K17:K18) | L19: =SUM(L17:L18) | M19: =SUM(M17:M18) | N19: =SUM(N17:N18) | O19: =SUM(O17:O18) | Q19: =SUM(Q17:Q18) | R19: =SUM(R17:R18)
A20: KD4A | C20: ='4A'!D13 | E20: ='4A'!E13 | F20: ='4A'!F13 | G20: =+'4A'!D9 | I20: =+'4A'!E9 | J20: =+'4A'!F9 | K20: ='4A'!D12 | M20: =+'4A'!I9 | N20: ='4A'!F12 | O20: =C20+G20+K20 | Q20: =+E20+I20 | R20: =O20+Q20
A21: c/lech | B21: GCS-4A | C21: =+C19-C20 | D21: =+D19-D20 | E21: =+E19-E20 | F21: =+F19-F20 | G21: =+G19-G20 | H21: =+H19-H20 | I21: =+I19-I20 | J21: =+J19-J20 | ... R21: =+R19-R20
A23: GL0903 | C23: ='0903'!X3 | G23: ='0903'!X4+'0903'!X1 | K23: ='0903'!X2 | O23: =SUM(C23:N23)
A24: c/lech | B24: KD4A-GL0903 | C24: =+C20-C23 | G24: =+G20-G23 | K24: =+K20-K23 | O24: =+O20-O23
A26: TA35 | D26: TA_035 | F26: GCS T8-2026 sang T9/26 HT | H26: GCS T6-2026 | J26: Chênh lệch
D27: Doanh số | E27: Tiền thuế | F27: Doanh số | G27: Tiền thuế | H27: Doanh số | I27: Tiền thuế | J27: Doanh số | K27: Tiền thuế
C28: DIEN00 | D28: =SUMIFS('TA35'!$H:$H,'TA35'!$T:$T,TAXVTA!$C28) | E28: =SUMIFS('TA35'!$J:$J,'TA35'!$T:$T,TAXVTA!$C28) | F28: 95198300 | H28: =GCS!H39 | J28: =D28-F28-H28 | K28: =E28-G28-I28
C29: DIEN01 | D29: =SUMIFS('TA35'!$H:$H,'TA35'!$T:$T,TAXVTA!$C29) | E29: =SUMIFS('TA35'!$J:$J,'TA35'!$T:$T,TAXVTA!$C29) | F29: 693017465643 | G29: ='33895'!M2 | H29: =GCS!H38 | I29: =GCS!I38 | J29: =D29-F29-H29 | K29: =E29-G29-I29
C30: CSPK02 | D30: =SUMIFS('TA35'!$H:$H,'TA35'!$T:$T,TAXVTA!$C30)+'TA35'!W5 | E30: =SUMIFS('TA35'!$J:$J,'TA35'!$T:$T,TAXVTA!$C30) | F30: 538950224 | G30: ='33895'!M3 | H30: =GCS!L40 | I30: =GCS!M38 | J30: =D30-F30-H30 | K30: =E30-G30-I30
C31: 1388ĐĐ | D31: =SUMIFS('TA35'!$H:$H,'TA35'!$T:$T,TAXVTA!$C31) | E31: =SUMIFS('TA35'!$J:$J,'TA35'!$T:$T,TAXVTA!$C31)
C32: 5118QT | D32: =SUMIFS('TA35'!$H:$H,'TA35'!$T:$T,TAXVTA!$C32) | E32: =SUMIFS('TA35'!$J:$J,'TA35'!$T:$T,TAXVTA!$C32)
C33: 4500TT | D33: =SUMIFS('TA35'!$H:$H,'TA35'!$T:$T,TAXVTA!$C33) | E33: =SUMIFS('TA35'!$J:$J,'TA35'!$T:$T,TAXVTA!$C33)
C34: Cộng | D34: =SUM(D28:D33) | E34: =SUM(E28:E33) | F34: =SUM(F28:F33) | G34: =SUM(G28:G33) | H34: =SUM(H28:H33) | I34: =SUM(I28:I33) | J34: =SUM(J28:J33) | K34: =SUM(K28:K33)
A36: GL33895 (GL_038) | E36: =SUMIFS('33895'!$K:$K,'33895'!$J:$J,TAXVTA!C$15) | I36: =SUMIFS('33895'!$K:$K,'33895'!$J:$J,TAXVTA!G$15) | Q36: =+E36+I36
A37: c/lech | B37: KDGCS-GL33895 | E37: =+E18-E36 | I37: =+I18-I36 | Q37: =+Q18-Q36
D38: Doanh số | E38: Tiền thuế
A39: TA030 | B39: TK333111 | D39: ='333111'!M2 | E39: =+'333111'!M7
A40: c/lech | B40: KDGCS-TA30 | D40: =E17-D39 | E40: =D40+G29
A41: c/lech | B41: TA35-TA30 | D41: =E29-G29-D39
O43: Tên hàng hóa, dịch vụ | P43: Giá trị hàng hóa, dịch vụ chưa có thuế GTGT | Q43: Thuế GTGT của hàng hóa, dịch vụ bán ra được giảm
B44: Thuế đầu ra lên tờ khai | C44: Doanh,số | D44: thuế,suất | E44: Tiền,thuế | F44: Sau,thuế | M44: NHẬP LÊN TỜ KHÁI THUẾ THÁNG | O44: Hoạt động kinh doanh điện | P44: =C46+C48 | Q44: =E46+E48
A45: Điện | B45: DIEN00 | C45: =SUMIFS('TA35'!$H:$H,'TA35'!$T:$T,TAXVTA!B45,'TA35'!$I:$I,TAXVTA!D45) | D45: 0 | E45: =SUMIFS('TA35'!$J:$J,'TA35'!$T:$T,TAXVTA!B45,'TA35'!$I:$I,TAXVTA!D45) | F45: =C45+E45 | K45: 91678635810 | O45: Điều động vật tư thiết bị | P45: =C49 | Q45: =E49
...

Sheet GCS
A2: TỔNG CÔNG TY ĐIỆN LỰC THÀNH PHỐ HỒ CHÍ MINH TNHH
A3: CÔNG TY ĐIỆN LỰC VŨNG TÀU
A5: BÁO CÁO TỔNG HỢP THEO NGÀY GHI CHỈ SỐ VÀ PHÁT HÀNH HÓA ĐƠN
A6: Tháng năm: 09/2026
A8: Stt | B8: Ngày ghi | C8: Số sổ GCS | D8: Số hóa đơn | E8: Ngày phát hành hóa đơn | F8: Điện năng tiêu thụ | I8: Tiền điện tác dụng | J8: Thuế điện tác dụng | K8: Tổng tiền điện tác dụng | L8: Tiền CSPK | M8: Thuế CSPK | N8: Tổng tiền CSPK | O8: Tổng cộng
F9: SH | G9: Ngoài SH | H9: Tổng
A10: Loại hoá đơn : Hủy bỏ
A11: 1 | B11: 30/09/2026 | C11: 8 | D11: 9 | E11: 46295 | F11: -8593 | G11: -18326 | H11: -26919 | I11: -90228084 | J11: -7218247 | K11: -97446331 | L11: -896068 | M11: -71685 | N11: -967753 | O11: -98414084 | P11: TRONGTHANG
A12: Tổng số | C12: 8 | D12: 9 | F12: -8593 | G12: -18326 | H12: -26919 | I12: -90228084 | J12: -7218247 | K12: -97446331 | L12: -896068 | M12: -71685 | N12: -967753 | O12: -98414084
A13: Loại hoá đơn : Lặp lại
A14: 2 | B14: 30/09/2026 | C14: 8 | D14: 9 | E14: 46295 | F14: 1812 | G14: 13634 | H14: 15446 | I14: 54987416 | J14: 4398992 | K14: 59386408 | L14: 0 | M14: 0 | N14: 0 | O14: 59386408 | P14: TRONGTHANG
A15: Tổng số: | C15: 8 | D15: 9 | F15: 1812 | G15: 13634 | H15: 15446 | I15: 54987416 | J15: 4398992 | K15: 59386408 | L15: 0 | M15: 0 | N15: 0 | O15: 59386408
A16: Loại hoá đơn : Phát sinh
A17: 3 | B17: 10/09/2026 | C17: 21 | D17: 450 | E17: 46276 | F17: 1677 | G17: 158599806 | H17: 158601483 | I17: 305939385736 | J17: 24466693819 | K17: 330406079555 | L17: 188521298 | M17: 15081702 | N17: 203603000 | O17: 330609682555 | P17: TRONGTHANG
A18: 4 | B18: 15/09/2026 | C18: 9 | D18: 190 | E18: 46281 | F18: 9285 | G18: 4567698 | H18: 4576983 | I18: 11196063409 | J18: 895685075 | K18: 12091748484 | L18: 47189941 | M18: 3775196 | N18: 50965137 | O18: 12142713621 | P18: TRONGTHANG
A19: 5 | B19: 20/09/2026 | C19: 21 | D19: 456 | E19: 46286 | F19: 1382 | G19: 179974564 | H19: 179975946 | I19: 340503392283 | J19: 27232232700 | K19: 367735624983 | L19: 122527217 | M19: 9802181 | N19: 132329398 | O19: 367867954381 | P19: TRONGTHANG
A20: 6 | B20: 30/09/2026 | C20: 2030 | D20: 237539 | E20: 46297 | F20: 77607796 | G20: 224896711 | H20: 302504507 | I20: 678922434286 | J20: 54304559408 | K20: 733226993694 | L20: 556214881 | M20: 44497199 | N20: 600712080 | O20: 733827705774 | P20: CUOITHANG
A21: Tổng số: | C21: 2081 | D21: 238635 | F21: 77620140 | G21: 568038779 | H21: 645658919 | I21: 1336561275714 | J21: 106899171002 | K21: 1443460446716 | L21: 914453337 | M21: 73156278 | N21: 987609615 | O21: 1444448056331
A22: Loại hoá đơn : Thoái hoàn
A23: 7 | B23: 30/09/2026 | C23: 6 | D23: 6 | E23: 46295 | F23: -3191 | G23: -800 | H23: -3991 | I23: -12575260 | J23: -1006021 | K23: -13581281 | L23: 0 | M23: 0 | N23: 0 | O23: -13581281 | P23: TRONGTHANG
A24: Tổng số: | C24: 6 | D24: 6 | F24: -3191 | G24: -800 | H24: -3991 | I24: -12575260 | J24: -1006021 | K24: -13581281 | L24: 0 | M24: 0 | N24: 0 | O24: -13581281
A25: Loại hoá đơn : Truy thu
A26: 8 | B26: 10/09/2026 | C26: 3 | D26: 6 | E26: 46276 | F26: 0 | G26: 35252 | H26: 35252 | I26: 82523432 | J26: 6601875 | K26: 89125307 | L26: 0 | M26: 0 | N26: 0 | O26: 89125307 | P26: TRONGTHANG
A27: 9 | B27: 15/09/2026 | C27: 1 | D27: 1 | E27: 46281 | F27: 0 | G27: 0 | H27: 0 | I27: 0 | J27: 0 | K27: 0 | L27: 0 | M27: 0 | N27: 0 | O27: 0 | P27: TRONGTHANG
A28: 10 | C28: 17 | D28: 24 | E28: 46297 | F28: 20532 | G28: 102389 | H28: 122921 | I28: 414704832 | J28: 33176388 | K28: 447881220 | L28: 0 | M28: 0 | N28: 0 | O28: 447881220 | P28: CUOITHANG
A29: Tổng số: | C29: 21 | D29: 31 | F29: 20532 | G29: 137641 | H29: 158173 | I29: 497228264 | J29: 39778263 | K29: 537006527 | L29: 0 | M29: 0 | N29: 0 | O29: 537006527
H31: TIENDIEN | I31: THUE DIEN | J31: TONG | K31: CSPK | L31: THUE CSPK | M31: TONG CSPK
G33: TRONGTHANG | H33: =SUMIF($P:$P,G33,$I:$I) | I33: =SUMIF($P:$P,G33,$J:$J) | J33: =SUMIF($P:$P,G33,$K:$K) | K33: =SUMIF($P:$P,G33,$L:$L) | L33: =SUMIF($P:$P,G33,$M:$M) | M33: =SUMIF($P:$P,G33,$N:$N) | N33: =SUMIF($P:$P,G33,$O:$O)
G34: CUOITHANG | H34: =SUMIF($P:$P,G34,$I:$I) | I34: =SUMIF($P:$P,G34,$J:$J) | J34: =SUMIF($P:$P,G34,$K:$K) | K34: =SUMIF($P:$P,G34,$L:$L) | L34: =SUMIF($P:$P,G34,$M:$M) | M34: =SUMIF($P:$P,G34,$N:$N) | N34: =SUMIF($P:$P,G34,$O:$O)
H35: =SUM(H33:H34) | I35: =SUM(I33:I34) | J35: =SUM(J33:J34) | K35: =SUM(K33:K34) | L35: =SUM(L33:L34) | M35: =SUM(M33:M34) | N35: =SUM(N33:N34)
H36: =H35-D54-D56 | I36: =I35-E54 | J36: =J35-F54-F56 | K36: =K35-D55 | L36: =L35-E55 | M36: =M35-F55 | N36: =N35-F58
E37: Trong đó | F37: TRONGTHANG
G38: DIEN01 | H38: =H33-H39 | I38: =I33-I39 | J38: =J33-J39 | L38: =K33-L39 | M38: =L33 | N38: =L38+M38 | O38: CSPK02
G39: DIEN00 | H39: ='Nhom TC'!O1 | I39: 0 | J39: =H39+I39 | M39: 0 | N39: =L39+M39 | O39: CSPK00
H40: =SUM(H38:H39) | I40: =SUM(I38:I39) | J40: =SUM(J38:J39) | L40: =SUM(L38:L39) | M40: =SUM(M38:M39) | N40: =L40+M40
H41: =H33-H40 | I41: =I33-I40 | J41: =J33-J40
G42: CSPK02 | K42: =K33 | L42: =L33 | M42: =M33 | N42: =N33
H43: =+H40+H42-H33 | I43: =+I40+I42-I33 | J43: =+J40+J42-J33 | K43: =+K40+K42-K33 | L43: =+L40+L42-L33 | M43: =+M40+M42-M33 | N43: =+N40+N42-N33
F44: CUOITHANG
G45: DIEN01 | H45: =H34-H46 | I45: =I34 | J45: =J34-J46
...

Sheet 0903
A1: HCMC - Công ty Điện lực Vũng Tàu | W1: CSPK00 | X1: =SUMIF($V:$V,$W1,$O:$O)
W2: DIEN00 | X2: =SUMIF($V:$V,$W2,$O:$O)
A3: Báo cáo liệt kê giao dịch phát sinh theo tài khoản | W3: DIEN01 | X3: =SUMIF($V:$V,$W3,$O:$O)
A4: Từ ngày 01/09/2026 đến ngày 30/09/2026 | W4: CSPK02 | X4: =SUMIF($V:$V,$W4,$O:$O)
W5: 1388DD | X5: =SUMIF($V:$V,$W5,$O:$O) | Y5: vật tư điều động
A6: Nguồn phát sinh | B6: Số giao dịch | C6: Ngày giao dịch | D6: Chi nhánh | E6: Trung tâm chi phí | F6: Tài khoản | G6: Loại hình | H6: Sản phẩm | I6: Yếu tố | J6: Đơn vị nội bộ | K6: Dự phòng đơn vị | L6: Dự phòng EVN | M6: Loại tiền | N6: Nợ nguyên tệ | O6: Có nguyên tệ | P6: Nợ quy đổi | Q6: Có quy đổi | R6: Nội dung | S6: Trạng thái hạch toán | T6: Người tạo | U6: Người cập nhật | W6: 5118QT | X6: =SUMIF($V:$V,$W6,$O:$O) | Y6: quà tặng
A7: GL | B7: 3188 | C7: 46295 | D7: 0 | E7: 0 | F7: 51511110000 | G7: 0 | H7: 0 | I7: 999 | J7: 0 | K7: 0 | L7: 0 | M7: VND | O7: 30437 | Q7: 30437 | R7: K/c 51511 > 911511 (LÃI TIỀN CHO VAY) | S7: P | T7: DUYENTT.HCM.VTA | U7: DUYENTT.HCM.VTA | V7: =LEFT(R7,6) | W7: 4500TT | X7: =SUMIF($V:$V,$W7,$O:$O) | Y7: dường dây thông tin
A8: GL | B8: 3103 | C8: 46295 | D8: 0 | E8: 0 | F8: 51511110000 | G8: 0 | H8: 0 | I8: 999 | J8: 0 | K8: 0 | L8: 0 | M8: VND | N8: 30437 | P8: 30437 | R8: K/c 51511 > 911511 (LÃI TIỀN CHO VAY) | S8: P | T8: DUYENTT.HCM.VTA | U8: DUYENTT.HCM.VTA | V8: =LEFT(R8,6) | X8: =SUM(X2:X7)
A9: GL | B9: 3181 | C9: 46295 | D9: 0 | E9: 0 | F9: 51511110000 | G9: 1310 | H9: 0 | I9: 0 | J9: 0 | K9: 0 | L9: 0 | M9: VND | O9: -30437 | Q9: -30437 | R9: Điều chỉnh hạch toán TK theo G0926VC0011-25/9/26 | S9: P | T9: HUENT.HCM.VTA | U9: DUYENTT.HCM.VTA | V9: =LEFT(R9,6)
A10: AR_RECEIPTS | B10: G0926VC0011 | C10: 46290 | D10: 0 | E10: 0 | F10: 51511110000 | G10: 1310 | H10: 0 | I10: 0 | J10: 0 | K10: 0 | L10: 0 | M10: VND | O10: 30437 | Q10: 30437 | R10: Nhập lãi TK NH VCB T9/26 | S10: F | T10: HUENT.HCM.VTA | U10: HUENT.HCM.VTA | V10: =LEFT(R10,6)

Sheet 3A

Sheet 4A
A1: MADONVI | B1: TENDONVI | C1: TONGDTP | D1: TIENDIEN | E1: TIENCSPK | F1: THUE_TD | G1: THUE_CSPK | H1: TONGDTPKH | I1: TIENDIENKH | J1: GIABQKH
A2: PE1800 | B2: Công ty Điện lực Vũng Tàu | C2: 645801628 | D2: 1337010688050 | E2: 913557269 | F2: 106935123989 | G2: 73084593 | H2: 7416000000 | I2: 0 | J2: 2066
C3: =VALUE(C2) | D3: =VALUE(D2) | E3: =VALUE(E2) | F3: =VALUE(F2) | G3: =VALUE(G2) | H3: =VALUE(H2) | I3: =VALUE(I2) | J3: =VALUE(J2)
D7: trước thuế | E7: thuế | F7: sau thuế
A8: Điện | B8: DIEN01 | D8: =D3 | E8: =F3 | F8: =+D8+E8 | G8: =D8*8% | H8: =E8-G8
A9: CSPK | B9: CSPK02 | D9: =E3 | E9: =G3 | F9: =+D9+E9 | G9: =D9*8% | H9: =E9-G9
D10: =SUM(D8:D9) | E10: =SUM(E8:E9) | F10: =SUM(F8:F9)
A12: Trong DIEN01 có | B12: DIEN00 | D12: ='Nhom TC'!O4 | E12: 0 | F12: =D12+E12
B13: DIEN01 | D13: =D8-D12 | E13: =E8-E12 | F13: =F8-F12 | G13: =D13*8% | H13: =E13-G13
A16: Trong DIEN01 có | B16: CSPK02 | D16: =E2-D17
B17: CSPK00 | D17: ='Nhom TC'!O5
A20: GL_0903 | B20: DIEN01 | D20: ='0903'!X3 | E20: =D13-D20
B21: CSPK02 | D21: ='0903'!X2 | E21: =D12-D21
B22: CSPK00 | D22: ='0903'!X1 | E22: =D17-D22

Sheet TA35
X1: 333111 | Z1: 333113 | AB1: 333114
J2: Mẫu số : 01-1/GTGT | V2: DIEN00 | W2: =SUMIFS($H:$H,$T:$T,$V2) | X2: =SUMIFS($J:$J,$T:$T,$V2)
J3: (Ban hành kèm theo thông tư | V3: DIEN01 | W3: =SUMIFS($H:$H,$T:$T,$V3) | X3: =SUMIFS($J:$J,$T:$T,$V3)
J4: số 119/2014/TT-BTC ngày | V4: CSPK02 | W4: =SUMIFS($H:$H,$T:$T,$V4) | X4: =SUMIFS($J:$J,$T:$T,$V4)
J5: 25/08/2014 của Bộ tài chính) | V5: CSPK00 | W5: =SUMIFS($H:$H,$T:$T,$V5) | X5: =SUMIFS($J:$J,$T:$T,$V5)
V6: 1388ĐĐ | W6: =SUMIFS($H:$H,$T:$T,$V6) | X6: =SUMIFS($J:$J,$T:$T,$V6) | Y6: =SUMIFS($H:$H,$T:$T,$V6) | Z6: =SUMIFS($J:$J,$T:$T,$V6) | AC6: vật tư điều động
A7: BẢNG KÊ HÓA ĐƠN, CHỨNG TỪ HÀNG HÓA, DỊCH VỤ BÁN RA(Kiểm soát số liệu) | V7: 5118QT | W7: =SUMIFS($H:$H,$T:$T,$V7) | X7: =SUMIFS($J:$J,$T:$T,$V7) | Y7: =SUMIFS($H:$H,$T:$T,$V7) | Z7: =SUMIFS($J:$J,$T:$T,$V7) | AC7: quà tặng
A8: Kèm theo tờ kê khai thuế GTGT theo mẫu số 01/GTGT | V8: 4500TT | W8: =SUMIFS($H:$H,$T:$T,$V8) | X8: =SUMIFS($J:$J,$T:$T,$V8) | AA8: =SUMIFS($H:$H,$T:$T,$V8) | AB8: =SUMIFS($J:$J,$T:$T,$V8) | AC8: dường dây thông tin
A9: Từ ngày 01/09/2026 đến ngày 30/09/2026 | W9: =SUM(W2:W8) | X9: =SUM(X2:X8) | Y9: =SUM(Y2:Y8) | Z9: =SUM(Z2:Z8) | AA9: =SUM(AA2:AA8) | AB9: =SUM(AB2:AB8)
A11: Người nộp thuế : CHI NHÁNH TỔNG CÔNG TY ĐIỆN LỰC THÀNH PHỐ HỒ CHÍ MINH TNHH - CÔNG TY ĐIỆN LỰC VŨNG TÀU | U11: trước thuế | V11: =SUM(W11:AB11) | W11: =W9 | Y11: =Y9 | AA11: =AA9
A12: Mã số thuế : 0300951119-010 | U12: thuế | V12: =SUM(W12:AB12) | X12: =X9 | Z12: =Z9 | AB12: =AB9
A13: Đơn vị tính: đồng Việt Nam | V13: =SUM(V11:V12)
A14: STT | B14: Hóa đơn, chứng từ bán | E14: Tên người mua | F14: Mã số thuế người mua | G14: Mặt hàng | H14: Doanh số bán chưa có thuế | I14: Thuế suất | J14: Thuế GTGT | K14: Ghi chú | L14: Nguồn chứng từ | M14: Số chứng từ | N14: Ngày lập chứng từ | O14: Thời hạn thanh toán trả chậm | P14: Số tiền đã thanh toán | Q14: Loại hình kinh doanh | R14: Người lập chứng từ | S14: Trạng thái
B15: Ký hiệu hóa đơn | C15: Số hóa đơn | D15: Ngày, tháng, năm phát hành | U15: Kiểm dò MST | V15: Thuế suất
A16: 1 | B16: 2 | C16: 3 | D16: 4 | E16: 5 | F16: 6 | G16: 7 | H16: 8 | I16: 9 | J16: 10 | K16: 11 | L16: 12 | M16: 13 | N16: 14 | O16: 15 | P16: 16 | Q16: 17 | R16: 18 | S16: 19 | W16: =W9-H51
A17: 1.Hàng hóa, dịch vụ không chịu thuế GTGT | V17: 9
A18: 1 | C18: ' | F18: '
A19: Tổng cộng | T19: =LEFT(G19,6) | Y19: 5
A20: 2.Hàng hóa, dịch vụ chịu thuế suất thuế GTGT 0% | T20: =LEFT(G20,6) | U20: =LEN(F20) | Y20: 8
A21: 1 | B21: 1K26TDA | C21: ' | D21: 46276 | E21: DIEN00-DOANH THU HÓA ĐƠN TIỀN ĐIỆN PHÁT SINH | F21: 'KHDIENKINHDOANH | G21: DIEN00 | H21: 105713000 | I21: 0 | J21: 0 | K21: DIEN00-DOANH THU HÓA ĐƠN TIỀN ĐIỆN PHÁT SINH-CT TNHH NHÔM TOÀN CẦU VIỆT NAM KỲ 1/9/2026 | L21: AR_TRANS | M21: 2107 | N21: 46276 | O21: 46276 | Q21: Không xác định | R21: QUYENNN.HCM.VTA | S21: Complete | T21: =LEFT(G21,6) | U21: =LEN(F21) | Y21: 10
A22: 2 | B22: 1K26TDA | C22: ' | D22: 46286 | E22: DIEN00-DOANH THU HÓA ĐƠN TIỀN ĐIỆN PHÁT SINH | F22: 'KHDIENKINHDOANH | G22: DIEN00 | H22: 100483557 | I22: 0 | J22: 0 | K22: DIEN00-DOANH THU HÓA ĐƠN TIỀN ĐIỆN PHÁT SINH-CT TNHH NHÔM TOÀN CẦU VIỆT NAM KỲ 2/09/2026 | L22: AR_TRANS | M22: 2132 | N22: 46286 | O22: 46286 | Q22: Không xác định | R22: QUYENNN.HCM.VTA | S22: Complete | T22: =LEFT(G22,6) | U22: =LEN(F22) | V22: 0
A23: 3 | B23: 1K26TDA | C23: ' | E23: DIEN00-DOANH THU HÓA ĐƠN TIỀN ĐIỆN PHÁT SINH-CT TNHH NHÔM TOÀN CẦU VIỆT NAM KỲ 3/08/2026 | F23: ' | G23: DIEN00 | H23: 99442300 | I23: 0 | J23: 0 | L23: GL | M23: 2839 | N23: 46276 | O23: 46276 | P23: 99442300 | Q23: Không xác định | R23: QUYENNN.HCM.VTA | S23: Not Reversed | T23: =LEFT(G23,6) | U23: =LEN(F23) | V23: 0
A24: Tổng cộng | H24: 305638857 | J24: 0 | P24: 99442300 | T24: =LEFT(G24,6) | U24: =LEN(F24) | V24: 0
A25: 3.Hàng hóa, dịch vụ chịu thuế suất thuế GTGT 5% | T25: =LEFT(G25,6) | U25: =LEN(F25)
A26: 1 | C26: ' | F26: ' | T26: =LEFT(G26,6) | U26: =LEN(F26)
A27: Tổng cộng | T27: =LEFT(G27,6) | U27: =LEN(F27)
A28: 4.Hàng hóa, dịch vụ chịu thuế suất thuế GTGT 10% | T28: =LEFT(G28,6) | U28: =LEN(F28)
A29: 1 | B29: K26TAH | C29: '84 | D29: 46275 | E29: CHI NHÁNH TỔNG CÔNG TY ĐIỆN LỰC THÀNH PHỐ HỒ CHÍ MINH TNHH - CÔNG TY LƯỚI ĐIỆN CAO THẾ THÀNH PHỐ HỒ CHÍ MINH | F29: '0300951119-016 | G29: 1388ĐĐ - Điều động VTTB theo CV 6267 ngày 04/09/26, PGH 03.VHJ.43.0002 ngày 07/09/26 - HĐ 84/10.09.2026 | H29: 334144500 | I29: 8 | J29: 26731560 | K29: CK | L29: AR_TRANS | M29: 2149 | N29: 46275 | O29: 46275 | Q29: Không xác định | R29: CHAULTN.HCM.VTA | S29: Complete | T29: =LEFT(G29,6) | U29: =LEN(F29)
A30: 2 | B30: K26TAH | C30: '85 | D30: 46282 | E30: Chi nhánh Tổng Công ty Điện lực Thành phố Hồ Chí Minh TNHH - Công ty Dịch vụ Điện lực Thành phố Hồ Chí Minh | F30: '0300951119-017 | G30: 1388ĐĐ - Điều động VTTH theo PĐĐ 9165 ngày 20/08/26 & PGH 03.VH1.17.0002 ngày 08/09/26 - HĐ 85/17.09.2026 | H30: 156916987 | I30: 10 | J30: 15691699 | K30: CK | L30: AR_TRANS | M30: 2150 | N30: 46282 | O30: 46282 | P30: 172608686 | Q30: Không xác định | R30: CHAULTN.HCM.VTA | S30: Complete | T30: =LEFT(G30,6) | U30: =LEN(F30) | V30: 8
A31: 3 | B31: K26TAH | C31: '86 | D31: 46282 | E31: Chi nhánh Tổng Công ty Điện lực Thành phố Hồ Chí Minh TNHH - Công ty Dịch vụ Điện lực Thành phố Hồ Chí Minh | F31: '0300951119-017 | G31: 1388ĐĐ - Điều động VTTB theo PĐNĐĐ 9165 ngày 20/08/26 và PGH 03.VH1.17.0002 ngày 08/09/26 - HĐ 86/17.09.2026 | H31: 33600000 | I31: 8 | J31: 2688000 | K31: CK | L31: AR_TRANS | M31: 2154 | N31: 46282 | O31: 46282 | P31: 36288000 | Q31: Không xác định | R31: CHAULTN.HCM.VTA | S31: Complete | T31: =LEFT(G31,6) | U31: =LEN(F31) | V31: 8
A32: 4 | B32: K26TAH | C32: '87 | D32: 46283 | E32: Chi nhánh Tổng Công ty Điện lực Thành phố Hồ Chí Minh TNHH - Công ty Dịch vụ Điện lực Thành phố Hồ Chí Minh | F32: '0300951119-017 | G32: 1388ĐĐ - Điều động VTTB theo PĐN ĐĐ 9970 ngày 17/09/26 và PGH 03.VH1.57.0010 ngày 17/09/26 - HĐ 87 ngày 18/09/2026 | H32: 3675000 | I32: 8 | J32: 294000 | K32: CK | L32: AR_TRANS | M32: 2139 | N32: 46283 | O32: 46283 | Q32: Không xác định | R32: CHAULTN.HCM.VTA | S32: Complete | T32: =LEFT(G32,6) | U32: =LEN(F32) | V32: 8
A33: 5 | B33: K26TAH | C33: '88 | D33: 46283 | E33: Chi nhánh Tổng Công ty Điện lực Thành phố Hồ Chí Minh TNHH - Công ty Dịch vụ Điện lực Thành phố Hồ Chí Minh | F33: '0300951119-017 | G33: 1388ĐĐ - Điều động VTTB theo PĐNĐĐ 9840 ngày 15/09/2026 và PGH 03.VH1.57.0008, 03.VH1.57.0009 ngày 15/09/26 - HĐ 88 ngày 18/09/26 | H33: 174936197 | I33: 8 | J33: 13994896 | K33: CK | L33: AR_TRANS | M33: 2155 | N33: 46283 | O33: 46283 | Q33: Không xác định | R33: CHAULTN.HCM.VTA | S33: Complete | T33: =LEFT(G33,6) | U33: =LEN(F33) | V33: 8
A34: 6 | B34: K26TAH | C34: '89 | D34: 46286 | E34: CHI NHÁNH TỔNG CÔNG TY ĐIỆN LỰC THÀNH PHỐ HỒ CHÍ MINH TNHH - CÔNG TY ĐIỆN LỰC BÌNH DƯƠNG | F34: '0300951119-028 | G34: 1388ĐĐ - Điều động VTTB theo CV 5120 nagỳ 18/09/2026 và PGH 03.VH1.57.0011 ngày 18/09/26 - HĐ 89 ngày 21/09/26 | H34: 52530000 | I34: 8 | J34: 4202400 | K34: CK | L34: AR_TRANS | M34: 2140 | N34: 46286 | O34: 46286 | Q34: Không xác định | R34: CHAULTN.HCM.VTA | S34: Complete | T34: =LEFT(G34,6) | U34: =LEN(F34) | V34: 8
A35: 7 | B35: K26TAH | C35: '90 | D35: 46286 | E35: Chi nhánh Tổng Công ty Điện lực Thành phố Hồ Chí Minh TNHH - Công ty Dịch vụ Điện lực Thành phố Hồ Chí Minh | F35: '0300951119-017 | G35: 1388ĐĐ - Điều động VTTB theo PĐN ĐĐ 10031 ngày 18/09/2026 và PGH 03.VH1.57.0012 ngày 21/09/26 - HĐ 90 ngày 21/09/2026 | H35: 2450000 | I35: 8 | J35: 196000 | K35: CK | L35: AR_TRANS | M35: 2156 | N35: 46286 | O35: 46286 | Q35: Không xác định | R35: CHAULTN.HCM.VTA | S35: Complete | T35: =LEFT(G35,6) | U35: =LEN(F35) | V35: 8
A36: 8 | B36: K26TAH | C36: '91 | D36: 46287 | E36: CHI NHÁNH TỔNG CÔNG TY ĐIỆN LỰC THÀNH PHỐ HỒ CHÍ MINH TNHH - CÔNG TY ĐIỆN LỰC ĐẤT ĐỎ | F36: '0300951119-020 | G36: 1388ĐĐ - Điều động VTTB theo CV 2925 ngày 18/09/26 và PGH 03.VH1.57.0013 ngày 21/09/2026 - HĐ 91 ngày 22/09/2026 | H36: 117544514 | I36: 8 | J36: 9403561 | K36: CK | L36: AR_TRANS | M36: 2157 | N36: 46287 | O36: 46287 | Q36: Không xác định | R36: CHAULTN.HCM.VTA | S36: Complete | T36: =LEFT(G36,6) | U36: =LEN(F36) | V36: 8
A37: 9 | B37: K26TAH | C37: '92 | D37: 46293 | E37: CHI NHÁNH TỔNG CÔNG TY ĐIỆN LỰC THÀNH PHỐ HỒ CHÍ MINH TNHH - CÔNG TY ĐIỆN LỰC BÌNH DƯƠNG | F37: '0300951119-028 | G37: 1388ĐĐ - Điều động VTTB theo CV 5219/24.09.26 của PC Bình Dương, PGH 03.VH1.57.0014 ngày 24.09.26 - HĐ 92 ngày 28.09.26 | H37: 5242293 | I37: 8 | J37: 419383 | K37: CK | L37: AR_TRANS | M37: 2167 | N37: 46293 | O37: 46293 | Q37: Không xác định | R37: CHAULTN.HCM.VTA | S37: Complete | T37: =LEFT(G37,6) | U37: =LEN(F37) | V37: 8
A38: 10 | B38: K26TAH | C38: '93 | D38: 46293 | E38: CHI NHÁNH 9 - CÔNG TY TNHH TRUYỀN HÌNH CÁP SAIGONTOURIST | F38: '0301463315-006 | G38: 4500TT - Doanh thu cho thuê cột điện từ 01/07/26 đến 30/09/26 SCTV - HĐ 93 ngày 28/09/2026 | H38: 274710660 | I38: 8 | J38: 21976853 | K38: CK | L38: AR_TRANS | M38: 2182 | N38: 46293 | O38: 46293 | Q38: Không xác định | R38: CHAULTN.HCM.VTA | S38: Complete | T38: =LEFT(G38,6) | U38: =LEN(F38) | V38: 10
A39: 11 | B39: K26TAH | C39: '94 | D39: 46293 | E39: MobiFone Thành phố Hồ Chí Minh - Chi nhánh Tổng công ty Viễn thông MobiFone | F39: '0100686209-002 | G39: 4500TT - Doanh thu cho thuê cột điện treo cáp viễn thông từ 01/07/26 đến 30/09/26 (MBF) - HĐ 94 ngày 28/09/26 | H39: 1213549653 | I39: 8 | J39: 97083972 | K39: CK | L39: AR_TRANS | M39: 2183 | N39: 46293 | O39: 46293 | Q39: Không xác định | R39: CHAULTN.HCM.VTA | S39: Complete | T39: =LEFT(G39,6) | U39: =LEN(F39) | V39: 8
A40: 12 | B40: K26TAH | C40: '95 | D40: 46293 | E40: Chi nhánh Công ty Cổ phần Viễn thông FPT | F40: '0101778163-001 | G40: 4500TT - Doanh thu cho thuê cột điện treo cáp viễn thông từ 01/09/2026 đến 30/09/26 FPT - HĐ 95 ngày 28/09/2026 | H40: 57336523 | I40: 8 | J40: 4586922 | K40: CK | L40: AR_TRANS | M40: 2168 | N40: 46293 | O40: 46293 | Q40: Không xác định | R40: CHAULTN.HCM.VTA | S40: Complete | T40: =LEFT(G40,6) | U40: =LEN(F40) | V40: 10
A41: 13 | B41: K26TAH | C41: '96 | D41: 46293 | E41: VNPT thành phố Hồ Chí Minh | F41: '0300954529 | G41: 4500TT - Doanh thu cho thuê cột điện từ 01/09/26 đến 30/09/26 VNPT - HĐ 96 ngày 28/09/26 | H41: 150296766 | I41: 8 | J41: 12023741 | K41: CK | L41: AR_TRANS | M41: 2184 | N41: 46293 | O41: 46293 | Q41: Không xác định | R41: CHAULTN.HCM.VTA | S41: Complete | T41: =LEFT(G41,6) | U41: =LEN(F41) | V41: 10
...

Sheet 333111
A1: TỔNG CÔNG TY ĐIỆN LỰC THÀNH PHỐ HỒ CHÍ MINH TNHH | M1: 333111 | N1: 333113 | O1: 333114
A2: CHI NHÁNH TỔNG CÔNG TY ĐIỆN LỰC THÀNH PHỐ HỒ CHÍ MINH TNHH - CÔNG TY ĐIỆN LỰC VŨNG TÀU | L2: DIEN01 | M2: =SUMIFS($F:$F,$K:$K,M$1,$J:$J,$L2,$I:$I,5) | N2: =SUMIFS($F:$F,$K:$K,N$1,$J:$J,$L2,$I:$I,5) | O2: =SUMIFS($F:$F,$K:$K,O$1,$J:$J,$L2,$I:$I,5)
A3: SỔ CHI TIẾT THEO TÀI KHOẢN THUẾ | L3: CSPK02 | M3: =SUMIFS($F:$F,$K:$K,M$1,$J:$J,$L3,$I:$I,5) | N3: =SUMIFS($F:$F,$K:$K,N$1,$J:$J,$L3,$I:$I,5) | O3: =SUMIFS($F:$F,$K:$K,O$1,$J:$J,$L3,$I:$I,5)
A4: Tài khoản: 33311 - Thuế và các khoản phải nộp Nhà nước – Thuế giá trị gia tăng phải nộp – Thuế GTGT đầu ra | L4: 1388ĐĐ | M4: =SUMIFS($F:$F,$K:$K,M$1,$J:$J,$L4,$I:$I,5) | N4: =SUMIFS($F:$F,$K:$K,N$1,$J:$J,$L4,$I:$I,5) | O4: =SUMIFS($F:$F,$K:$K,O$1,$J:$J,$L4,$I:$I,5) | Q4: vật tư điều động
A5: Loại hình: - | L5: 5118QT | M5: =SUMIFS($F:$F,$K:$K,M$1,$J:$J,$L5,$I:$I,5) | N5: =SUMIFS($F:$F,$K:$K,N$1,$J:$J,$L5,$I:$I,5) | O5: =SUMIFS($F:$F,$K:$K,O$1,$J:$J,$L5,$I:$I,5) | Q5: quà tặng
A6: Từ ngày: 01/09/2026 đến ngày: 30/09/2026 | L6: 4500TT | M6: =SUMIFS($F:$F,$K:$K,M$1,$J:$J,$L6,$I:$I,5) | N6: =SUMIFS($F:$F,$K:$K,N$1,$J:$J,$L6,$I:$I,5) | O6: =SUMIFS($F:$F,$K:$K,O$1,$J:$J,$L6,$I:$I,5) | Q6: dường dây thông tin
M7: =SUM(M2:M6) | N7: =SUM(N2:N6) | O7: =SUM(O2:O6) | P7: =SUM(P2:P6)
A9: CHỨNG TỪ | D9: DIỄN GIẢI | E9: PHÁT SINH NỢ | F9: PHÁT SINH CÓ | G9: Người hạch toán | H9: Trạng thái
A10: Ngày chứng từ | B10: Số chứng từ | C10: Nguồn chứng từ
A11: Tài khoản: 33311100000 | D11: Dư đầu kỳ | E11: 922629212 | I11: =LEN(A11) | J11: =LEFT(D11,6) | K11: =IF(LEFT(A11,11)="Tài khoản: ",MID(A11,12,6),K10)
A12: 46276 | B12: '2106 | C12: AR_TRANS | D12: DIEN01-DOANH THU HÓA ĐƠN TIỀN ĐIỆN PHÁT SINH TỪ NGÀY 11/09/2026 ĐẾN 11/09/2026 | F12: 24466693819 | G12: QUYENNN.HCM.VTA | H12: Final to Post | I12: =LEN(A12) | J12: =LEFT(D12,6) | K12: =IF(LEFT(A12,11)="Tài khoản: ",MID(A12,12,6),K11)
A13: 46276 | B13: '2108 | C13: AR_TRANS | D13: CSPK02-DOANH THU HÓA ĐƠN TIỀN VÔ CÔNG PHÁT SINH TỪ NGÀY 11/09/2026 ĐẾN 11/09/2026 | F13: 15081702 | G13: QUYENNN.HCM.VTA | H13: Final to Post | I13: =LEN(A13) | J13: =LEFT(D13,6) | K13: =IF(LEFT(A13,11)="Tài khoản: ",MID(A13,12,6),K12)
A14: 46276 | B14: '2839 | C14: GL | D14: CSPK02-Giải trừ thuế GTGT đầu ra từ 33895 sang 333111 AR 2038-31/08/2026 | F14: 48749477 | G14: QUYENNN.HCM.VTA | H14: Post | I14: =LEN(A14) | J14: =LEFT(D14,6) | K14: =IF(LEFT(A14,11)="Tài khoản: ",MID(A14,12,6),K13)
A15: 46276 | B15: '2839 | C15: GL | D15: DIEN01-Giải trừ thuế GTGT đầu ra từ 33895 sang 333111 AR 2036-31/08/2026 | F15: 58912650773 | G15: QUYENNN.HCM.VTA | H15: Post | I15: =LEN(A15) | J15: =LEFT(D15,6) | K15: =IF(LEFT(A15,11)="Tài khoản: ",MID(A15,12,6),K14)
A16: 46281 | B16: '2175 | C16: AR_TRANS | D16: DIEN01-DOANH THU HÓA ĐƠN TIỀN ĐIỆN PHÁT SINH TỪ NGÀY 16/09/2026 ĐẾN 16/09/2026 | F16: 895685075 | G16: QUYENNN.HCM.VTA | H16: Final to Post | I16: =LEN(A16) | J16: =LEFT(D16,6) | K16: =IF(LEFT(A16,11)="Tài khoản: ",MID(A16,12,6),K15)
A17: 46281 | B17: '2176 | C17: AR_TRANS | D17: CSPK02-DOANH THU HÓA ĐƠN TIỀN VÔ CÔNG PHÁT SINH TỪ NGÀY 16/09/2026 ĐẾN 16/09/206 | F17: 3775196 | G17: QUYENNN.HCM.VTA | H17: Final to Post | I17: =LEN(A17) | J17: =LEFT(D17,6) | K17: =IF(LEFT(A17,11)="Tài khoản: ",MID(A17,12,6),K16)
A18: 46281 | B18: 'AP262465 | C18: AP_INV | D18: Phải nộp tiền thuế GTGT tháng 8/2026 | E18: 577370788 | G18: TUAN2HM.HCM.VTA | H18: Final to Post | I18: =LEN(A18) | J18: =LEFT(D18,6) | K18: =IF(LEFT(A18,11)="Tài khoản: ",MID(A18,12,6),K17)
A19: 46286 | B19: '2131 | C19: AR_TRANS | D19: DIEN01-DOANH THU HÓA ĐƠN TIỀN ĐIỆN PHÁT SINH TỪ NGÀY 21/09/2026 ĐẾN 21/09/2026 | F19: 27232232700 | G19: QUYENNN.HCM.VTA | H19: Final to Post | I19: =LEN(A19) | J19: =LEFT(D19,6) | K19: =IF(LEFT(A19,11)="Tài khoản: ",MID(A19,12,6),K18)
A20: 46286 | B20: '2133 | C20: AR_TRANS | D20: CSPK02-DOANH THU HÓA ĐƠN TIỀN VÔ CÔNG PHÁT SINH TỪ NGÀY 21/09/2026 ĐẾN 21/09/2026 | F20: 9802181 | G20: QUYENNN.HCM.VTA | H20: Final to Post | I20: =LEN(A20) | J20: =LEFT(D20,6) | K20: =IF(LEFT(A20,11)="Tài khoản: ",MID(A20,12,6),K19)
A21: 46295 | B21: '2170 | C21: AR_TRANS | D21: CSPK02-DOANH THU HÓA ĐƠN TIỀN VÔ CÔNG HỦY BỎ T09/2026 | F21: -71685 | G21: QUYENNN.HCM.VTA | H21: Final to Post | I21: =LEN(A21) | J21: =LEFT(D21,6) | K21: =IF(LEFT(A21,11)="Tài khoản: ",MID(A21,12,6),K20)
A22: 46295 | B22: '2171 | C22: AR_TRANS | D22: DIEN01-DOANH THU HÓA ĐƠN TIỀN ĐIỆN LẶP LẠI T09/2026 | F22: 4398992 | G22: QUYENNN.HCM.VTA | H22: Final to Post | I22: =LEN(A22) | J22: =LEFT(D22,6) | K22: =IF(LEFT(A22,11)="Tài khoản: ",MID(A22,12,6),K21)
A23: 46295 | B23: '2172 | C23: AR_TRANS | D23: DIEN01-DOANH THU HÓA ĐƠN TIỀN ĐIỆN THOÁI HOÀN T09/2026 | F23: -1006021 | G23: QUYENNN.HCM.VTA | H23: Final to Post | I23: =LEN(A23) | J23: =LEFT(D23,6) | K23: =IF(LEFT(A23,11)="Tài khoản: ",MID(A23,12,6),K22)
A24: 46295 | B24: '2173 | C24: AR_TRANS | D24: DIEN01-DOANH THU HÓA ĐƠN TIỀN ĐIỆN TRUY THU T09/2026 | F24: 39778263 | G24: QUYENNN.HCM.VTA | H24: Final to Post | I24: =LEN(A24) | J24: =LEFT(D24,6) | K24: =IF(LEFT(A24,11)="Tài khoản: ",MID(A24,12,6),K23)
A25: 46295 | B25: '2187 | C25: AR_TRANS | D25: DIEN01-DOANH THU HÓA ĐƠN TIỀN ĐIỆN HỦY BỎ T09/2026 | F25: -7218247 | G25: QUYENNN.HCM.VTA | H25: Final to Post | I25: =LEN(A25) | J25: =LEFT(D25,6) | K25: =IF(LEFT(A25,11)="Tài khoản: ",MID(A25,12,6),K24)
A26: 46295 | B26: '2855 | C26: GL | D26: Kết chuyển TK 13313_9000 qua TK 333111 | E26: 110027 | G26: LINH3NTT.HCM.VTA | H26: Post | I26: =LEN(A26) | J26: =LEFT(D26,6) | K26: =IF(LEFT(A26,11)="Tài khoản: ",MID(A26,12,6),K25)
A27: 46295 | B27: '3122 | C27: GL | D27: Kết chuyển Thuế GTGT (333113,333114 về 333111) Tháng 9/2026 | F27: 212968193 | G27: TUAN2HM.HCM.VTA | H27: Unpost | I27: =LEN(A27) | J27: =LEFT(D27,6) | K27: =IF(LEFT(A27,11)="Tài khoản: ",MID(A27,12,6),K26)
A28: 46295 | B28: '3123 | C28: GL | D28: Kê khai thuế GTGT tháng 9 CT ĐTXD | E28: 27831187 | G28: HIENNTK.HCM.VTA | H28: Post | I28: =LEN(A28) | J28: =LEFT(D28,6) | K28: =IF(LEFT(A28,11)="Tài khoản: ",MID(A28,12,6),K27)
A29: 46295 | B29: '3193 | C29: GL | D29: K/c thuế GTGT từ 1331 về 3331 tháng 9/2026 | E29: 102540977433 | G29: TUAN2HM.HCM.VTA | H29: Unpost | I29: =LEN(A29) | J29: =LEFT(D29,6) | K29: =IF(LEFT(A29,11)="Tài khoản: ",MID(A29,12,6),K28)
D30: Cộng phát sinh | E30: 103146289435 | F30: 111833520418 | I30: =LEN(A30) | J30: =LEFT(D30,6) | K30: =IF(LEFT(A30,11)="Tài khoản: ",MID(A30,12,6),K29)
D31: Dư cuối kỳ | F31: 7764601771 | I31: =LEN(A31) | J31: =LEFT(D31,6) | K31: =IF(LEFT(A31,11)="Tài khoản: ",MID(A31,12,6),K30)
A32: Tài khoản: 33311300000 | D32: Dư đầu kỳ | I32: =LEN(A32) | J32: =LEFT(D32,6) | K32: =IF(LEFT(A32,11)="Tài khoản: ",MID(A32,12,6),K31)
A33: 46275 | B33: '2149 | C33: AR_TRANS | D33: 1388ĐĐ - Điều động VTTB theo CV 6267 ngày 04/09/26, PGH 03.VHJ.43.0002 ngày 07/09/26 - HĐ 84/10.09.2026 | F33: 26731560 | G33: CHAULTN.HCM.VTA | H33: Final to Post | I33: =LEN(A33) | J33: =LEFT(D33,6) | K33: =IF(LEFT(A33,11)="Tài khoản: ",MID(A33,12,6),K32)
A34: 46282 | B34: '2150 | C34: AR_TRANS | D34: 1388ĐĐ - Điều động VTTH theo PĐĐ 9165 ngày 20/08/26 & PGH 03.VH1.17.0002 ngày 08/09/26 - HĐ 85/17.09.2026 | F34: 15691699 | G34: CHAULTN.HCM.VTA | H34: Final to Post | I34: =LEN(A34) | J34: =LEFT(D34,6) | K34: =IF(LEFT(A34,11)="Tài khoản: ",MID(A34,12,6),K33)
A35: 46282 | B35: '2154 | C35: AR_TRANS | D35: 1388ĐĐ - Điều động VTTB theo PĐNĐĐ 9165 ngày 20/08/26 và PGH 03.VH1.17.0002 ngày 08/09/26 - HĐ 86/17.09.2026 | F35: 2688000 | G35: CHAULTN.HCM.VTA | H35: Final to Post | I35: =LEN(A35) | J35: =LEFT(D35,6) | K35: =IF(LEFT(A35,11)="Tài khoản: ",MID(A35,12,6),K34)
A36: 46283 | B36: '2139 | C36: AR_TRANS | D36: 1388ĐĐ - Điều động VTTB theo PĐN ĐĐ 9970 ngày 17/09/26 và PGH 03.VH1.57.0010 ngày 17/09/26 - HĐ 87 ngày 18/09/2026 | F36: 294000 | G36: CHAULTN.HCM.VTA | H36: Final to Post | I36: =LEN(A36) | J36: =LEFT(D36,6) | K36: =IF(LEFT(A36,11)="Tài khoản: ",MID(A36,12,6),K35)
A37: 46283 | B37: '2155 | C37: AR_TRANS | D37: 1388ĐĐ - Điều động VTTB theo PĐNĐĐ 9840 ngày 15/09/2026 và PGH 03.VH1.57.0008, 03.VH1.57.0009 ngày 15/09/26 - HĐ 88 ngày 18/09/26 | F37: 13994896 | G37: CHAULTN.HCM.VTA | H37: Final to Post | I37: =LEN(A37) | J37: =LEFT(D37,6) | K37: =IF(LEFT(A37,11)="Tài khoản: ",MID(A37,12,6),K36)
A38: 46286 | B38: '2140 | C38: AR_TRANS | D38: 1388ĐĐ - Điều động VTTB theo CV 5120 nagỳ 18/09/2026 và PGH 03.VH1.57.0011 ngày 18/09/26 - HĐ 89 ngày 21/09/26 | F38: 4202400 | G38: CHAULTN.HCM.VTA | H38: Final to Post | I38: =LEN(A38) | J38: =LEFT(D38,6) | K38: =IF(LEFT(A38,11)="Tài khoản: ",MID(A38,12,6),K37)
A39: 46286 | B39: '2156 | C39: AR_TRANS | D39: 1388ĐĐ - Điều động VTTB theo PĐN ĐĐ 10031 ngày 18/09/2026 và PGH 03.VH1.57.0012 ngày 21/09/26 - HĐ 90 ngày 21/09/2026 | F39: 196000 | G39: CHAULTN.HCM.VTA | H39: Final to Post | I39: =LEN(A39) | J39: =LEFT(D39,6) | K39: =IF(LEFT(A39,11)="Tài khoản: ",MID(A39,12,6),K38)
A40: 46287 | B40: '2157 | C40: AR_TRANS | D40: 1388ĐĐ - Điều động VTTB theo CV 2925 ngày 18/09/26 và PGH 03.VH1.57.0013 ngày 21/09/2026 - HĐ 91 ngày 22/09/2026 | F40: 9403561 | G40: CHAULTN.HCM.VTA | H40: Final to Post | I40: =LEN(A40) | J40: =LEFT(D40,6) | K40: =IF(LEFT(A40,11)="Tài khoản: ",MID(A40,12,6),K39)
A41: 46293 | B41: '2167 | C41: AR_TRANS | D41: 1388ĐĐ - Điều động VTTB theo CV 5219/24.09.26 của PC Bình Dương, PGH 03.VH1.57.0014 ngày 24.09.26 - HĐ 92 ngày 28.09.26 | F41: 419383 | G41: CHAULTN.HCM.VTA | H41: Final to Post | I41: =LEN(A41) | J41: =LEFT(D41,6) | K41: =IF(LEFT(A41,11)="Tài khoản: ",MID(A41,12,6),K40)
...

Sheet 33895
A1: TỔNG CÔNG TY ĐIỆN LỰC THÀNH PHỐ HỒ CHÍ MINH TNHH | M1: Nợ_giải trừ | N1: Có_treo
A2: CHI NHÁNH TỔNG CÔNG TY ĐIỆN LỰC THÀNH PHỐ HỒ CHÍ MINH TNHH - CÔNG TY ĐIỆN LỰC VŨNG TÀU | L2: DIEN01 | M2: =SUMIF($J:$J,$L2,F:F) | N2: =SUMIF($J:$J,$L2,G:G)
A3: SỔ CHI TIẾT TÀI KHOẢN THEO 3 CẤP ĐỐI TƯỢNG DFF | L3: CSPK02 | M3: =SUMIF($J:$J,$L3,F:F) | N3: =SUMIF($J:$J,$L3,G:G)
A4: Tài khoản 33895 - Phải trả, phải nộp khác – Thuế đầu ra chưa kê khai | M4: =SUM(M2:M3) | N4: =SUM(N2:N3)
A5: Tất cả loại hình
A6: Từ ngày 01/09/2026 đến ngày 30/09/2026
A7: Nguồn bút toán | B7: Chứng từ | E7: Diễn giải | F7: Số phát sinh Nợ | G7: Số phát sinh Có | H7: Người lập | I7: Trạng Thái
B8: Ngày | C8: Số CT Phân hệ phụ | D8: Số CT phân | H8: Chứng từ
D9: hệ GL
A10: 33895000000-Phải trả, phải nộp khác – Thuế đầu ra chưa kê khai
E11: Số dư đầu kỳ | G11: 58961400250
A12: Khác | G12: 58961400250
A13: Khác | G13: 58961400250
A14: Khác | G14: 58961400250
A15: GL-Manual | B15: 46276 | D15: 2839 | E15: 082900.000000.000.33895000000.0000.0000.000.000000.0000.0000 | F15: 58912650773 | H15: QUYENNN.HCM.VTA | I15: Post | J15: DIEN01 | K15: =IF(H15=$K$9,G15,0)
E16: DIEN01-Giải trừ thuế GTGT đầu ra từ 33895 sang 333111 AR 2036-31/08/2026 | J16: DIEN01 | K16: =IF(H16=$K$9,G16,0)
A17: GL-Manual | B17: 46276 | D17: 2839 | E17: 082900.000000.000.33895000000.0000.0000.000.000000.0000.0000 | H17: QUYENNN.HCM.VTA | I17: Post | J17: DIEN00 | K17: =IF(H17=$K$9,G17,0)
E18: DIEN00-Giải trừ thuế GTGT đầu ra từ 33895 sang 333111 AR 2037-31/08/2026 | J18: DIEN00 | K18: =IF(H18=$K$9,G18,0)
A19: GL-Manual | B19: 46276 | D19: 2839 | E19: 082900.000000.000.33895000000.0000.0000.000.000000.0000.0000 | F19: 48749477 | H19: QUYENNN.HCM.VTA | I19: Post | J19: CSPK02 | K19: =IF(H19=$K$9,G19,0)
E20: CSPK02-Giải trừ thuế GTGT đầu ra từ 33895 sang 333111 AR 2038-31/08/2026 | J20: CSPK02 | K20: =IF(H20=$K$9,G20,0)
A21: AR-Transaction | B21: 46295 | C21: 2177 | E21: 082900.000000.000.33895000000.0000.0000.000.000000.0000.0000 | G21: 54304559408 | H21: QUYENNN.HCM.VTA | I21: Final Post GL | J21: DIEN01 | K21: =IF(H21=$K$9,G21,0)
E22: DIEN01-DOANH THU HÓA ĐƠN TIỀN ĐIỆN PHÁT SINH T09/2026 | J22: DIEN01 | K22: =IF(H22=$K$9,G22,0)
A23: AR-Transaction | B23: 46295 | C23: 2201 | E23: 082900.000000.000.33895000000.0000.0000.000.000000.0000.0000 | G23: 44497199 | H23: QUYENNN.HCM.VTA | I23: Final Post GL | J23: CSPK02 | K23: =IF(H23=$K$9,G23,0)
E24: CSPK02-DOANH THU HÓA ĐƠN TIỀN VÔ CÔNG PHÁT SINH T09/2026 | J24: CSPK02 | K24: =IF(H24=$K$9,G24,0)
A25: AR-Transaction | B25: 46295 | C25: 2178 | E25: 082900.000000.000.33895000000.0000.0000.000.000000.0000.0000 | H25: QUYENNN.HCM.VTA | I25: Final Post GL | J25: DIEN00 | K25: =IF(H25=$K$9,G25,0)
E26: DIEN00-DOANH THU HÓA ĐƠN TIỀN ĐIỆN PHÁT SINH-CT TNHH NHÔM TOÀN CẦU VIỆT NAM KỲ 3/9/2026 | J26: DIEN00 | K26: =IF(H26=$K$9,G26,0)
B27: Cộng phát sinh – cấp 3 | F27: 58961400250 | G27: 54349056607
B28: Dư cuối kỳ | G28: 54349056607
B29: Cộng phát sinh – cấp 2 | F29: 58961400250 | G29: 54349056607
B30: Dư cuối kỳ | G30: 54349056607
B31: Cộng phát sinh – cấp 1 | F31: 58961400250 | G31: 54349056607
B32: Dư cuối kỳ | G32: 54349056607
B33: Cộng phát sinh-33895000000 | F33: 58961400250 | G33: 54349056607
B34: Dư cuối kỳ- | G34: 54349056607
B35: Tổng Dư đầu kỳ - 33895000000 | G35: 58961400250
B36: Tổng Cộng phát sinh | F36: 58961400250 | G36: 54349056607
B37: Tổng Dư cuối kỳ | G37: 54349056607
C38: Người lập biểu | D38: Kế toán trưởng
C39: (Ký, họ tên) | D39: (Ký, họ tên)

Sheet TA36
J1: Mẫu số : 01-2/GTGT | W1: TUAN2HM.HCM.VTA | X1: =SUMIF($R:$R,$W1,$H:$H) | Y1: =SUMIF($R:$R,$W1,$J:$J) | Z1: =SUMIF('13311'!$G:$G,'TA36'!$W1,'13311'!$E:$E) | AA1: =Y1-Z1
J2: (Ban hành kèm theo thông tư | W2: LINH3NTT.HCM.VTA | X2: =SUMIF($R:$R,$W2,$H:$H) | Y2: =SUMIF($R:$R,$W2,$J:$J) | Z2: =SUMIF('13311'!$G:$G,'TA36'!$W2,'13311'!$E:$E) | AA2: =Y2-Z2
J3: số 119/2014/TT-BTC ngày | W3: THANH5DT.HCM.VTA | X3: =SUMIF($R:$R,$W3,$H:$H) | Y3: =SUMIF($R:$R,$W3,$J:$J) | Z3: =SUMIF('13311'!$G:$G,'TA36'!$W3,'13311'!$E:$E) | AA3: =Y3-Z3
J4: 25/08/2014 của Bộ tài chính) | W4: HIENNTK.HCM.VTA | X4: =SUMIF($R:$R,$W4,$H:$H) | Y4: =SUMIF($R:$R,$W4,$J:$J) | Z4: =SUMIF('13311'!$G:$G,'TA36'!$W4,'13311'!$E:$E) | AA4: =Y4-Z4
W5: QUYENNN.HCM.VTA | X5: =SUMIF($R:$R,$W5,$H:$H) | Y5: =SUMIF($R:$R,$W5,$J:$J) | Z5: =SUMIF('13311'!$G:$G,'TA36'!$W5,'13311'!$E:$E) | AA5: =Y5-Z5
B6: BẢNG KÊ HÓA ĐƠN, CHỨNG TỪ HÀNG HÓA, DỊCH VỤ MUA VÀO(Kiểm soát số liệu) | W6: HUENT.HCM.VTA | X6: =SUMIF($R:$R,$W6,$H:$H) | Y6: =SUMIF($R:$R,$W6,$J:$J) | Z6: =SUMIF('13311'!$G:$G,'TA36'!$W6,'13311'!$E:$E) | AA6: =Y6-Z6
B7: Kèm theo tờ kê khai thuế GTGT theo mẫu số 01/GTGT | W7: THAOPTT.HCM.VTA | X7: =SUMIF($R:$R,$W7,$H:$H) | Y7: =SUMIF($R:$R,$W7,$J:$J) | Z7: =SUMIF('13311'!$G:$G,'TA36'!$W7,'13311'!$E:$E) | AA7: =Y7-Z7
B8: Từ ngày 01/09/2026 đến ngày 30/09/2026 | W8: CHAULTN.HCM.VTA | X8: =SUMIF($R:$R,$W8,$H:$H) | Y8: =SUMIF($R:$R,$W8,$J:$J) | Z8: =SUMIF('13311'!$G:$G,'TA36'!$W8,'13311'!$E:$E) | AA8: =Y8-Z8
W9: THUTT.HCM.VTA | X9: =SUMIF($R:$R,$W9,$H:$H) | Y9: =SUMIF($R:$R,$W9,$J:$J) | Z9: =SUMIF('13311'!$G:$G,'TA36'!$W9,'13311'!$E:$E) | AA9: =Y9-Z9
B10: Người nộp thuế : CHI NHÁNH TỔNG CÔNG TY ĐIỆN LỰC THÀNH PHỐ HỒ CHÍ MINH TNHH - CÔNG TY ĐIỆN LỰC VŨNG TÀU | X10: =SUM(X1:X9) | Y10: =SUM(Y1:Y9) | Z10: =SUM(Z1:Z9) | AA10: =SUM(AA1:AA9)
B11: Mã số thuế : 0300951119-010 | X11: TAX36 | Y11: TAX36 | Z11: TA030
N12: Đơn vị tính: đồng Việt Nam | V12: XDCB | X12: trước thuế | Y12: tiền thuế
W13: SXKD | X13: =X10-X14 | Y13: =Y10-Y14
A14: STT | B14: Hóa đơn chứng từ bán | E14: Tên người bán | F14: Mã số thuế người bán | G14: Mặt hàng | H14: Doanh số mua chưa có thuế | I14: Thuế suất (%) | J14: Thuế GTGT | K14: Ghi chú | L14: Nguồn chứng từ | M14: Số chứng từ | N14: Ngày lập chứng từ | O14: Thời hạn thanh toán trả chậm | P14: Số tiền đã thanh toán | Q14: Loại hình SXKD | R14: Người lập chứng từ | S14: Trạng thái | T14: =IF(OR(LEN(F14)=11,LEN(F14)=15),"Đ","SAI") | U14: =ROUND(H14*I14%,0)-J14 | V14: =IF(Q14=$V$12,13313,13311) | W14: XDCB | X14: =SUMIF($Q:$Q,$V$12,$H:$H) | Y14: =SUMIF($Q:$Q,$V$12,$J:$J)
B15: Ký hiệu hóa đơn | C15: Số hóa đơn | D15: Ngày, tháng, năm phát hành | T15: =IF(OR(LEN(F15)=11,LEN(F15)=15),"Đ","SAI") | U15: =ROUND(H15*I15%,0)-J15 | V15: =IF(Q15=$V$12,13313,13311) | X15: =SUM(X13:X14) | Y15: =SUM(Y13:Y14)
A16: [1] | B16: [2] | C16: [3] | D16: [4] | E16: [5] | F16: [6] | G16: [7] | H16: [8] | I16: [9] | J16: [10] | K16: [11] | L16: [12] | M16: [13] | N16: [14] | O16: [15] | P16: [16] | Q16: [17] | R16: [18] | S16: [19] | T16: =IF(OR(LEN(F16)=11,LEN(F16)=15),"Đ","SAI") | U16: =ROUND(H16*I16%,0)-J16 | V16: =IF(Q16=$V$12,13313,13311)
A17: 1. Hàng hóa, dịch vụ dùng riêng cho SXKD chịu thuế GTGT đủ điều kiện được khấu trừ | T17: =IF(OR(LEN(F17)=11,LEN(F17)=15),"Đ","SAI") | U17: =ROUND(H17*I17%,0)-J17 | V17: =IF(Q17=$V$12,13313,13311)
A18: 1 | B18: 1K26TAA | C18: '1325 | D18: 46268 | E18: TỔNG CÔNG TY ĐIỆN LỰC THÀNH PHỐ HỒ CHÍ MINH | F18: '0300951119 | G18: Thuế GTGT VTĐĐ- hđơn 1325-03.09.26 | H18: 802200000 | I18: 8 | J18: 64176000 | K18: CK | L18: GL | M18: '2853 | N18: 46294 | O18: 46294 | P18: 866376000 | Q18: Không xác định | R18: THANH5DT.HCM.VTA | S18: Not Reversed | T18: =IF(OR(LEN(F18)=11,LEN(F18)=15),"Đ","SAI") | U18: =ROUND(H18*I18%,0)-J18 | V18: =IF(Q18=$V$12,13313,13311)
A19: 2 | B19: 1K26TAA | C19: '1329 | D19: 46269 | E19: TỔNG CÔNG TY ĐIỆN LỰC THÀNH PHỐ HỒ CHÍ MINH | F19: '0300951119 | G19: Thuế GTGT VTĐĐ- hđơn 1329-04.09.26 | H19: 175440000 | I19: 8 | J19: 14035200 | K19: CK | L19: GL | M19: '2853 | N19: 46294 | O19: 46294 | P19: 189475200 | Q19: Không xác định | R19: THANH5DT.HCM.VTA | S19: Not Reversed | T19: =IF(OR(LEN(F19)=11,LEN(F19)=15),"Đ","SAI") | U19: =ROUND(H19*I19%,0)-J19 | V19: =IF(Q19=$V$12,13313,13311)
A20: 3 | B20: 1K26TAA | C20: '1368 | D20: 46273 | E20: TỔNG CÔNG TY ĐIỆN LỰC THÀNH PHỐ HỒ CHÍ MINH | F20: '0300951119 | G20: Thuế GTGT VTĐĐ- hđơn 1368-08.09.26 | H20: 167700000 | I20: 8 | J20: 13416000 | K20: CK | L20: GL | M20: '2853 | N20: 46294 | O20: 46294 | P20: 181116000 | Q20: Không xác định | R20: THANH5DT.HCM.VTA | S20: Not Reversed | T20: =IF(OR(LEN(F20)=11,LEN(F20)=15),"Đ","SAI") | U20: =ROUND(H20*I20%,0)-J20 | V20: =IF(Q20=$V$12,13313,13311)
A21: 4 | B21: 1K26TAA | C21: '1415 | D21: 46281 | E21: TỔNG CÔNG TY ĐIỆN LỰC THÀNH PHỐ HỒ CHÍ MINH | F21: '0300951119 | G21: Thuế GTGT VTĐĐ- hđơn 1415-16.09.26 | H21: 147060000 | I21: 8 | J21: 11764800 | K21: CK | L21: GL | M21: '2853 | N21: 46294 | O21: 46294 | P21: 158824800 | Q21: Không xác định | R21: THANH5DT.HCM.VTA | S21: Not Reversed | T21: =IF(OR(LEN(F21)=11,LEN(F21)=15),"Đ","SAI") | U21: =ROUND(H21*I21%,0)-J21 | V21: =IF(Q21=$V$12,13313,13311)
A22: 5 | B22: 1K26TAA | C22: '1435 | D22: 46283 | E22: TỔNG CÔNG TY ĐIỆN LỰC THÀNH PHỐ HỒ CHÍ MINH | F22: '0300951119 | G22: Thuế GTGT VTĐĐ- hđơn 1435-18.09.26 | H22: 933600000 | I22: 8 | J22: 74688000 | K22: CK | L22: GL | M22: '2853 | N22: 46294 | O22: 46294 | P22: 1008288000 | Q22: Không xác định | R22: THANH5DT.HCM.VTA | S22: Not Reversed | T22: =IF(OR(LEN(F22)=11,LEN(F22)=15),"Đ","SAI") | U22: =ROUND(H22*I22%,0)-J22 | V22: =IF(Q22=$V$12,13313,13311)
A23: 6 | B23: 1K26TAA | C23: '1436 | D23: 46283 | E23: TỔNG CÔNG TY ĐIỆN LỰC THÀNH PHỐ HỒ CHÍ MINH | F23: '0300951119 | G23: Thuế GTGT VTĐĐ- hđơn 1436-18.09.26 | H23: 223400000 | I23: 8 | J23: 17872000 | K23: CK | L23: GL | M23: '2853 | N23: 46294 | O23: 46294 | P23: 241272000 | Q23: Không xác định | R23: THANH5DT.HCM.VTA | S23: Not Reversed | T23: =IF(OR(LEN(F23)=11,LEN(F23)=15),"Đ","SAI") | U23: =ROUND(H23*I23%,0)-J23 | V23: =IF(Q23=$V$12,13313,13311)
A24: 7 | B24: 1K26TAA | C24: '1531 | D24: 46295 | E24: TỔNG CÔNG TY ĐIỆN LỰC THÀNH PHỐ HỒ CHÍ MINH | F24: '0300951119 | G24: Thuế GTGT VTĐĐ- hđơn 1531-30.09.26 | H24: 675900000 | I24: 8 | J24: 54072000 | K24: CK | L24: GL | M24: '2853 | N24: 46294 | O24: 46294 | P24: 729972000 | Q24: Không xác định | R24: THANH5DT.HCM.VTA | S24: Not Reversed | T24: =IF(OR(LEN(F24)=11,LEN(F24)=15),"Đ","SAI") | U24: =ROUND(H24*I24%,0)-J24 | V24: =IF(Q24=$V$12,13313,13311)
A25: 8 | B25: 1K26TAA | C25: '00026746 | D25: 46279 | E25: Ngân hàng TMCP Đầu Tư Và Phát Triển - CN Bà Rịa Vũng Tàu | F25: '0100150619-006 | G25: Dịch vụ ngân hàng | H25: 50000 | I25: 10 | J25: 5000 | L25: GL | M25: '2855 | N25: 46295 | O25: 46295 | P25: 55000 | Q25: ĐẦU TƯ XÂY DỰNG | R25: LINH3NTT.HCM.VTA | S25: Not Reversed | T25: =IF(OR(LEN(F25)=11,LEN(F25)=15),"Đ","SAI") | U25: =ROUND(H25*I25%,0)-J25 | V25: =IF(Q25=$V$12,13313,13311)
A26: 9 | B26: 1K26TAA | C26: '00026849 | D26: 46280 | E26: Ngân hàng TMCP Đầu Tư Và Phát Triển - CN Bà Rịa Vũng Tàu | F26: '0100150619-006 | G26: Dịch vụ ngân hàng | H26: 20000 | I26: 10 | J26: 2000 | L26: GL | M26: '2855 | N26: 46295 | O26: 46295 | P26: 22000 | Q26: ĐẦU TƯ XÂY DỰNG | R26: LINH3NTT.HCM.VTA | S26: Not Reversed | T26: =IF(OR(LEN(F26)=11,LEN(F26)=15),"Đ","SAI") | U26: =ROUND(H26*I26%,0)-J26 | V26: =IF(Q26=$V$12,13313,13311) | X26: =H26*8%
A27: 10 | B27: 1K26TAA | C27: '00027125 | D27: 46286 | E27: Ngân hàng TMCP Đầu Tư Và Phát Triển - CN Bà Rịa Vũng Tàu | F27: '0100150619-006 | G27: Dịch vụ ngân hàng | H27: 838803 | I27: 10 | J27: 83880 | L27: GL | M27: '2855 | N27: 46295 | O27: 46295 | P27: 922683 | Q27: ĐẦU TƯ XÂY DỰNG | R27: LINH3NTT.HCM.VTA | S27: Not Reversed | T27: =IF(OR(LEN(F27)=11,LEN(F27)=15),"Đ","SAI") | U27: =ROUND(H27*I27%,0)-J27 | V27: =IF(Q27=$V$12,13313,13311)
A28: 11 | B28: 1K26TAA | C28: '00027710 | D28: 46294 | E28: Ngân hàng TMCP Đầu tư và Phát triển Việt Nam- CN Bà Rịa Vũng Tàu | F28: '0100150619-006 | G28: Dịch vụ ngân hàng | H28: 191476 | I28: 10 | J28: 19147 | L28: GL | M28: '2855 | N28: 46295 | O28: 46295 | P28: 210623 | Q28: ĐẦU TƯ XÂY DỰNG | R28: LINH3NTT.HCM.VTA | S28: Not Reversed | T28: =IF(OR(LEN(F28)=11,LEN(F28)=15),"Đ","SAI") | U28: =ROUND(H28*I28%,0)-J28 | V28: =IF(Q28=$V$12,13313,13311)
A29: 12 | B29: 1K26TDA | C29: '00000032 | D29: 46295 | E29: NGÂN HÀNG TMCP ĐẦU TƯ VÀ PHÁT TRIỂN VIỆT NAM | F29: '0100150619--006 | G29: PHÍ CHUYỂN TIỀN | H29: 5709746 | I29: 10 | J29: 570975 | K29: GL_0926Q10 | L29: GL | M29: '2903 | N29: 46295 | O29: 46295 | P29: 6280721 | Q29: Không xác định | R29: QUYENNN.HCM.VTA | S29: Not Reversed | T29: =IF(OR(LEN(F29)=11,LEN(F29)=15),"Đ","SAI") | U29: =ROUND(H29*I29%,0)-J29 | V29: =IF(Q29=$V$12,13313,13311)
A30: 13 | B30: 1K26TDA | C30: '00000033 | D30: 46295 | E30: NGÂN HÀNG TMCP ĐẦU TƯ VÀ PHÁT TRIỂN VIỆT NAM | F30: '0100150619-006 | G30: PHÍ CHUYỂN TIỀN | H30: 3300006 | I30: 10 | J30: 330001 | K30: GL_0926Q10 | L30: GL | M30: '2903 | N30: 46295 | O30: 46295 | P30: 3630007 | Q30: Không xác định | R30: QUYENNN.HCM.VTA | S30: Not Reversed | T30: =IF(OR(LEN(F30)=11,LEN(F30)=15),"Đ","SAI") | U30: =ROUND(H30*I30%,0)-J30 | V30: =IF(Q30=$V$12,13313,13311)
A31: 14 | B31: 1K26TDA | C31: '00000034 | D31: 46295 | E31: NGÂN HÀNG TMCP ĐẦU TƯ VÀ PHÁT TRIỂN VIỆT NAM | F31: '0100150619-006 | G31: PHÍ CHUYỂN TIỀN | H31: 5682448 | I31: 10 | J31: 568245 | K31: GL_0926Q10 | L31: GL | M31: '2903 | N31: 46295 | O31: 46295 | P31: 6250693 | Q31: Không xác định | R31: QUYENNN.HCM.VTA | S31: Not Reversed | T31: =IF(OR(LEN(F31)=11,LEN(F31)=15),"Đ","SAI") | U31: =ROUND(H31*I31%,0)-J31 | V31: =IF(Q31=$V$12,13313,13311)
A32: 15 | B32: 1K26TAA | C32: '1335 | D32: 46271 | E32: TONG CONG TY DIEN LUC THANH PHO HO CHI MINH TNHH | F32: '0300951119 | G32: ĐIỆN MUA NỘI BỘ THÁNG 8/2026 | H32: 1355819328509 | I32: 8 | J32: 100431061371 | L32: GL_REV | M32: '2905 | N32: 46295 | O32: 46295 | P32: 1456250389880 | Q32: Không xác định | R32: TUAN2HM.HCM.VTA | S32: Reversed | T32: =IF(OR(LEN(F32)=11,LEN(F32)=15),"Đ","SAI") | U32: =ROUND(H32*I32%,0)-J32 | V32: =IF(Q32=$V$12,13313,13311)
A33: 16 | B33: 1C26TVC | C33: '43 | D33: 46206 | E33: Công ty cổ phần tư vấn xây dựng IN.CI.VI | F33: '0400780851 | G33: Tư vấn thẩm tra BCNCKT | H33: 44444444 | I33: 8 | J33: 3555556 | L33: GL | M33: '3123 | N33: 46295 | O33: 46295 | P33: 48000000 | Q33: ĐẦU TƯ XÂY DỰNG | R33: HIENNTK.HCM.VTA | S33: Not Reversed | T33: =IF(OR(LEN(F33)=11,LEN(F33)=15),"Đ","SAI") | U33: =ROUND(H33*I33%,0)-J33 | V33: =IF(Q33=$V$12,13313,13311)
A34: 17 | B34: 1C26TVC | C34: '44 | D34: 46206 | E34: Công ty cổ phần tư vấn xây dựng IN.CI.VI | F34: '0400780851 | G34: Tư vấn thẩm tra BCNCKT | H34: 44444444 | I34: 8 | J34: 3555556 | L34: GL | M34: '3123 | N34: 46295 | O34: 46295 | P34: 48000000 | Q34: ĐẦU TƯ XÂY DỰNG | R34: HIENNTK.HCM.VTA | S34: Not Reversed | T34: =IF(OR(LEN(F34)=11,LEN(F34)=15),"Đ","SAI") | U34: =ROUND(H34*I34%,0)-J34 | V34: =IF(Q34=$V$12,13313,13311)
A35: 18 | B35: 1C26TVC | C35: '45 | D35: 46216 | E35: Công ty cổ phần tư vấn xây dựng IN.CI.VI | F35: '0400780851 | G35: Tư vấn thẩm tra BCNCKT | H35: 44444444 | I35: 8 | J35: 3555556 | L35: GL | M35: '3123 | N35: 46295 | O35: 46295 | P35: 48000000 | Q35: ĐẦU TƯ XÂY DỰNG | R35: HIENNTK.HCM.VTA | S35: Not Reversed | T35: =IF(OR(LEN(F35)=11,LEN(F35)=15),"Đ","SAI") | U35: =ROUND(H35*I35%,0)-J35 | V35: =IF(Q35=$V$12,13313,13311)
A36: 19 | B36: 1C26TVC | C36: '46 | D36: 46216 | E36: Công ty cổ phần tư vấn xây dựng IN.CI.VI | F36: '0400780851 | G36: Tư vấn thẩm tra BCNCKT | H36: 44444444 | I36: 8 | J36: 3555556 | L36: GL | M36: '3123 | N36: 46295 | O36: 46295 | P36: 48000000 | Q36: ĐẦU TƯ XÂY DỰNG | R36: HIENNTK.HCM.VTA | S36: Not Reversed | T36: =IF(OR(LEN(F36)=11,LEN(F36)=15),"Đ","SAI") | U36: =ROUND(H36*I36%,0)-J36 | V36: =IF(Q36=$V$12,13313,13311)
A37: 20 | B37: 1C26TPT | C37: '132 | D37: 46252 | E37: Công ty TNHH kiểm toán quốc tế PNT | F37: '0102133859 | G37: Tư vấn kiểm toán | H37: 67334259 | I37: 8 | J37: 5386741 | L37: GL | M37: '3123 | N37: 46295 | O37: 46295 | P37: 72721000 | Q37: ĐẦU TƯ XÂY DỰNG | R37: HIENNTK.HCM.VTA | S37: Not Reversed | T37: =IF(OR(LEN(F37)=11,LEN(F37)=15),"Đ","SAI") | U37: =ROUND(H37*I37%,0)-J37 | V37: =IF(Q37=$V$12,13313,13311)
A38: 21 | B38: 1C26TAX | C38: '263 | D38: 46198 | E38: Công ty TNHH kiểm toán và tư vấn thuế ATAX | F38: '0400544325 | G38: Tư vấn kiểm toán | H38: 102777778 | I38: 8 | J38: 8222222 | L38: GL | M38: '3123 | N38: 46295 | O38: 46295 | P38: 111000000 | Q38: ĐẦU TƯ XÂY DỰNG | R38: HIENNTK.HCM.VTA | S38: Not Reversed | T38: =IF(OR(LEN(F38)=11,LEN(F38)=15),"Đ","SAI") | U38: =ROUND(H38*I38%,0)-J38 | V38: =IF(Q38=$V$12,13313,13311)
A39: 22 | B39: 1K26TAA | C39: '1104 | D39: 46240 | E39: TỔNG CÔNG TY ĐIỆN LỰC THÀNH PHỐ HỒ CHÍ MINH TNHH | F39: '0300951119 | G39: Điện mua nội bộ Tháng 7/2026 | H39: -108846181798 | I39: 8 | J39: 0 | K39: CK | L39: GL | M39: '3124 | N39: 46295 | O39: 46295 | P39: -108846181798 | Q39: Không xác định | R39: TUAN2HM.HCM.VTA | S39: Not Reversed | T39: =IF(OR(LEN(F39)=11,LEN(F39)=15),"Đ","SAI") | U39: =ROUND(H39*I39%,0)-J39 | V39: =IF(Q39=$V$12,13313,13311)
A40: 23 | B40: 1K26TAA | C40: '1335 | D40: 46271 | E40: TONG CONG TY DIEN LUC THANH PHO HO CHI MINH TNHH | F40: '0300951119 | G40: ĐIỆN MUA NỘI BỘ THÁNG 8/2026 | H40: 1255388267138 | I40: 8 | J40: 100431061371 | L40: GL | M40: '3125 | N40: 46295 | O40: 46295 | P40: 1355819328509 | Q40: Không xác định | R40: TUAN2HM.HCM.VTA | S40: Not Reversed | T40: =IF(OR(LEN(F40)=11,LEN(F40)=15),"Đ","SAI") | U40: =ROUND(H40*I40%,0)-J40 | V40: =IF(Q40=$V$12,13313,13311)
...

Sheet 13311
A1: TỔNG CÔNG TY ĐIỆN LỰC THÀNH PHỐ HỒ CHÍ MINH TNHH | K1: Tài khoản:
A2: CHI NHÁNH TỔNG CÔNG TY ĐIỆN LỰC THÀNH PHỐ HỒ CHÍ MINH TNHH - CÔNG TY ĐIỆN LỰC VŨNG TÀU | K2: 13311 | L2: =SUMIF($J:$J,$K2,$I:$I)
A3: SỔ CHI TIẾT THEO TÀI KHOẢN THUẾ | K3: 13313 | L3: =SUMIF($J:$J,$K3,$I:$I)
A4: Tài khoản: 1331 - Thuế GTGT được khấu trừ – Thuế GTGT được khấu trừ của hàng hoá, dịch vụ | K4: cuối kỳ 1331 | L4: =SUM(L2:L3)
A5: Loại hình: -
A6: Từ ngày: 01/09/2026 đến ngày: 30/09/2026
A9: CHỨNG TỪ | D9: DIỄN GIẢI | E9: PHÁT SINH NỢ | F9: PHÁT SINH CÓ | G9: Người hạch toán | H9: Trạng thái
A10: Ngày chứng từ | B10: Số chứng từ | C10: Nguồn chứng từ
A11: Tài khoản: 13311000000 | D11: Dư đầu kỳ | E11: 60549888887 | I11: =IF(LEN(A11)=5,E11,0) | J11: =IF(LEFT(A11,11)="Tài khoản: ",MID(A11,12,5),J10)
A12: 46272 | B12: 'R0926ĐTT0584 | C12: AR_REC | D12: Chuyển trả phí chuyển tiền T09/2026 BIDV HĐS 00025893-07/09/2026 | E12: 70000 | G12: QUYENNN.HCM.VTA | H12: Final to Post | I12: =IF(LEN(A12)=5,E12,0) | J12: =IF(LEFT(A12,11)="Tài khoản: ",MID(A12,12,5),J11)
A13: 46273 | B13: 'R0926ĐTT0588 | C13: AR_REC | D13: Chuyển trả phí chuyển tiền T09/2026+duy trì dịch vụ T08/2026 BIDV HĐS 00026077-08/09/2026 | E13: 75000 | G13: QUYENNN.HCM.VTA | H13: Final to Post | I13: =IF(LEN(A13)=5,E13,0) | J13: =IF(LEFT(A13,11)="Tài khoản: ",MID(A13,12,5),J12)
A14: 46279 | B14: 'R0926SC1051 | C14: AR_REC | D14: Chuyển TT tiền bảo vệ T8/26 cho CTy Chính Tín Nghĩa theo HĐơn 92-31/08/26 | E14: 10240000 | G14: HUENT.HCM.VTA | H14: Final to Post | I14: =IF(LEN(A14)=5,E14,0) | J14: =IF(LEFT(A14,11)="Tài khoản: ",MID(A14,12,5),J13)
A15: 46279 | B15: 'R0926ĐTT0602 | C15: AR_REC | D15: Chuyển trả phí quản lý tài khoản T09/2026 TK 7600265128 BIDV HĐS 00026747-14/09/2026 | E15: 5000 | G15: QUYENNN.HCM.VTA | H15: Final to Post | I15: =IF(LEN(A15)=5,E15,0) | J15: =IF(LEFT(A15,11)="Tài khoản: ",MID(A15,12,5),J14)
A16: 46280 | B16: 'C0926C265 | C16: AR_REC | D16: Thanh toán tiền rửa xe ôtô T08-2026 - Hóa đơn 786/28.08.26 | E16: 249600 | G16: THAOPTT.HCM.VTA | H16: Final to Post | I16: =IF(LEN(A16)=5,E16,0) | J16: =IF(LEFT(A16,11)="Tài khoản: ",MID(A16,12,5),J15)
A17: 46280 | B17: 'C0926C268 | C17: AR_REC | D17: Thanh toán tiền đặt ăn SXKD - Hóa đơn 64582/31.08.26 | E17: 285028 | G17: THAOPTT.HCM.VTA | H17: Final to Post | I17: =IF(LEN(A17)=5,E17,0) | J17: =IF(LEFT(A17,11)="Tài khoản: ",MID(A17,12,5),J16)
A18: 46280 | B18: 'C0926C269 | C18: AR_REC | D18: Thanh toán tiền thuê máy cuốc xử lý cáp ngầm hẻm 563 Ng An Ninh, P.Tam Thắng - Hóa đơn 24/26.08.26 | E18: 222222 | G18: THAOPTT.HCM.VTA | H18: Final to Post | I18: =IF(LEN(A18)=5,E18,0) | J18: =IF(LEFT(A18,11)="Tài khoản: ",MID(A18,12,5),J17)
A19: 46280 | B19: 'C0926C271 | C19: AR_REC | D19: Thanh toán tiền thuê máy cuốc xử lý cáp ngầm cổng CC Gateway; P.Tam Thắng - Hóa đơn 25/27.0.26 | E19: 222222 | G19: THAOPTT.HCM.VTA | H19: Final to Post | I19: =IF(LEN(A19)=5,E19,0) | J19: =IF(LEFT(A19,11)="Tài khoản: ",MID(A19,12,5),J18)
A20: 46281 | B20: 'R0926ĐTT0607 | C20: AR_REC | D20: Chuyển trả phí chuyển tiền T09/2026 BIDV HĐS 00026905-16/09/2026 | E20: 10000 | G20: QUYENNN.HCM.VTA | H20: Final to Post | I20: =IF(LEN(A20)=5,E20,0) | J20: =IF(LEFT(A20,11)="Tài khoản: ",MID(A20,12,5),J19)
A21: 46288 | B21: 'R0926AG056 | C21: AR_REC | D21: Thanh toán phí QLTK AGR T09-2026 | E21: 1500 | G21: THAOPTT.HCM.VTA | H21: Final to Post | I21: =IF(LEN(A21)=5,E21,0) | J21: =IF(LEFT(A21,11)="Tài khoản: ",MID(A21,12,5),J20)
A22: 46288 | B22: 'R0926NNT0623 | C22: AR_REC | D22: Chuyển trả phí quản lý tài khoản T09/2026 NH Nông Nghiệp HĐS 00447438-23/09/2026 | E22: 1500 | G22: QUYENNN.HCM.VTA | H22: Final to Post | I22: =IF(LEN(A22)=5,E22,0) | J22: =IF(LEFT(A22,11)="Tài khoản: ",MID(A22,12,5),J21)
A23: 46290 | B23: 'R0926ĐTT0629 | C23: AR_REC | D23: Chuyển trả phí chuyển tiền T09/2026 BIDV HĐS 00027547-25/09/2026 | E23: 40000 | G23: QUYENNN.HCM.VTA | H23: Final to Post | I23: =IF(LEN(A23)=5,E23,0) | J23: =IF(LEFT(A23,11)="Tài khoản: ",MID(A23,12,5),J22)
... A479: 46295 | B479: '3175 | C479: GL | D479: THUẾ GTGT ĐIỆN MTMN T02-2026 | E479: 45973 | G479: THAOPTT.HCM.VTA | H479: Post | I479: =IF(LEN(A479)=5,E479,0) | J479: =IF(LEFT(A479,11)="Tài khoản: ",MID(A479,12,5),J478)
A480: 46295 | B480: '3193 | C480: GL | D480: K/c thuế GTGT từ 1331 về 3331 tháng 9/2026 | F480: 102486905433 | G480: TUAN2HM.HCM.VTA | H480: Unpost | I480: =IF(LEN(A480)=5,E480,0) | J480: =IF(LEFT(A480,11)="Tài khoản: ",MID(A480,12,5),J479)
A481: 46295 | B481: 'R0926SC1160 | C481: AR_REC | D481: KHVT_Thanh toán tiền cước vận chuyển VTTB ra Côn Đảo - Hóa đơn 9140/18.09.26 | E481: 1684000 | G481: THAOPTT.HCM.VTA | H481: Final to Post | I481: =IF(LEN(A481)=5,E481,0) | J481: =IF(LEFT(A481,11)="Tài khoản: ",MID(A481,12,5),J480)
A482: 46295 | B482: 'R0926SC1165 | C482: AR_REC | D482: VPCT_PC Vũng Tàu chuyển tiền sửa chữa Phòng xét thầu - Hóa đơn 459/23.09.26 | E482: 2910800 | G482: THAOPTT.HCM.VTA | H482: Final to Post | I482: =IF(LEN(A482)=5,E482,0) | J482: =IF(LEFT(A482,11)="Tài khoản: ",MID(A482,12,5),J481)
D483: Cộng phát sinh | E483: 102486905433 | F483: 102486905433 | I483: =IF(LEN(A483)=5,E483,0) | J483: =IF(LEFT(A483,11)="Tài khoản: ",MID(A483,12,5),J482)
