Workbook

Sheet TAXVTA
A1: THUẾ ĐẦU VÀO
K2: C/LECH
A3: TA36 | C3: Tài khoản | D3: Doanh số | E3: thuế suất | F3: Tiền thuế | G3: Sau thuế | I3: TA30 | J3: Tiền thuế | K3: TA36-TA30
A4: TA36 | C4: 13311 | D4: =SUMIF('TA36'!$V:$V,TAXVTA!C4,'TA36'!$H:$H) -> 1321171020806 | F4: =SUMIF('TA36'!$V:$V,TAXVTA!C4,'TA36'!$J:$J) -> 105695245168 | G4: =+D4+F4 -> 1426866265974 | I4: TA30 | J4: ='13311'!L2 -> 105695245168 | K4: =+F4-J4 -> 0
A5: TA36 | C5: 13313 | D5: =SUMIF('TA36'!$V:$V,TAXVTA!C5,'TA36'!$H:$H) -> 22317143432 | F5: =SUMIF('TA36'!$V:$V,TAXVTA!C5,'TA36'!$J:$J) -> 1785491138 | G5: =+D5+F5 -> 24102634570 | I5: TA30 | J5: ='13311'!L3 -> 1785491138 | K5: =+F5-J5 -> 0
D6: =SUM(D4:D5) -> 1343488164238 | F6: =SUM(F4:F5) -> 107480736306 | G6: =SUM(G4:G5) -> 1450968900544 | J6: =SUM(J4:J5) -> 107480736306 | K6: =SUM(K4:K5) -> 0
C8: thuế đầu vào lên tờ khai | D8: Doanh số | E8: thuế suất | F8: Tiền thuế | G8: Sau thuế | O8: Tên hàng hóa, dịch vụ | P8: Giá trị hàng hóa, dịch vụ mua vào chưa có thuế GTGT được khấu trừ trong kỳ | Q8: Thuế GTGT của hàng hóa, dịch vụ mua vào được khấu trừ trong kỳ
D9: =SUMIFS('TA36'!$H:$H,'TA36'!$I:$I,TAXVTA!$E9) -> 26769800 | E9: 5 | F9: =SUMIFS('TA36'!$J:$J,'TA36'!$I:$I,TAXVTA!$E$9) -> 1338490 | G9: =D9+F9 -> 28108290 | O9: Hàng hóa dịnh vụ mua vào áp thuế suất 8% | P9: =D10 -> 1343337095251 | Q9: =F10 -> 107466967898
D10: =SUMIFS('TA36'!$H:$H,'TA36'!$I:$I,TAXVTA!$E10) -> 1343337095251 | E10: 8 | F10: =SUMIFS('TA36'!$J:$J,'TA36'!$I:$I,TAXVTA!$E10) -> 107466967898 | G10: =D10+F10 -> 1450804063149
D11: =SUMIFS('TA36'!$H:$H,'TA36'!$I:$I,TAXVTA!$E11) -> 124299187 | E11: 10 | F11: =SUMIFS('TA36'!$J:$J,'TA36'!$I:$I,TAXVTA!$E11) -> 12429918 | G11: =D11+F11 -> 136729105
D12: =SUM(D9:D11) -> 1343488164238 | F12: =SUM(F9:F11) -> 107480736306 | G12: =SUM(G9:G11) -> 1450968900544
D13: ='TA36'!X15 -> 1343488164238 | F13: ='TA36'!Y15 -> 107480736306
A14: THUẾ,ĐẦU,RA | D14: =+D12-D13 -> 0 | F14: =+F12-F13 -> 0
C15: DIEN01 | D15: DIEN01 | E15: DIEN01 | F15: DIEN01 | G15: CSPK02 | H15: CSPK02 | I15: CSPK02 | J15: CSPK02 | K15: DIEN00 | L15: DIEN00 | M15: DIEN00 | N15: DIEN00 | O15: CỘNG | P15: CỘNG | Q15: CỘNG | R15: CỘNG
C16: Doanh,số | D16: thuế,suất | E16: Tiền,thuế | F16: Sau,thuế | G16: Doanh,số | H16: thuế,suất | I16: Tiền,thuế | J16: Sau,thuế | K16: Doanh,số | L16: thuế,suất | M16: Tiền,thuế | N16: Sau,thuế | O16: Doanh,số | P16: thuế,suất | Q16: Tiền,thuế | R16: Sau,thuế
A17: KDGCS | B17: TRONGTHANG | C17: =GCS!H40 -> 654867197777 | E17: =GCS!I40 -> 52389375828 | F17: =GCS!J40 -> 707256573605 | G17: =+GCS!K35 -> 166049636 | I17: =GCS!L35 -> 13283972 | J17: =GCS!M35 -> 179333608 | K17: =GCS!H41 -> 158073900 | M17: 0 | N17: =GCS!J41 -> 158073900 | O17: =C17+G17+K17 -> 655191321313 | Q17: =+E17+I17 -> 52402659800 | R17: =+O17+Q17 -> 707593981113
A18: KDGCS | B18: CUOITHANG | C18: =+GCS!H47 -> 765642586406 | E18: =+GCS!I47 -> 61251406929 | F18: =GCS!J47 -> 826893993335 | G18: =+GCS!K36 -> 596561995 | I18: =GCS!L36 -> 47724956 | J18: =GCS!M36 -> 644286951 | K18: =GCS!H48 -> 95871352 | N18: =GCS!J48 -> 95871352 | O18: =+C18+G18+K18 -> 766335019753 | Q18: =+E18+I18 -> 61299131885 | R18: =+O18+Q18 -> 827634151638
C19: =SUM(C17:C18) -> 1420509784183 | E19: =SUM(E17:E18) -> 113640782757 | F19: =SUM(F17:F18) -> 1534150566940 | G19: =SUM(G17:G18) -> 762611631 | I19: =SUM(I17:I18) -> 61008928 | J19: =SUM(J17:J18) -> 823620559 | K19: =SUM(K17:K18) -> 253945252 | L19: =SUM(L17:L18) -> 0 | M19: =SUM(M17:M18) -> 0 | N19: =SUM(N17:N18) -> 253945252 | O19: =SUM(O17:O18) -> 1421526341066 | Q19: =SUM(Q17:Q18) -> 113701791685 | R19: =SUM(R17:R18) -> 1535228132751
A20: KD4A | C20: ='4A'!D13 -> 1420509784183 | E20: ='4A'!E13 -> 113640782757 | F20: ='4A'!F13 -> 1534150566940 | G20: =+'4A'!D9 -> 762611631 | I20: =+'4A'!E9 -> 61008928 | J20: =+'4A'!F9 -> 823620559 | K20: ='4A'!D12 -> 253945252 | M20: =+'4A'!I9 -> 0 | N20: ='4A'!F12 -> 253945252 | O20: =C20+G20+K20 -> 1421526341066 | Q20: =+E20+I20 -> 113701791685 | R20: =O20+Q20 -> 1535228132751
A21: c/lech | B21: GCS-4A | C21: =+C19-C20 -> 0 | D21: =+D19-D20 -> 0 | E21: =+E19-E20 -> 0 | F21: =+F19-F20 -> 0 | G21: =+G19-G20 -> 0 | H21: =+H19-H20 -> 0 | I21: =+I19-I20 -> 0 | J21: =+J19-J20 -> 0 | ... R21: =+R19-R20 -> 0
A23: GL0903 | C23: ='0903'!X3 -> 1420509784183 | G23: ='0903'!X4+'0903'!X1 -> 762611631 | K23: ='0903'!X2 -> 253945252 | O23: =SUM(C23:N23) -> 1421526341066
A24: c/lech | B24: KD4A-GL0903 | C24: =+C20-C23 -> 0 | G24: =+G20-G23 -> 0 | K24: =+K20-K23 -> 0 | O24: =+O20-O23 -> 0
A26: TA35 | D26: TA_035 | F26: GCS T4-2026 sang T5/26 HT | H26: GCS T5-2026 | J26: Chênh lệch
D27: Doanh số | E27: Tiền thuế | F27: Doanh số | G27: Tiền thuế | H27: Doanh số | I27: Tiền thuế | J27: Doanh số | K27: Tiền thuế
C28: DIEN00 | D28: =SUMIFS('TA35'!$H:$H,'TA35'!$T:$T,TAXVTA!$C28) -> 239893600 | E28: =SUMIFS('TA35'!$J:$J,'TA35'!$T:$T,TAXVTA!$C28) -> 0 | F28: 81819700 | H28: =GCS!H41 -> 158073900 | J28: =D28-F28-H28 -> 0 | K28: =E28-G28-I28 -> 0
C29: DIEN01 | D29: =SUMIFS('TA35'!$H:$H,'TA35'!$T:$T,TAXVTA!$C29) -> 1356716633174 | E29: =SUMIFS('TA35'!$J:$J,'TA35'!$T:$T,TAXVTA!$C29) -> 108537330869 | F29: 701849435397 | G29: 56147955041 | H29: =GCS!H40 -> 654867197777 | I29: =GCS!I40 -> 52389375828 | J29: =D29-F29-H29 -> 0 | K29: =E29-G29-I29 -> 0
C30: CSPK02 | D30: =SUMIFS('TA35'!$H:$H,'TA35'!$T:$T,TAXVTA!$C30)+'TA35'!W5 -> 641477615 | E30: =SUMIFS('TA35'!$J:$J,'TA35'!$T:$T,TAXVTA!$C30) -> 51318199 | F30: 475427979 | G30: 38034227 | H30: =GCS!L42 -> 166049636 | I30: =GCS!M40 -> 13283972 | J30: =D30-F30-H30 -> 0 | K30: =E30-G30-I30 -> 0
C31: 1388ĐĐ | D31: =SUMIFS('TA35'!$H:$H,'TA35'!$T:$T,TAXVTA!$C31) -> 4451010687 | E31: =SUMIFS('TA35'!$J:$J,'TA35'!$T:$T,TAXVTA!$C31) -> 356080855
C32: 5118QT | D32: =SUMIFS('TA35'!$H:$H,'TA35'!$T:$T,TAXVTA!$C32) -> 0 | E32: =SUMIFS('TA35'!$J:$J,'TA35'!$T:$T,TAXVTA!$C32) -> 0
C33: 4500TT | D33: =SUMIFS('TA35'!$H:$H,'TA35'!$T:$T,TAXVTA!$C33) -> 253573360 | E33: =SUMIFS('TA35'!$J:$J,'TA35'!$T:$T,TAXVTA!$C33) -> 20285870
C34: Cộng | D34: =SUM(D28:D33) -> 1362302588436 | E34: =SUM(E28:E33) -> 108965015793 | F34: =SUM(F28:F33) -> 702406683076 | G34: =SUM(G28:G33) -> 56185989268 | H34: =SUM(H28:H33) -> 655191321313 | I34: =SUM(I28:I33) -> 52402659800 | J34: =SUM(J28:J33) -> 0 | K34: =SUM(K28:K33) -> 0
A36: GL33895 (GL_038) | E36: =SUMIFS('33895'!$K:$K,'33895'!$J:$J,TAXVTA!C$15) -> 61251406929 | I36: =SUMIFS('33895'!$K:$K,'33895'!$J:$J,TAXVTA!G$15) -> 47724956 | Q36: =+E36+I36 -> 61299131885
A37: c/lech | B37: KDGCS-GL33895 | E37: =+E18-E36 -> 0 | I37: =+I18-I36 -> 0 | Q37: =+Q18-Q36 -> 0
D38: Doanh số | E38: Tiền thuế
A39: TA030 | B39: TK333111 | D39: ='333111'!M2 -> 52389375828 | E39: =+'333111'!M7 -> 52402659800
A40: c/lech | B40: KDGCS-TA30 | D40: =E17-D39 -> 0 | E40: =D40+G29 -> 56147955041
A41: c/lech | B41: TA35-TA30 | D41: =D39-E29 -> -56147955041
O43: Tên hàng hóa, dịch vụ | P43: Giá trị hàng hóa, dịch vụ chưa có thuế GTGT | Q43: Thuế GTGT của hàng hóa, dịch vụ bán ra được giảm
B44: Thuế đầu ra lên tờ khai | C44: Doanh,số | D44: thuế,suất | E44: Tiền,thuế | F44: Sau,thuế | M44: NHẬP LÊN TỜ KHÁI THUẾ THÁNG | O44: Hoạt động kinh doanh điện | P44: =C46+C48 -> 1357358110789 | Q44: =E46+E48 -> 108588649068
A45: Điện | B45: DIEN00 | C45: =SUMIFS('TA35'!$H:$H,'TA35'!$T:$T,TAXVTA!B45,'TA35'!$I:$I,TAXVTA!D45) -> 239893600 | D45: 0 | E45: =SUMIFS('TA35'!$J:$J,'TA35'!$T:$T,TAXVTA!B45,'TA35'!$I:$I,TAXVTA!D45) -> 0 | F45: =C45+E45 -> 239893600 | K45: 91678635810 | O45: Điều động vật tư thiết bị | P45: =C49 -> 4451010687 | Q45: =E49 -> 356080855
...

Sheet GCS
A2: TỔNG CÔNG TY ĐIỆN LỰC THÀNH PHỐ HỒ CHÍ MINH TNHH
A3: CÔNG TY ĐIỆN LỰC VŨNG TÀU
A5: BÁO CÁO TỔNG HỢP THEO NGÀY GHI CHỈ SỐ VÀ PHÁT HÀNH HÓA ĐƠN
A6: Tháng năm: 04/2026
A8: Stt | B8: Ngày ghi | C8: Số sổ GCS | D8: Số hóa đơn | E8: Ngày phát hành hóa đơn | F8: Điện năng tiêu thụ | I8: Tiền điện tác dụng | J8: Thuế điện tác dụng | K8: Tổng tiền điện tác dụng | L8: Tiền CSPK | M8: Thuế CSPK | N8: Tổng tiền CSPK | O8: Tổng cộng
F9: SH | G9: Ngoài SH | H9: Tổng
A10: Loại hoá đơn : Hủy bỏ
A11: 1 | B11: =INDEX('[1]1,8-PH_GCS'!C2:C12,1,1) -> 31/03/2026 | C11: =INDEX('[1]1,8-PH_GCS'!$B2:$N12,1,1) -> 1 | D11: =INDEX('[1]1,8-PH_GCS'!$B2:$N12,1,3) -> 1 | E11: =B11 -> 31/03/2026 | F11: =INDEX('[1]1,8-PH_GCS'!$B2:$N12,1,5) -> 0 | G11: =INDEX('[1]1,8-PH_GCS'!$B2:$N12,1,6) -> -1879 | H11: =INDEX('[1]1,8-PH_GCS'!$B2:$N12,1,4) -> -1879 | I11: =INDEX('[1]1,8-PH_GCS'!$B2:$N12,1,7) -> -6680400 | J11: =INDEX('[1]1,8-PH_GCS'!$B2:$N12,1,8) -> -534432 | K11: =INDEX('[1]1,8-PH_GCS'!$B2:$N12,1,9) -> -7214832 | L11: =INDEX('[1]1,8-PH_GCS'!$B2:$N12,1,10) -> 0 | M11: =INDEX('[1]1,8-PH_GCS'!$B2:$N12,1,11) -> 0 | N11: =INDEX('[1]1,8-PH_GCS'!$B2:$N12,1,12) -> 0 | O11: =INDEX('[1]1,8-PH_GCS'!$B2:$N12,1,13) -> -7214832 | P11: TRONGTHANG
A12: 2 | B12: =INDEX('[1]1,8-PH_GCS'!C3:C13,1,1) -> 31/05/2026 | C12: =INDEX('[1]1,8-PH_GCS'!$B3:$N13,1,1) -> 35 | D12: =INDEX('[1]1,8-PH_GCS'!$B3:$N13,1,3) -> 98 | E12: =B12 -> 31/05/2026 | F12: =INDEX('[1]1,8-PH_GCS'!$B3:$N13,1,5) -> -26677 | G12: =INDEX('[1]1,8-PH_GCS'!$B3:$N13,1,6) -> -57257 | H12: =INDEX('[1]1,8-PH_GCS'!$B3:$N13,1,4) -> -83934 | I12: =INDEX('[1]1,8-PH_GCS'!$B3:$N13,1,7) -> -223276078 | J12: =INDEX('[1]1,8-PH_GCS'!$B3:$N13,1,8) -> -17862090 | K12: =INDEX('[1]1,8-PH_GCS'!$B3:$N13,1,9) -> -241138168 | L12: =INDEX('[1]1,8-PH_GCS'!$B3:$N13,1,10) -> 0 | M12: =INDEX('[1]1,8-PH_GCS'!$B3:$N13,1,11) -> 0 | N12: =INDEX('[1]1,8-PH_GCS'!$B3:$N13,1,12) -> 0 | O12: =INDEX('[1]1,8-PH_GCS'!$B3:$N13,1,13) -> -241138168 | P12: TRONGTHANG
A13: Tổng số | C13: =SUM(C11:C12) -> 36 | D13: =SUM(D11:D12) -> 99 | F13: =SUM(F11:F12) -> -26677 | G13: =SUM(G11:G12) -> -59136 | H13: =SUM(H11:H12) -> -85813 | I13: =SUM(I11:I12) -> -229956478 | J13: =SUM(J11:J12) -> -18396522 | K13: =SUM(K11:K12) -> -248353000 | L13: =SUM(L11:L12) -> 0 | M13: =SUM(M11:M12) -> 0 | ... O13: =SUM(O11:O12) -> -248353000
A14: Loại hoá đơn : Lặp lại
A15: 3 | B15: =INDEX('[1]1,8-PH_GCS'!C4:C16,1,1) -> 30/04/2026 | C15: =INDEX('[1]1,8-PH_GCS'!$B4:$N16,1,1) -> 1 | D15: =INDEX('[1]1,8-PH_GCS'!$B4:$N16,1,3) -> 1 | E15: =B15 -> 30/04/2026 | F15: =INDEX('[1]1,8-PH_GCS'!$B4:$N16,1,5) -> 0 | G15: =INDEX('[1]1,8-PH_GCS'!$B4:$N16,1,6) -> 1540 | H15: =INDEX('[1]1,8-PH_GCS'!$B4:$N16,1,4) -> 1540 | I15: =INDEX('[1]1,8-PH_GCS'!$B4:$N16,1,7) -> 5326506 | J15: =INDEX('[1]1,8-PH_GCS'!$B4:$N16,1,8) -> 426120 | K15: =INDEX('[1]1,8-PH_GCS'!$B4:$N16,1,9) -> 5752626 | L15: =INDEX('[1]1,8-PH_GCS'!$B4:$N16,1,10) -> 0 | M15: =INDEX('[1]1,8-PH_GCS'!$B4:$N16,1,11) -> 0 | N15: =INDEX('[1]1,8-PH_GCS'!$B4:$N16,1,12) -> 0 | O15: =INDEX('[1]1,8-PH_GCS'!$B4:$N16,1,13) -> 5752626 | P15: TRONGTHANG
A16: 4 | B16: =INDEX('[1]1,8-PH_GCS'!C5:C17,1,1) -> 31/05/2026 | C16: =INDEX('[1]1,8-PH_GCS'!$B5:$N17,1,1) -> 35 | D16: =INDEX('[1]1,8-PH_GCS'!$B5:$N17,1,3) -> 98 | E16: =B16 -> 31/05/2026 | F16: =INDEX('[1]1,8-PH_GCS'!$B5:$N17,1,5) -> 11718 | G16: =INDEX('[1]1,8-PH_GCS'!$B5:$N17,1,6) -> 143003 | H16: =INDEX('[1]1,8-PH_GCS'!$B5:$N17,1,4) -> 154721 | I16: =INDEX('[1]1,8-PH_GCS'!$B5:$N17,1,7) -> 453677616 | J16: =INDEX('[1]1,8-PH_GCS'!$B5:$N17,1,8) -> 36294207 | K16: =INDEX('[1]1,8-PH_GCS'!$B5:$N17,1,9) -> 489971823 | L16: =INDEX('[1]1,8-PH_GCS'!$B5:$N17,1,10) -> 0 | M16: =INDEX('[1]1,8-PH_GCS'!$B5:$N17,1,11) -> 0 | N16: =INDEX('[1]1,8-PH_GCS'!$B5:$N17,1,12) -> 0 | O16: =INDEX('[1]1,8-PH_GCS'!$B5:$N17,1,13) -> 489971823 | P16: TRONGTHANG
A17: Tổng số: | C17: =SUM(C15:C16) -> 36 | D17: =SUM(D15:D16) -> 99 | F17: =SUM(F15:F16) -> 11718 | G17: =SUM(G15:G16) -> 144543 | H17: =SUM(H15:H16) -> 156261 | I17: =SUM(I15:I16) -> 459004122 | J17: =SUM(J15:J16) -> 36720327 | K17: =SUM(K15:K16) -> 495724449 | L17: =SUM(L15:L16) -> 0 | M17: =SUM(M15:M16) -> 0 | ... O17: =SUM(O15:O16) -> 495724449
A18: Loại hoá đơn : Phát sinh
A19: 5 | B19: =INDEX('[1]1,8-PH_GCS'!C6:C21,1,1) -> 10/05/2026 | C19: =INDEX('[1]1,8-PH_GCS'!$B6:$N21,1,1) -> 22 | D19: =INDEX('[1]1,8-PH_GCS'!$B6:$N21,1,3) -> 431 | E19: 46153 | F19: =INDEX('[1]1,8-PH_GCS'!$B6:$N21,1,5) -> 1582 | G19: =INDEX('[1]1,8-PH_GCS'!$B6:$N21,1,6) -> 167584009 | H19: =INDEX('[1]1,8-PH_GCS'!$B6:$N21,1,4) -> 167585591 | I19: =INDEX('[1]1,8-PH_GCS'!$B6:$N21,1,7) -> 318577781957 | J19: =INDEX('[1]1,8-PH_GCS'!$B6:$N21,1,8) -> 25480346999 | K19: =INDEX('[1]1,8-PH_GCS'!$B6:$N21,1,9) -> 344058128956 | L19: =INDEX('[1]1,8-PH_GCS'!$B6:$N21,1,10) -> 63034452 | M19: =INDEX('[1]1,8-PH_GCS'!$B6:$N21,1,11) -> 5042756 | N19: =INDEX('[1]1,8-PH_GCS'!$B6:$N21,1,12) -> 68077208 | O19: =INDEX('[1]1,8-PH_GCS'!$B6:$N21,1,13) -> 344126206164 | P19: TRONGTHANG
A20: 6 | B20: =INDEX('[1]1,8-PH_GCS'!C7:C22,1,1) -> 15/05/2026 | C20: =INDEX('[1]1,8-PH_GCS'!$B7:$N22,1,1) -> 8 | D20: =INDEX('[1]1,8-PH_GCS'!$B7:$N22,1,3) -> 188 | E20: 46158 | F20: =INDEX('[1]1,8-PH_GCS'!$B7:$N22,1,5) -> 7650 | G20: =INDEX('[1]1,8-PH_GCS'!$B7:$N22,1,6) -> 5519709 | H20: =INDEX('[1]1,8-PH_GCS'!$B7:$N22,1,4) -> 5527359 | I20: =INDEX('[1]1,8-PH_GCS'!$B7:$N22,1,7) -> 13249288139 | J20: =INDEX('[1]1,8-PH_GCS'!$B7:$N22,1,8) -> 1059943044 | K20: =INDEX('[1]1,8-PH_GCS'!$B7:$N22,1,9) -> 14309231183 | L20: =INDEX('[1]1,8-PH_GCS'!$B7:$N22,1,10) -> 34333124 | M20: =INDEX('[1]1,8-PH_GCS'!$B7:$N22,1,11) -> 2746651 | N20: =INDEX('[1]1,8-PH_GCS'!$B7:$N22,1,12) -> 37079775 | O20: =INDEX('[1]1,8-PH_GCS'!$B7:$N22,1,13) -> 14346310958 | P20: TRONGTHANG
A21: 7 | B21: =INDEX('[1]1,8-PH_GCS'!C8:C23,1,1) -> 20/05/2026 | C21: =INDEX('[1]1,8-PH_GCS'!$B8:$N23,1,1) -> 21 | D21: =INDEX('[1]1,8-PH_GCS'!$B8:$N23,1,3) -> 435 | E21: 46163 | F21: =INDEX('[1]1,8-PH_GCS'!$B8:$N23,1,5) -> 1648 | G21: =INDEX('[1]1,8-PH_GCS'!$B8:$N23,1,6) -> 167498187 | H21: =INDEX('[1]1,8-PH_GCS'!$B8:$N23,1,4) -> 167499835 | I21: =INDEX('[1]1,8-PH_GCS'!$B8:$N23,1,7) -> 322724399951 | J21: =INDEX('[1]1,8-PH_GCS'!$B8:$N23,1,8) -> 25811181662 | K21: =INDEX('[1]1,8-PH_GCS'!$B8:$N23,1,9) -> 348535581613 | L21: =INDEX('[1]1,8-PH_GCS'!$B8:$N23,1,10) -> 68682060 | M21: =INDEX('[1]1,8-PH_GCS'!$B8:$N23,1,11) -> 5494565 | N21: =INDEX('[1]1,8-PH_GCS'!$B8:$N23,1,12) -> 74176625 | O21: =INDEX('[1]1,8-PH_GCS'!$B8:$N23,1,13) -> 348609758238 | P21: TRONGTHANG
A22: 8 | B22: =INDEX('[1]1,8-PH_GCS'!C9:C24,1,1) -> 31/05/2026 | C22: =INDEX('[1]1,8-PH_GCS'!$B9:$N24,1,1) -> 2027 | D22: =INDEX('[1]1,8-PH_GCS'!$B9:$N24,1,3) -> 237233 | E22: 46175 | F22: =INDEX('[1]1,8-PH_GCS'!$B9:$N24,1,5) -> 95846215 | G22: =INDEX('[1]1,8-PH_GCS'!$B9:$N24,1,6) -> 238508165 | H22: =INDEX('[1]1,8-PH_GCS'!$B9:$N24,1,4) -> 334354380 | I22: =INDEX('[1]1,8-PH_GCS'!$B9:$N24,1,7) -> 765738457758 | J22: =INDEX('[1]1,8-PH_GCS'!$B9:$N24,1,8) -> 61251406929 | K22: =INDEX('[1]1,8-PH_GCS'!$B9:$N24,1,9) -> 826989864687 | L22: =INDEX('[1]1,8-PH_GCS'!$B9:$N24,1,10) -> 596561995 | M22: =INDEX('[1]1,8-PH_GCS'!$B9:$N24,1,11) -> 47724956 | N22: =INDEX('[1]1,8-PH_GCS'!$B9:$N24,1,12) -> 644286951 | O22: =INDEX('[1]1,8-PH_GCS'!$B9:$N24,1,13) -> 827634151638 | P22: CUOITHANG
A23: Tổng số: | C23: =SUM(C19:C22) -> 2078 | D23: =SUM(D19:D22) -> 238287 | F23: =SUM(F19:F22) -> 95857095 | G23: =SUM(G19:G22) -> 579110070 | H23: =SUM(H19:H22) -> 674967165 | I23: =SUM(I19:I22) -> 1420289927805 | J23: =SUM(J19:J22) -> 113602878634 | K23: =SUM(K19:K22) -> 1533892806439 | L23: =SUM(L19:L22) -> 762611631 | M23: =SUM(M19:M22) -> 61008928 | ... O23: =SUM(O19:O22) -> 1534716426998
A24: Loại hoá đơn : Thoái hoàn
A25: 9 | B25: =INDEX('[1]1,8-PH_GCS'!C10:C27,1,1) -> 31/05/2026 | C25: =INDEX('[1]1,8-PH_GCS'!$B10:$N27,1,1) -> 10 | D25: =INDEX('[1]1,8-PH_GCS'!$B10:$N27,1,3) -> 10 | E25: 46173 | F25: =INDEX('[1]1,8-PH_GCS'!$B10:$N27,1,5) -> -3655 | G25: =INDEX('[1]1,8-PH_GCS'!$B10:$N27,1,6) -> -8219 | H25: =INDEX('[1]1,8-PH_GCS'!$B10:$N27,1,4) -> -11874 | I25: =INDEX('[1]1,8-PH_GCS'!$B10:$N27,1,7) -> -37491358 | J25: =INDEX('[1]1,8-PH_GCS'!$B10:$N27,1,8) -> -2999309 | K25: =INDEX('[1]1,8-PH_GCS'!$B10:$N27,1,9) -> -40490667 | L25: =INDEX('[1]1,8-PH_GCS'!$B10:$N27,1,10) -> 0 | M25: =INDEX('[1]1,8-PH_GCS'!$B10:$N27,1,11) -> 0 | N25: =INDEX('[1]1,8-PH_GCS'!$B10:$N27,1,12) -> 0 | O25: =INDEX('[1]1,8-PH_GCS'!$B10:$N27,1,13) -> -40490667 | P25: TRONGTHANG
A26: Tổng số: | C26: =SUM(C25:C25) -> 10 | D26: =SUM(D25:D25) -> 10 | E26: =SUM(E25:E25) -> 46173 | F26: =SUM(F25:F25) -> -3655 | G26: =SUM(G25:G25) -> -8219 | H26: =SUM(H25:H25) -> -11874 | I26: =SUM(I25:I25) -> -37491358 | J26: =SUM(J25:J25) -> -2999309 | ... O26: =SUM(O25:O25) -> -40490667
A27: Loại hoá đơn : Truy thu
A28: 10 | B28: =INDEX('[1]1,8-PH_GCS'!C11:C33,1,1) -> 10/05/2026 | C28: =INDEX('[1]1,8-PH_GCS'!$B11:$N33,1,1) -> 2 | D28: =INDEX('[1]1,8-PH_GCS'!$B11:$N33,1,3) -> 15 | E28: 46153 | F28: =INDEX('[1]1,8-PH_GCS'!$B11:$N33,1,5) -> 0 | G28: =INDEX('[1]1,8-PH_GCS'!$B11:$N33,1,6) -> 13398 | H28: =INDEX('[1]1,8-PH_GCS'!$B11:$N33,1,4) -> 13398 | I28: =INDEX('[1]1,8-PH_GCS'!$B11:$N33,1,7) -> 27790994 | J28: =INDEX('[1]1,8-PH_GCS'!$B11:$N33,1,8) -> 2223280 | K28: =INDEX('[1]1,8-PH_GCS'!$B11:$N33,1,9) -> 30014274 | L28: =INDEX('[1]1,8-PH_GCS'!$B11:$N33,1,10) -> 0 | M28: =INDEX('[1]1,8-PH_GCS'!$B11:$N33,1,11) -> 0 | N28: =INDEX('[1]1,8-PH_GCS'!$B11:$N33,1,12) -> 0 | O28: =INDEX('[1]1,8-PH_GCS'!$B11:$N33,1,13) -> 30014274 | P28: TRONGTHANG
A29: 11 | B29: =INDEX('[1]1,8-PH_GCS'!C12:C34,1,1) -> 31/05/2026 | C29: =INDEX('[1]1,8-PH_GCS'!$B12:$N34,1,1) -> 43 | D29: =INDEX('[1]1,8-PH_GCS'!$B12:$N34,1,3) -> 92 | E29: 46173 | F29: =INDEX('[1]1,8-PH_GCS'!$B12:$N34,1,5) -> 24701 | G29: =INDEX('[1]1,8-PH_GCS'!$B12:$N34,1,6) -> 68320 | H29: =INDEX('[1]1,8-PH_GCS'!$B12:$N34,1,4) -> 93021 | I29: =INDEX('[1]1,8-PH_GCS'!$B12:$N34,1,7) -> 254454350 | J29: =INDEX('[1]1,8-PH_GCS'!$B12:$N34,1,8) -> 20356347 | K29: =INDEX('[1]1,8-PH_GCS'!$B12:$N34,1,9) -> 274810697 | L29: =INDEX('[1]1,8-PH_GCS'!$B12:$N34,1,10) -> 0 | M29: =INDEX('[1]1,8-PH_GCS'!$B12:$N34,1,11) -> 0 | N29: =INDEX('[1]1,8-PH_GCS'!$B12:$N34,1,12) -> 0 | O29: =INDEX('[1]1,8-PH_GCS'!$B12:$N34,1,13) -> 274810697 | P29: TRONGTHANG
A30: Tổng số: | C30: =SUM(C28:C29) -> 45 | D30: =SUM(D28:D29) -> 107 | E30: =SUM(E28:E29) -> 92326 | F30: =SUM(F28:F29) -> 24701 | G30: =SUM(G28:G29) -> 81718 | H30: =SUM(H28:H29) -> 106419 | I30: =SUM(I28:I29) -> 282245344 | J30: =SUM(J28:J29) -> 22579627 | ... O30: =SUM(O28:O29) -> 304824971
A31: Tổng số: | C31: =C13+C17+C23+C26+C30 -> 2205 | D31: =D13+D17+D23+D26+D30 -> 238602 | F31: =F13+F17+F23+F26+F30 -> 95863182 | G31: =G13+G17+G23+G26+G30 -> 579268976 | H31: =H13+H17+H23+H26+H30 -> 675132158 | I31: =I13+I17+I23+I26+I30 -> 1420763729435 | J31: =J13+J17+J23+J26+J30 -> 113640782757 | K31: =K13+K17+K23+K26+K30 -> 1534404512192 | L31: =L13+L17+L23+L26+L30 -> 762611631 | M31: =M13+M17+M23+M26+M30 -> 61008928 | ... O31: =O13+O17+O23+O26+O30 -> 1535228132751
H33: TIENDIEN | I33: THUE DIEN | J33: TONG | K33: CSPK | L33: THUE CSPK | M33: TONG CSPK
G35: TRONGTHANG | H35: =SUMIF($P:$P,G35,$I:$I) -> 655025271677 | I35: =SUMIF($P:$P,G35,$J:$J) -> 52389375828 | J35: =SUMIF($P:$P,G35,$K:$K) -> 707414647505 | K35: =SUMIF($P:$P,G35,$L:$L) -> 166049636 | L35: =SUMIF($P:$P,G35,$M:$M) -> 13283972 | M35: =SUMIF($P:$P,G35,$N:$N) -> 179333608 | N35: =SUMIF($P:$P,G35,$O:$O) -> 707593981113
G36: CUOITHANG | H36: =SUMIF($P:$P,G36,$I:$I) -> 765738457758 | I36: =SUMIF($P:$P,G36,$J:$J) -> 61251406929 | J36: =SUMIF($P:$P,G36,$K:$K) -> 826989864687 | K36: =SUMIF($P:$P,G36,$L:$L) -> 596561995 | L36: =SUMIF($P:$P,G36,$M:$M) -> 47724956 | M36: =SUMIF($P:$P,G36,$N:$N) -> 644286951 | N36: =SUMIF($P:$P,G36,$O:$O) -> 827634151638
H37: =SUM(H35:H36) -> 1420763729435 | I37: =SUM(I35:I36) -> 113640782757 | J37: =SUM(J35:J36) -> 1534404512192 | K37: =SUM(K35:K36) -> 762611631 | L37: =SUM(L35:L36) -> 61008928 | M37: =SUM(M35:M36) -> 823620559 | N37: =SUM(N35:N36) -> 1535228132751
H38: =H37-D56-D58 -> 0 | I38: =I37-E56 -> 0 | J38: =J37-F56-F58 -> 0 | K38: =K37-D57 -> 0 | L38: =L37-E57 -> 0 | M38: =M37-F57 -> 0 | N38: =N37-F60 -> 0
E39: Trong đó | F39: TRONGTHANG
G40: DIEN01 | H40: =H35-H41 -> 654867197777 | I40: =I35-I41 -> 52389375828 | J40: =J35-J41 -> 707256573605 | L40: =K35-L41 -> 166049636 | M40: =L35 -> 13283972 | N40: =L40+M40 -> 179333608 | O40: CSPK02
G41: DIEN00 | H41: ='Nhom TC'!O1 -> 158073900 | I41: 0 | J41: =H41+I41 -> 158073900 | M41: 0 | N41: =L41+M41 -> 0 | O41: CSPK00
H42: =SUM(H40:H41) -> 655025271677 | I42: =SUM(I40:I41) -> 52389375828 | J42: =SUM(J40:J41) -> 707414647505 | L42: =SUM(L40:L41) -> 166049636 | M42: =SUM(M40:M41) -> 13283972 | N42: =L42+M42 -> 179333608
H43: =H35-H42 -> 0 | I43: =I35-I42 -> 0 | J43: =J35-J42 -> 0
G44: CSPK02 | K44: =K35 -> 166049636 | L44: =L35 -> 13283972 | M44: =M35 -> 179333608 | N44: =N35 -> 707593981113
H45: =+H42+H44-H35 -> 0 | I45: =+I42+I44-I35 -> 0 | J45: =+J42+J44-J35 -> 0 | K45: =+K42+K44-K35 -> 0 | L45: =+L42+L44-L35 -> 166049636 | M45: =+M42+M44-M35 -> 13283972 | N45: =+N42+N44-N35 -> 179333608
...

Sheet 0903
A1: HCMC - Công ty Điện lực Vũng Tàu | W1: CSPK00 | X1: =SUMIF($V:$V,$W1,$O:$O) -> 0
W2: DIEN00 | X2: =SUMIF($V:$V,$W2,$O:$O) -> 253945252
A3: Báo cáo liệt kê giao dịch phát sinh theo tài khoản | W3: DIEN01 | X3: =SUMIF($V:$V,$W3,$O:$O) -> 1420509784183
A4: Từ ngày 01/05/2026 đến ngày 31/05/2026 | W4: CSPK02 | X4: =SUMIF($V:$V,$W4,$O:$O) -> 762611631
W5: 1388DD | X5: =SUMIF($V:$V,$W5,$O:$O) -> 0 | Y5: vật tư điều động
A6: Nguồn phát sinh | B6: Số giao dịch | C6: Ngày giao dịch | D6: Chi nhánh | E6: Trung tâm chi phí | F6: Tài khoản | G6: Loại hình | H6: Sản phẩm | I6: Yếu tố | J6: Đơn vị nội bộ | K6: Dự phòng đơn vị | L6: Dự phòng EVN | M6: Loại tiền | N6: Nợ nguyên tệ | O6: Có nguyên tệ | P6: Nợ quy đổi | Q6: Có quy đổi | R6: Nội dung | S6: Trạng thái hạch toán | T6: Người tạo | U6: Người cập nhật | W6: 5118QT | X6: =SUMIF($V:$V,$W6,$O:$O) -> 0 | Y6: quà tặng
A7: AR_TRANSACTIONS | B7: 1632 | C7: 46168 | D7: 000000 | E7: 000 | F7: 51140000000 | G7: 4500 | H7: 0000 | I7: 000 | J7: 000000 | K7: 0000 | L7: 0000 | M7: VND | O7: 57336523 | Q7: 57336523 | R7: 4500TT - Doanh thu cho thuê cột điện treo cáp viễn thông từ 01/05/26 đến 31/05/26 - HĐ 43/26.05.26 | S7: D | T7: CHAULTN.HCM.VTA | U7: CHAULTN.HCM.VTA | V7: =LEFT(R7,6) -> 4500TT | W7: 4500TT | X7: =SUMIF($V:$V,$W7,$O:$O) -> 253573360 | Y7: dường dây thông tin
A8: AR_TRANSACTIONS | B8: 1624 | C8: 46158 | D8: 000000 | E8: 000 | F8: 51113000000 | G8: 1310 | H8: 0000 | I8: 000 | J8: 000000 | K8: 0000 | L8: 0000 | M8: VND | O8: 34333124 | Q8: 34333124 | R8: CSPK02-DOANH THU HÓA ĐƠN TIỀN VÔ CÔNG PHÁT SINH TỪ NGÀY 16/05/2026 ĐẾN 16/05/2026 | S8: D | T8: QUYENNN.HCM.VTA | U8: QUYENNN.HCM.VTA | V8: =LEFT(R8,6) -> CSPK02 | X8: =SUM(X2:X7) -> 1421779914426
A9: AR_TRANSACTIONS | B9: 1625 | C9: 46163 | D9: 000000 | E9: 000 | F9: 51111000000 | G9: 1310 | H9: 0000 | I9: 000 | J9: 000000 | K9: 0000 | L9: 0000 | M9: VND | O9: 322639770751 | Q9: 322639770751 | R9: DIEN01-DOANH THU HÓA ĐƠN TIỀN ĐIỆN PHÁT SINH TỪ NGÀY 21/05/2026 ĐẾN 21/05/2026 | S9: D | T9: QUYENNN.HCM.VTA | U9: QUYENNN.HCM.VTA | V9: =LEFT(R9,6) -> DIEN01
A10: AR_TRANSACTIONS | B10: 1626 | C10: 46163 | D10: 000000 | E10: 000 | F10: 51113000000 | G10: 1310 | H10: 0000 | I10: 000 | J10: 000000 | K10: 0000 | L10: 0000 | M10: VND | O10: 68682060 | Q10: 68682060 | R10: CSPK02-DOANH THU HÓA ĐƠN TIỀN VÔ CÔNG PHÁT SINH TỪ NGÀY 21/05/2026 ĐẾN 21/05/2026 | S10: D | T10: QUYENNN.HCM.VTA | U10: QUYENNN.HCM.VTA | V10: =LEFT(R10,6) -> CSPK02
A11: AR_TRANSACTIONS | B11: 1627 | C11: 46163 | D11: 000000 | E11: 000 | F11: 51111000000 | G11: 1310 | H11: 0000 | I11: 000 | J11: 000000 | K11: 0000 | L11: 0000 | M11: VND | O11: 84629200 | Q11: 84629200 | R11: DIEN00-DOANH THU HÓA ĐƠN TIỀN ĐIỆN PHÁT SINH-CT TNHH NHÔM TOÀN CẦU VIỆT NAM KỲ 2/5/2026 | S11: D | T11: QUYENNN.HCM.VTA | U11: QUYENNN.HCM.VTA | V11: =LEFT(R11,6) -> DIEN00
A12: AR_TRANSACTIONS | B12: 1646 | C12: 46168 | D12: 000000 | E12: 000 | F12: 51140000000 | G12: 4500 | H12: 0000 | I12: 000 | J12: 000000 | K12: 0000 | L12: 0000 | M12: VND | O12: 150296766 | Q12: 150296766 | R12: 4500TT - Doanh thu cho thuê cột điện treo cáp viễn thông tháng 05/2026 - HĐ 45 ngày 26/05/2026 | S12: D | T12: CHAULTN.HCM.VTA | U12: CHAULTN.HCM.VTA | V12: =LEFT(R12,6) -> 4500TT
A13: AR_TRANSACTIONS | B13: 1615 | C13: 46153 | D13: 000000 | E13: 000 | F13: 51111000000 | G13: 1310 | H13: 0000 | I13: 000 | J13: 000000 | K13: 0000 | L13: 0000 | M13: VND | O13: 318504337257 | Q13: 318504337257 | R13: DIEN01-DOANH THU HÓA ĐƠN TIỀN ĐIỆN PHÁT SINH TỪ NGÀY 11/05/2026 ĐẾN 11/05/2026 | S13: D | T13: QUYENNN.HCM.VTA | U13: QUYENNN.HCM.VTA | V13: =LEFT(R13,6) -> DIEN01
A14: AR_TRANSACTIONS | B14: 1616 | C14: 46153 | D14: 000000 | E14: 000 | F14: 51111000000 | G14: 1310 | H14: 0000 | I14: 000 | J14: 000000 | K14: 0000 | L14: 0000 | M14: VND | O14: 73444700 | Q14: 73444700 | R14: DIEN00-DOANH THU HÓA ĐƠN TIỀN ĐIỆN PHÁT SINH-CT TNHH NHÔM TOÀN CẦU VIỆT NAM KỲ 1/5/2026 | S14: D | T14: QUYENNN.HCM.VTA | U14: QUYENNN.HCM.VTA | V14: =LEFT(R14,6) -> DIEN00
A15: AR_TRANSACTIONS | B15: 1617 | C15: 46153 | D15: 000000 | E15: 000 | F15: 51113000000 | G15: 1310 | H15: 0000 | I15: 000 | J15: 000000 | K15: 0000 | L15: 0000 | M15: VND | O15: 63034452 | Q15: 63034452 | R15: CSPK02-DOANH THU HÓA ĐƠN TIỀN VÔ CÔNG PHÁT SINH TỪ NGÀY 11/05/2026 ĐẾN 11/05/2026 | S15: D | T15: QUYENNN.HCM.VTA | U15: QUYENNN.HCM.VTA | V15: =LEFT(R15,6) -> CSPK02
A16: AR_TRANSACTIONS | B16: 1618 | C16: 46158 | D16: 000000 | E16: 000 | F16: 51111000000 | G16: 1310 | H16: 0000 | I16: 000 | J16: 000000 | K16: 0000 | L16: 0000 | M16: VND | O16: 13249288139 | Q16: 13249288139 | R16: DIEN01-DOANH THU HÓA ĐƠN TIỀN ĐIỆN PHÁT SINH TỪ NGÀY 16/05/2026 ĐẾN 16/05/2026 | S16: D | T16: QUYENNN.HCM.VTA | U16: QUYENNN.HCM.VTA | V16: =LEFT(R16,6) -> DIEN01
A17: AR_TRANSACTIONS | B17: 1647 | C17: 46173 | D17: 000000 | E17: 000 | F17: 51111000000 | G17: 1310 | H17: 0000 | I17: 000 | J17: 000000 | K17: 0000 | L17: 0000 | M17: VND | O17: 765642586406 | Q17: 765642586406 | R17: DIEN01-DOANH THU HÓA ĐƠN TIỀN ĐIỆN PHÁT SINH T05/2026 | S17: D | T17: QUYENNN.HCM.VTA | U17: QUYENNN.HCM.VTA | V17: =LEFT(R17,6) -> DIEN01
A18: AR_TRANSACTIONS | B18: 1648 | C18: 46173 | D18: 000000 | E18: 000 | F18: 51111000000 | G18: 1310 | H18: 0000 | I18: 000 | J18: 000000 | K18: 0000 | L18: 0000 | M18: VND | O18: 95871352 | Q18: 95871352 | R18: DIEN00-DOANH THU HÓA ĐƠN TIỀN ĐIỆN PHÁT SINH-CT TNHH NHÔM TOÀN CẦU VIỆT NAM KỲ 3/5/2026 | S18: D | T18: QUYENNN.HCM.VTA | U18: QUYENNN.HCM.VTA | V18: =LEFT(R18,6) -> DIEN00
A19: AR_TRANSACTIONS | B19: 1649 | C19: 46173 | D19: 000000 | E19: 000 | F19: 51113000000 | G19: 1310 | H19: 0000 | I19: 000 | J19: 000000 | K19: 0000 | L19: 0000 | M19: VND | O19: 596561995 | Q19: 596561995 | R19: CSPK02-DOANH THU HÓA ĐƠN TIỀN VÔ CÔNG PHÁT SINH T05/2026 | S19: D | T19: QUYENNN.HCM.VTA | U19: QUYENNN.HCM.VTA | V19: =LEFT(R19,6) -> CSPK02
A20: AR_TRANSACTIONS | B20: 1633 | C20: 46168 | D20: 000000 | E20: 000 | F20: 51140000000 | G20: 4500 | H20: 0000 | I20: 000 | J20: 000000 | K20: 0000 | L20: 0000 | M20: VND | O20: 45940071 | Q20: 45940071 | R20: 4500TT - Doanh thu cho thuê cột điện treo cáp viễn thông (VTVCAB) tháng 05/2026 - HĐ 44 ngày 26/05/2026 | S20: D | T20: CHAULTN.HCM.VTA | U20: CHAULTN.HCM.VTA | V20: =LEFT(R20,6) -> 4500TT
... A24: AR_TRANSACTIONS | B24: 1662 | C24: 46173 | D24: 000000 | E24: 000 | F24: 51111000000 | G24: 1310 | H24: 0000 | I24: 000 | J24: 000000 | K24: 0000 | L24: 0000 | M24: VND | O24: -37491358 | Q24: -37491358 | R24: DIEN01-DOANH THU HÓA ĐƠN TIỀN ĐIỆN THOÁI HOÀN T05/2026 | S24: D | T24: QUYENNN.HCM.VTA | U24: QUYENNN.HCM.VTA | V24: =LEFT(R24,6) -> DIEN01
A25: Tổng cộng | O25: 1421779914426 | Q25: 1421779914426 | V25: =LEFT(R25,6)
V26: =LEFT(R26,6)
V27: =LEFT(R27,6)
V28: =LEFT(R28,6)
V29: =LEFT(R29,6)
V30: =LEFT(R30,6)
V31: =LEFT(R31,6)
V32: =LEFT(R32,6)
V34: =LEFT(R34,6)
V35: =LEFT(R35,6)
V36: =LEFT(R36,6)
V37: =LEFT(R37,6)
V38: =LEFT(R38,6)
... V57: =LEFT(R57,6)

Sheet 3A

Sheet 4A
A1: MADONVI | B1: TENDONVI | C1: TONGDTP | D1: TIENDIEN | E1: TIENCSPK | F1: THUE_TD | G1: THUE_CSPK | H1: TONGDTPKH | I1: TIENDIENKH | J1: GIABQKH
A2: PE1800 | B2: Công ty Điện lực Vũng Tàu | C2: 675132158 | D2: 1420763729435 | E2: 762611631 | F2: 113640782757 | G2: 61008928 | H2: 0 | I2: 0 | J2: 0
D3: 1420763729435 | E3: 762611631 | F3: 113640782757 | G3: 61008928 | H3: =VALUE(H2) -> 0 | I3: =VALUE(I2) -> 0 | J3: =VALUE(J2) -> 0
D7: trước thuế | E7: thuế | F7: sau thuế
A8: Điện | B8: DIEN01 | D8: =D3 -> 1420763729435 | E8: =F3 -> 113640782757 | F8: =+D8+E8 -> 1534404512192 | G8: =D8*8% -> 1.136611e+11 | H8: =E8-G8 -> -20315598
A9: CSPK | B9: CSPK02 | D9: =E3 -> 762611631 | E9: =G3 -> 61008928 | F9: =+D9+E9 -> 823620559 | G9: =D9*8% -> 61008930 | H9: =E9-G9 -> -2.48
D10: =SUM(D8:D9) -> 1421526341066 | E10: =SUM(E8:E9) -> 113701791685 | F10: =SUM(F8:F9) -> 1535228132751
A12: Trong DIEN01 có | B12: DIEN00 | D12: ='Nhom TC'!O4 -> 253945252 | E12: 0 | F12: =D12+E12 -> 253945252
B13: DIEN01 | D13: =D8-D12 -> 1420509784183 | E13: =E8-E12 -> 113640782757 | F13: =F8-F12 -> 1534150566940 | G13: =D13*8% -> 1.1364078e+11 | H13: =E13-G13 -> 22.360001
A16: Trong DIEN01 có | B16: CSPK02 | D16: =E2-D17 -> 762611631
B17: CSPK00 | D17: ='Nhom TC'!O5 -> 0
A20: GL_0903 | B20: DIEN01 | D20: ='0903'!X3 -> 1420509784183 | E20: =D13-D20 -> 0
B21: CSPK02 | D21: ='0903'!X2 -> 253945252 | E21: =D12-D21 -> 0
B22: CSPK00 | D22: ='0903'!X1 -> 0 | E22: =D17-D22 -> 0

Sheet TA35
X1: 333111 | Z1: 333113 | AB1: 333114
J2: Mẫu số : 01-1/GTGT | V2: DIEN00 | W2: =SUMIFS($H:$H,$T:$T,$V2) -> 239893600 | X2: =SUMIFS($J:$J,$T:$T,$V2) -> 0
J3: (Ban hành kèm theo thông tư | V3: DIEN01 | W3: =SUMIFS($H:$H,$T:$T,$V3) -> 1356716633174 | X3: =SUMIFS($J:$J,$T:$T,$V3) -> 108537330869
J4: số 119/2014/TT-BTC ngày | V4: CSPK02 | W4: =SUMIFS($H:$H,$T:$T,$V4) -> 641477615 | X4: =SUMIFS($J:$J,$T:$T,$V4) -> 51318199
J5: 25/08/2014 của Bộ tài chính) | V5: CSPK00 | W5: =SUMIFS($H:$H,$T:$T,$V5) -> 0 | X5: =SUMIFS($J:$J,$T:$T,$V5) -> 0
V6: 1388ĐĐ | W6: =SUMIFS($H:$H,$T:$T,$V6) -> 4451010687 | X6: =SUMIFS($J:$J,$T:$T,$V6) -> 356080855 | Y6: =SUMIFS($H:$H,$T:$T,$V6) -> 4451010687 | Z6: =SUMIFS($J:$J,$T:$T,$V6) -> 356080855 | AC6: vật tư điều động
A7: BẢNG KÊ HÓA ĐƠN, CHỨNG TỪ HÀNG HÓA, DỊCH VỤ BÁN RA(Kiểm soát số liệu) | V7: 5118QT | W7: =SUMIFS($H:$H,$T:$T,$V7) -> 0 | X7: =SUMIFS($J:$J,$T:$T,$V7) -> 0 | Y7: =SUMIFS($H:$H,$T:$T,$V7) -> 0 | Z7: =SUMIFS($J:$J,$T:$T,$V7) -> 0 | AC7: quà tặng
A8: Kèm theo tờ kê khai thuế GTGT theo mẫu số 01/GTGT | V8: 4500TT | W8: =SUMIFS($H:$H,$T:$T,$V8) -> 253573360 | X8: =SUMIFS($J:$J,$T:$T,$V8) -> 20285870 | AA8: =SUMIFS($H:$H,$T:$T,$V8) -> 253573360 | AB8: =SUMIFS($J:$J,$T:$T,$V8) -> 20285870 | AC8: dường dây thông tin
A9: Từ ngày 01/05/2026 đến ngày 31/05/2026 | W9: =SUM(W2:W8) -> 1362302588436 | X9: =SUM(X2:X8) -> 108965015793 | Y9: =SUM(Y2:Y8) -> 4451010687 | Z9: =SUM(Z2:Z8) -> 356080855 | AA9: =SUM(AA2:AA8) -> 253573360 | AB9: =SUM(AB2:AB8) -> 20285870
A11: Người nộp thuế : CHI NHÁNH TỔNG CÔNG TY ĐIỆN LỰC THÀNH PHỐ HỒ CHÍ MINH TNHH - CÔNG TY ĐIỆN LỰC VŨNG TÀU | U11: trước thuế | V11: =SUM(W11:AB11) -> 1367007172483 | W11: =W9 -> 1362302588436 | Y11: =Y9 -> 4451010687 | AA11: =AA9 -> 253573360
A12: Mã số thuế : 0300951119-010 | U12: thuế | V12: =SUM(W12:AB12) -> 109341382518 | X12: =X9 -> 108965015793 | Z12: =Z9 -> 356080855 | AB12: =AB9 -> 20285870
A13: Mã số thuế : 0300951119-010 | V13: =SUM(V11:V12) -> 1476348555001
A14: STT | B14: Hóa đơn, chứng từ bán | E14: Tên người mua | F14: Mã số thuế người mua | G14: Mặt hàng | H14: Doanh số bán chưa có thuế | I14: Thuế suất | J14: Thuế GTGT | K14: Ghi chú | L14: Nguồn chứng từ | M14: Số chứng từ | N14: Ngày lập chứng từ | O14: Thời hạn thanh toán trả chậm | P14: Số tiền đã thanh toán | Q14: Loại hình kinh doanh | R14: Người lập chứng từ | S14: Trạng thái
B15: Ký hiệu hóa đơn | C15: Số hóa đơn | D15: Ngày, tháng, năm phát hành | U15: Kiểm dò MST | V15: Thuế suất
A16: 1 | B16: 2 | C16: 3 | D16: 4 | E16: 5 | F16: 6 | G16: 7 | H16: 8 | I16: 9 | J16: 10 | K16: 11 | L16: 12 | M16: 13 | N16: 14 | O16: 15 | P16: 16 | Q16: 17 | R16: 18 | S16: 19 | W16: =W9-H51 -> 0
A17: 1.Hàng hóa, dịch vụ không chịu thuế GTGT | V17: 9
A18: 1 | C18: ' | F18: '
A19: Tổng cộng | T19: =LEFT(K19,6) | Y19: 5
A20: 2.Hàng hóa, dịch vụ chịu thuế suất thuế GTGT 0% | T20: =LEFT(K20,6) | Y20: 8
A21: 1 | C21: ' | E21: DIEN00-DOANH THU HÓA ĐƠN TIỀN ĐIỆN PHÁT SINH-CT TNHH NHÔM TOÀN CẦU VIỆT NAM KỲ 3/4/2026 | F21: ' | G21: DIEN00 | H21: 81819700 | I21: 0 | J21: 0 | L21: GL | M21: 1356 | N21: 46163 | O21: 46163 | P21: 81819700 | Q21: Không xác định | R21: QUYENNN.HCM.VTA | S21: Not Reversed | T21: =LEFT(G21,6) -> DIEN00 | U21: =LEN(F21) -> 1 | Y21: 10
A22: 2 | C22: ' | D22: 46153 | E22: DIEN00-DOANH THU HÓA ĐƠN TIỀN ĐIỆN PHÁT SINH | F22: 'KHDIENKINHDOANH | G22: DIEN00 | H22: 73444700 | I22: 0 | J22: 0 | K22: DIEN00-DOANH THU HÓA ĐƠN TIỀN ĐIỆN PHÁT SINH-CT TNHH NHÔM TOÀN CẦU VIỆT NAM KỲ 1/5/2026 | L22: AR_TRANS | M22: 1616 | N22: 46153 | O22: 46153 | Q22: Không xác định | R22: QUYENNN.HCM.VTA | S22: Complete | T22: =LEFT(G22,6) -> DIEN00 | U22: =LEN(F22) -> 16 | V22: 0
A23: 3 | C23: ' | D23: 46163 | E23: DIEN00-DOANH THU HÓA ĐƠN TIỀN ĐIỆN PHÁT SINH | F23: 'KHDIENKINHDOANH | G23: DIEN00 | H23: 84629200 | I23: 0 | J23: 0 | K23: DIEN00-DOANH THU HÓA ĐƠN TIỀN ĐIỆN PHÁT SINH-CT TNHH NHÔM TOÀN CẦU VIỆT NAM KỲ 2/5/2026 | L23: AR_TRANS | M23: 1627 | N23: 46163 | O23: 46163 | Q23: Không xác định | R23: QUYENNN.HCM.VTA | S23: Complete | T23: =LEFT(G23,6) -> DIEN00 | U23: =LEN(F23) -> 16 | V23: 0
A24: Tổng cộng | H24: 239893600 | J24: 0 | P24: 81819700 | T24: =LEFT(G24,6) | U24: =LEN(F24) -> 0 | V24: 0
A25: 3.Hàng hóa, dịch vụ chịu thuế suất thuế GTGT 5% | T25: =LEFT(G25,6) | U25: =LEN(F25) -> 0
A26: 1 | C26: ' | F26: ' | T26: =LEFT(G26,6) | U26: =LEN(F26) -> 1
A27: Tổng cộng | T27: =LEFT(G27,6) | U27: =LEN(F27) -> 0
A28: 4.Hàng hóa, dịch vụ chịu thuế suất thuế GTGT 10% | T28: =LEFT(G28,6) | U28: =LEN(F28) -> 0
A29: 1 | B29: K26TAH | C29: '40 | D29: 46160 | E29: Chi nhánh Tổng Công ty Điện lực Thành phố Hồ Chí Minh TNHH - Công ty Điện lực Bến Cát | F29: '0300951119-007 | G29: 1388ĐĐ - Điều động VTTB cho PC Bến cát theo TB 2205 ngày 06/05/2026 - HĐ 40/18.05.2026 | H29: 1792931000 | I29: 8 | J29: 143434480 | K29: CK | L29: AR_TRANS | M29: 1605 | N29: 46160 | O29: 46160 | P29: 1936365480 | Q29: Không xác định | R29: CHAULTN.HCM.VTA | S29: Complete | T29: =LEFT(G29,6) -> 1388ĐĐ | U29: =LEN(F29) -> 15
A30: 2 | B30: K26TAH | C30: '41 | D30: 46161 | E30: Chi nhánh Tổng Công ty Điện lực Thành phố Hồ Chí Minh TNHH - Công ty Điện lực Thuận An | F30: '0300951119-002 | G30: 1388ĐĐ - Điều động VTTB cho PC Thuận An theo TB 2188 ngày 05/05/2026 - HĐ 41/19.05.2026 | H30: 2631095000 | I30: 8 | J30: 210487600 | K30: CK | L30: AR_TRANS | M30: 1606 | N30: 46161 | O30: 46161 | Q30: Không xác định | R30: CHAULTN.HCM.VTA | S30: Complete | T30: =LEFT(G30,6) -> 1388ĐĐ | U30: =LEN(F30) -> 15 | V30: 8
A31: 3 | B31: K26TAH | C31: '42 | D31: 46164 | E31: CHI NHÁNH TỔNG CÔNG TY ĐIỆN LỰC THÀNH PHỐ HỒ CHÍ MINH TNHH - CÔNG TY ĐIỆN LỰC ĐẤT ĐỎ | F31: '0300951119-020 | G31: 1388ĐĐ - Điều động VTTB CV 1365 ngày 18/05/2026 PC Đất Đỏ - HĐ 42 ngày 22/05/2026 | H31: 26984687 | I31: 8 | J31: 2158775 | K31: CK | L31: AR_TRANS | M31: 1631 | N31: 46164 | O31: 46164 | Q31: Không xác định | R31: CHAULTN.HCM.VTA | S31: Complete | T31: =LEFT(G31,6) -> 1388ĐĐ | U31: =LEN(F31) -> 15 | V31: 8
A32: 4 | B32: K26TAH | C32: '43 | D32: 46168 | E32: Chi nhánh Công ty Cổ phần Viễn thông FPT | F32: '0101778163-001 | G32: 4500TT - Doanh thu cho thuê cột điện treo cáp viễn thông từ 01/05/26 đến 31/05/26 - HĐ 43/26.05.26 | H32: 57336523 | I32: 8 | J32: 4586922 | K32: CK | L32: AR_TRANS | M32: 1632 | N32: 46168 | O32: 46168 | Q32: Không xác định | R32: CHAULTN.HCM.VTA | S32: Complete | T32: =LEFT(G32,6) -> 4500TT | U32: =LEN(F32) -> 15 | V32: 8
A33: 5 | B33: K26TAH | C33: '44 | D33: 46168 | E33: CHI NHÁNH CÔNG TY CỔ PHẦN TỔNG CÔNG TY TRUYỀN HÌNH CÁP VIỆT NAM TẠI TỈNH BÀ RỊA - VŨNG TÀU | F33: '0105926285-023 | G33: 4500TT - Doanh thu cho thuê cột điện treo cáp viễn thông (VTVCAB) tháng 05/2026 - HĐ 44 ngày 26/05/2026 | H33: 45940071 | I33: 8 | J33: 3675206 | K33: CK | L33: AR_TRANS | M33: 1633 | N33: 46168 | O33: 46168 | Q33: Không xác định | R33: CHAULTN.HCM.VTA | S33: Complete | T33: =LEFT(G33,6) -> 4500TT | U33: =LEN(F33) -> 15 | V33: 8
A34: 6 | B34: K26TAH | C34: '45 | D34: 46168 | E34: VNPT thành phố Hồ Chí Minh | F34: '0300954529 | G34: 4500TT - Doanh thu cho thuê cột điện treo cáp viễn thông tháng 05/2026 - HĐ 45 ngày 26/05/2026 | H34: 150296766 | I34: 8 | J34: 12023742 | K34: CK | L34: AR_TRANS | M34: 1646 | N34: 46168 | O34: 46168 | Q34: Không xác định | R34: CHAULTN.HCM.VTA | S34: Complete | T34: =LEFT(G34,6) -> 4500TT | U34: =LEN(F34) -> 11 | V34: 8
A35: 7 | C35: ' | E35: CSPK02-DOANH THU HÓA ĐƠN TIỀN VÔ CÔNG PHÁT SINH T04/2026 | F35: ' | G35: CSPK02 | H35: 475427979 | I35: 8 | J35: 38034227 | L35: GL | M35: 1356 | N35: 46163 | O35: 46163 | P35: 513462206 | Q35: Không xác định | R35: QUYENNN.HCM.VTA | S35: Not Reversed | T35: =LEFT(G35,6) -> CSPK02 | U35: =LEN(F35) -> 1 | V35: 8
A36: 8 | C36: ' | E36: DIEN01-DOANH THU HÓA ĐƠN TIỀN ĐIỆN PHÁT SINH T04/2026 | F36: ' | G36: DIEN01 | H36: 701849435397 | I36: 8 | J36: 56147955041 | L36: GL | M36: 1356 | N36: 46163 | O36: 46163 | P36: 757997390438 | Q36: Không xác định | R36: QUYENNN.HCM.VTA | S36: Not Reversed | T36: =LEFT(G36,6) -> DIEN01 | U36: =LEN(F36) -> 1 | V36: 8
A37: 9 | C37: ' | D37: 46153 | E37: DIEN01-DOANH THU HÓA ĐƠN TIỀN ĐIỆN PHÁT SINH | F37: 'KHDIENKINHDOANH | G37: DIEN01 | H37: 318504337257 | I37: 8 | J37: 25480346999 | K37: DIEN01-DOANH THU HÓA ĐƠN TIỀN ĐIỆN PHÁT SINH TỪ NGÀY 11/05/2026 ĐẾN 11/05/2026 | L37: AR_TRANS | M37: 1615 | N37: 46153 | O37: 46153 | P37: 276722640083 | Q37: Không xác định | R37: QUYENNN.HCM.VTA | S37: Complete | T37: =LEFT(G37,6) -> DIEN01 | U37: =LEN(F37) -> 16 | V37: 8
A38: 10 | C38: ' | D38: 46153 | E38: CSPK02-DOANH THU HÓA ĐƠN TIỀN VÔ CÔNG PHÁT SINH | F38: 'KHDIENVOCONG | G38: CSPK02 | H38: 63034452 | I38: 8 | J38: 5042756 | K38: CSPK02-DOANH THU HÓA ĐƠN TIỀN VÔ CÔNG PHÁT SINH TỪ NGÀY 11/05/2026 ĐẾN 11/05/2026 | L38: AR_TRANS | M38: 1617 | N38: 46153 | O38: 46153 | Q38: Không xác định | R38: QUYENNN.HCM.VTA | S38: Complete | T38: =LEFT(G38,6) -> CSPK02 | U38: =LEN(F38) -> 13 | V38: 10
A39: 11 | C39: ' | D39: 46158 | E39: DIEN01-DOANH THU HÓA ĐƠN TIỀN ĐIỆN PHÁT SINH | F39: 'KHDIENKINHDOANH | G39: DIEN01 | H39: 13249288139 | I39: 8 | J39: 1059943044 | K39: DIEN01-DOANH THU HÓA ĐƠN TIỀN ĐIỆN PHÁT SINH TỪ NGÀY 16/05/2026 ĐẾN 16/05/2026 | L39: AR_TRANS | M39: 1618 | N39: 46158 | O39: 46158 | Q39: Không xác định | R39: QUYENNN.HCM.VTA | S39: Complete | T39: =LEFT(G39,6) -> DIEN01 | U39: =LEN(F39) -> 16 | V39: 8
A40: 12 | C40: ' | D40: 46158 | E40: CSPK02-DOANH THU HÓA ĐƠN TIỀN VÔ CÔNG PHÁT SINH | F40: 'KHDIENVOCONG | G40: CSPK02 | H40: 34333124 | I40: 8 | J40: 2746651 | K40: CSPK02-DOANH THU HÓA ĐƠN TIỀN VÔ CÔNG PHÁT SINH TỪ NGÀY 16/05/2026 ĐẾN 16/05/2026 | L40: AR_TRANS | M40: 1624 | N40: 46158 | O40: 46158 | Q40: Không xác định | R40: QUYENNN.HCM.VTA | S40: Complete | T40: =LEFT(G40,6) -> CSPK02 | U40: =LEN(F40) -> 13 | V40: 10
A41: 13 | C41: ' | D41: 46163 | E41: DIEN01-DOANH THU HÓA ĐƠN TIỀN ĐIỆN PHÁT SINH | F41: 'KHDIENKINHDOANH | G41: DIEN01 | H41: 322639770751 | I41: 8 | J41: 25811181662 | K41: DIEN01-DOANH THU HÓA ĐƠN TIỀN ĐIỆN PHÁT SINH TỪ NGÀY 21/05/2026 ĐẾN 21/05/2026 | L41: AR_TRANS | M41: 1625 | N41: 46163 | O41: 46163 | P41: 5056387417 | Q41: Không xác định | R41: QUYENNN.HCM.VTA | S41: Complete | T41: =LEFT(G41,6) -> DIEN01 | U41: =LEN(F41) -> 16 | V41: 10
...

Sheet 333111
A1: TỔNG CÔNG TY ĐIỆN LỰC THÀNH PHỐ HỒ CHÍ MINH TNHH | J1: =E11 -> 1500000000 | M1: 333111 | N1: 333113 | O1: 333114
A2: CHI NHÁNH TỔNG CÔNG TY ĐIỆN LỰC THÀNH PHỐ HỒ CHÍ MINH TNHH - CÔNG TY ĐIỆN LỰC VŨNG TÀU | L2: DIEN01 | M2: =SUMIFS($F:$F,$K:$K,M$1,$J:$J,$L2,$I:$I,5) -> 52389375828 | N2: =SUMIFS($F:$F,$K:$K,N$1,$J:$J,$L2,$I:$I,5) -> 0 | O2: =SUMIFS($F:$F,$K:$K,O$1,$J:$J,$L2,$I:$I,5) -> 0
A3: SỔ CHI TIẾT THEO TÀI KHOẢN THUẾ | J3: =E33 -> 1500000000 | L3: CSPK02 | M3: =SUMIFS($F:$F,$K:$K,M$1,$J:$J,$L3,$I:$I,5) -> 13283972 | N3: =SUMIFS($F:$F,$K:$K,N$1,$J:$J,$L3,$I:$I,5) -> 0 | O3: =SUMIFS($F:$F,$K:$K,O$1,$J:$J,$L3,$I:$I,5) -> 0
A4: Tài khoản: 3331 - Thuế và các khoản phải nộp Nhà nước – Thuế giá trị gia tăng phải nộp | L4: 1388ĐĐ | M4: =SUMIFS($F:$F,$K:$K,M$1,$J:$J,$L4,$I:$I,5) -> 0 | N4: =SUMIFS($F:$F,$K:$K,N$1,$J:$J,$L4,$I:$I,5) -> 356080855 | O4: =SUMIFS($F:$F,$K:$K,O$1,$J:$J,$L4,$I:$I,5) -> 0 | Q4: vật tư điều động
A5: Loại hình: - | L5: 5118QT | M5: =SUMIFS($F:$F,$K:$K,M$1,$J:$J,$L5,$I:$I,5) -> 0 | N5: =SUMIFS($F:$F,$K:$K,N$1,$J:$J,$L5,$I:$I,5) -> 0 | O5: =SUMIFS($F:$F,$K:$K,O$1,$J:$J,$L5,$I:$I,5) -> 0 | Q5: quà tặng
A6: Từ ngày: 01/05/2026 đến ngày: 31/05/2026 | L6: 4500TT | M6: =SUMIFS($F:$F,$K:$K,M$1,$J:$J,$L6,$I:$I,5) -> 0 | N6: =SUMIFS($F:$F,$K:$K,N$1,$J:$J,$L6,$I:$I,5) -> 0 | O6: =SUMIFS($F:$F,$K:$K,O$1,$J:$J,$L6,$I:$I,5) -> 20285870 | Q6: dường dây thông tin
M7: =SUM(M2:M6) -> 52402659800 | N7: =SUM(N2:N6) -> 356080855 | O7: =SUM(O2:O6) -> 20285870 | P7: =SUM(P2:P6) -> 0
A9: CHỨNG TỪ | D9: DIỄN GIẢI | E9: PHÁT SINH NỢ | F9: PHÁT SINH CÓ | G9: Người hạch toán | H9: Trạng thái
A10: Ngày chứng từ | B10: Số chứng từ | C10: Nguồn chứng từ
A11: Tài khoản: 33311100000 | D11: Dư đầu kỳ | E11: 1500000000 | I11: =LEN(A11) -> 22 | K11: =IF(LEFT(A11,11)="Tài khoản: ",MID(A11,12,6),K10) -> 333111
A12: 46153 | B12: '1615 | C12: AR_TRANS | D12: DIEN01-DOANH THU HÓA ĐƠN TIỀN ĐIỆN PHÁT SINH TỪ NGÀY 11/05/2026 ĐẾN 11/05/2026 | F12: 25480346999 | G12: QUYENNN.HCM.VTA | H12: Final to Post | I12: =LEN(A12) -> 5 | J12: =LEFT(D12,6) -> DIEN01 | K12: =IF(LEFT(A12,11)="Tài khoản: ",MID(A12,12,6),K11) -> 333111
A13: 46153 | B13: '1617 | C13: AR_TRANS | D13: CSPK02-DOANH THU HÓA ĐƠN TIỀN VÔ CÔNG PHÁT SINH TỪ NGÀY 11/05/2026 ĐẾN 11/05/2026 | F13: 5042756 | G13: QUYENNN.HCM.VTA | H13: Final to Post | I13: =LEN(A13) -> 5 | J13: =LEFT(D13,6) -> CSPK02 | K13: =IF(LEFT(A13,11)="Tài khoản: ",MID(A13,12,6),K12) -> 333111
A14: 46158 | B14: '1618 | C14: AR_TRANS | D14: DIEN01-DOANH THU HÓA ĐƠN TIỀN ĐIỆN PHÁT SINH TỪ NGÀY 16/05/2026 ĐẾN 16/05/2026 | F14: 1059943044 | G14: QUYENNN.HCM.VTA | H14: Final to Post | I14: =LEN(A14) -> 5 | J14: =LEFT(D14,6) -> DIEN01 | K14: =IF(LEFT(A14,11)="Tài khoản: ",MID(A14,12,6),K13) -> 333111
A15: 46158 | B15: '1624 | C15: AR_TRANS | D15: CSPK02-DOANH THU HÓA ĐƠN TIỀN VÔ CÔNG PHÁT SINH TỪ NGÀY 16/05/2026 ĐẾN 16/05/2026 | F15: 2746651 | G15: QUYENNN.HCM.VTA | H15: Final to Post | I15: =LEN(A15) -> 5 | J15: =LEFT(D15,6) -> CSPK02 | K15: =IF(LEFT(A15,11)="Tài khoản: ",MID(A15,12,6),K14) -> 333111
A16: 46163 | B16: '1356 | C16: GL | D16: Giải trừ thuế GTGT đầu ra từ 33895 sang 333111-30/04/2026 AR1545 | F16: 56147955041 | G16: QUYENNN.HCM.VTA | H16: Post | I16: =LEN(A16) -> 5 | J16: =LEFT(D16,6) -> Giải t | K16: =IF(LEFT(A16,11)="Tài khoản: ",MID(A16,12,6),K15) -> 333111
A17: 46163 | B17: '1356 | C17: GL | D17: Giải trừ thuế GTGT đầu ra từ 33895 sang 333111-30/04/2026 AR1547 | F17: 38034227 | G17: QUYENNN.HCM.VTA | H17: Post | I17: =LEN(A17) -> 5 | J17: =LEFT(D17,6) -> Giải t | K17: =IF(LEFT(A17,11)="Tài khoản: ",MID(A17,12,6),K16) -> 333111
A18: 46163 | B18: '1625 | C18: AR_TRANS | D18: DIEN01-DOANH THU HÓA ĐƠN TIỀN ĐIỆN PHÁT SINH TỪ NGÀY 21/05/2026 ĐẾN 21/05/2026 | F18: 25811181662 | G18: QUYENNN.HCM.VTA | H18: Final to Post | I18: =LEN(A18) -> 5 | J18: =LEFT(D18,6) -> DIEN01 | K18: =IF(LEFT(A18,11)="Tài khoản: ",MID(A18,12,6),K17) -> 333111
A19: 46163 | B19: '1626 | C19: AR_TRANS | D19: CSPK02-DOANH THU HÓA ĐƠN TIỀN VÔ CÔNG PHÁT SINH TỪ NGÀY 21/05/2026 ĐẾN 21/05/2026 | F19: 5494565 | G19: QUYENNN.HCM.VTA | H19: Final to Post | I19: =LEN(A19) -> 5 | J19: =LEFT(D19,6) -> CSPK02 | K19: =IF(LEFT(A19,11)="Tài khoản: ",MID(A19,12,6),K18) -> 333111
A20: 46173 | B20: '1359 | C20: GL | D20: Kết chuyển TK 13313_9000 qua TK 333111 | E20: 598313 | G20: LINH3NTT.HCM.VTA | H20: Post | I20: =LEN(A20) -> 5 | J20: =LEFT(D20,6) -> Kết ch | K20: =IF(LEFT(A20,11)="Tài khoản: ",MID(A20,12,6),K19) -> 333111
A21: 46173 | B21: '1365 | C21: GL | D21: Kết chuyển TK13313_9000 qua TK 333111 | E21: 26248888 | G21: LINH3NTT.HCM.VTA | H21: Post | I21: =LEN(A21) -> 5 | J21: =LEFT(D21,6) -> Kết ch | K21: =IF(LEFT(A21,11)="Tài khoản: ",MID(A21,12,6),K20) -> 333111
A22: 46173 | B22: '1373 | C22: GL | D22: Kết chuyển GTGT tháng 5 | E22: 122327822 | G22: HIENNTK.HCM.VTA | H22: Post | I22: =LEN(A22) -> 5 | J22: =LEFT(D22,6) -> Kết ch | K22: =IF(LEFT(A22,11)="Tài khoản: ",MID(A22,12,6),K21) -> 333111
A23: 46173 | B23: '1488 | C23: GL | D23: Kết chuyển Thuế GTGT tháng 5/2026 | F23: 376366725 | G23: TUAN2HM.HCM.VTA | H23: Post | I23: =LEN(A23) -> 5 | J23: =LEFT(D23,6) -> Kết ch | K23: =IF(LEFT(A23,11)="Tài khoản: ",MID(A23,12,6),K22) -> 333111
A24: 46173 | B24: '1492 | C24: GL | D24: Kết chuyển thuế GTGT từ 1331 về 3331 tháng 05/2026 | E24: 108965015793 | G24: TUAN2HM.HCM.VTA | H24: Post | I24: =LEN(A24) -> 5 | J24: =LEFT(D24,6) -> Kết ch | K24: =IF(LEFT(A24,11)="Tài khoản: ",MID(A24,12,6),K23) -> 333111
A25: 46173 | B25: '1639 | C25: AR_TRANS | D25: DIEN01-DOANH THU HÓA ĐƠN TIỀN ĐIỆN HỦY BỎ T05/2026 | F25: -18396522 | G25: QUYENNN.HCM.VTA | H25: Final to Post | I25: =LEN(A25) -> 5 | J25: =LEFT(D25,6) -> DIEN01 | K25: =IF(LEFT(A25,11)="Tài khoản: ",MID(A25,12,6),K24) -> 333111
A26: 46173 | B26: '1640 | C26: AR_TRANS | D26: DIEN01-DOANH THU HÓA ĐƠN TIỀN ĐIỆN LẶP LẠI T05/2026 | F26: 36720327 | G26: QUYENNN.HCM.VTA | H26: Final to Post | I26: =LEN(A26) -> 5 | J26: =LEFT(D26,6) -> DIEN01 | K26: =IF(LEFT(A26,11)="Tài khoản: ",MID(A26,12,6),K25) -> 333111
A27: 46173 | B27: '1641 | C27: AR_TRANS | D27: DIEN01-DOANH THU HÓA ĐƠN TIỀN ĐIỆN TRUY THU T05/2026 | F27: 22579627 | G27: QUYENNN.HCM.VTA | H27: Final to Post | I27: =LEN(A27) -> 5 | J27: =LEFT(D27,6) -> DIEN01 | K27: =IF(LEFT(A27,11)="Tài khoản: ",MID(A27,12,6),K26) -> 333111
A28: 46173 | B28: '1655 | C28: GL | D28: Kết chuyển thuế GTGT CTĐTXD | E28: 218813875 | G28: HIENNTK.HCM.VTA | H28: Post | I28: =LEN(A28) -> 5 | J28: =LEFT(D28,6) -> Kết ch | K28: =IF(LEFT(A28,11)="Tài khoản: ",MID(A28,12,6),K27) -> 333111
A29: 46173 | B29: '1656 | C29: GL | D29: K/C Thuế GTGT VTTB ĐĐ ĐTXD T5/2026 | E29: 1417502240 | G29: TUAN2HM.HCM.VTA | H29: Unpost | I29: =LEN(A29) -> 5 | J29: =LEFT(D29,6) -> K/C Th | K29: =IF(LEFT(A29,11)="Tài khoản: ",MID(A29,12,6),K28) -> 333111
A30: 46173 | B30: '1657 | C30: GL | D30: Đ/c Kết chuyển thuế GTGT từ 1331 về 3331 tháng 05/2026 | E30: -1785491138 | G30: TUAN2HM.HCM.VTA | H30: Unpost | I30: =LEN(A30) -> 5 | J30: =LEFT(D30,6) -> Đ/c Kế | K30: =IF(LEFT(A30,11)="Tài khoản: ",MID(A30,12,6),K29) -> 333111
A31: 46173 | B31: '1662 | C31: AR_TRANS | D31: DIEN01-DOANH THU HÓA ĐƠN TIỀN ĐIỆN THOÁI HOÀN T05/2026 | F31: -2999309 | G31: QUYENNN.HCM.VTA | H31: Final to Post | I31: =LEN(A31) -> 5 | J31: =LEFT(D31,6) -> DIEN01 | K31: =IF(LEFT(A31,11)="Tài khoản: ",MID(A31,12,6),K30) -> 333111
D32: Cộng phát sinh | E32: 108965015793 | F32: 108965015793 | I32: =LEN(A32) -> 0 | J32: =LEFT(D32,6) -> Cộng p | K32: =IF(LEFT(A32,11)="Tài khoản: ",MID(A32,12,6),K31) -> 333111
D33: Dư cuối kỳ | E33: 1500000000 | I33: =LEN(A33) -> 0 | J33: =LEFT(D33,6) -> Dư cuố | K33: =IF(LEFT(A33,11)="Tài khoản: ",MID(A33,12,6),K32) -> 333111
A34: Tài khoản: 33311300000 | D34: Dư đầu kỳ | I34: =LEN(A34) -> 22 | J34: =LEFT(D34,6) -> Dư đầu | K34: =IF(LEFT(A34,11)="Tài khoản: ",MID(A34,12,6),K33) -> 333113
A35: 46160 | B35: '1605 | C35: AR_TRANS | D35: 1388ĐĐ - Điều động VTTB cho PC Bến cát theo TB 2205 ngày 06/05/2026 - HĐ 40/18.05.2026 | F35: 143434480 | G35: CHAULTN.HCM.VTA | H35: Final to Post | I35: =LEN(A35) -> 5 | J35: =LEFT(D35,6) -> 1388ĐĐ | K35: =IF(LEFT(A35,11)="Tài khoản: ",MID(A35,12,6),K34) -> 333113
A36: 46161 | B36: '1606 | C36: AR_TRANS | D36: 1388ĐĐ - Điều động VTTB cho PC Thuận An theo TB 2188 ngày 05/05/2026 - HĐ 41/19.05.2026 | F36: 210487600 | G36: CHAULTN.HCM.VTA | H36: Final to Post | I36: =LEN(A36) -> 5 | J36: =LEFT(D36,6) -> 1388ĐĐ | K36: =IF(LEFT(A36,11)="Tài khoản: ",MID(A36,12,6),K35) -> 333113
A37: 46164 | B37: '1631 | C37: AR_TRANS | D37: 1388ĐĐ - Điều động VTTB CV 1365 ngày 18/05/2026 PC Đất Đỏ - HĐ 42 ngày 22/05/2026 | F37: 2158775 | G37: CHAULTN.HCM.VTA | H37: Final to Post | I37: =LEN(A37) -> 5 | J37: =LEFT(D37,6) -> 1388ĐĐ | K37: =IF(LEFT(A37,11)="Tài khoản: ",MID(A37,12,6),K36) -> 333113
A38: 46173 | B38: '1488 | C38: GL | D38: Kết chuyển Thuế GTGT tháng 5/2026 | F38: -356080855 | G38: TUAN2HM.HCM.VTA | H38: Post | I38: =LEN(A38) -> 5 | J38: =LEFT(D38,6) -> Kết ch | K38: =IF(LEFT(A38,11)="Tài khoản: ",MID(A38,12,6),K37) -> 333113
D39: Cộng phát sinh | F39: 0 | I39: =LEN(A39) -> 0 | J39: =LEFT(D39,6) -> Cộng p | K39: =IF(LEFT(A39,11)="Tài khoản: ",MID(A39,12,6),K38) -> 333113
D40: Dư cuối kỳ | I40: =LEN(A40) -> 0 | J40: =LEFT(D40,6) -> Dư cuố | K40: =IF(LEFT(A40,11)="Tài khoản: ",MID(A40,12,6),K39) -> 333113
A41: Tài khoản: 33311400000 | D41: Dư đầu kỳ | I41: =LEN(A41) -> 22 | J41: =LEFT(D41,6) -> Dư đầu | K41: =IF(LEFT(A41,11)="Tài khoản: ",MID(A41,12,6),K40) -> 333114
...

Sheet 33895
A1: TỔNG CÔNG TY ĐIỆN LỰC THÀNH PHỐ HỒ CHÍ MINH TNHH | M1: Nợ_giải trừ | N1: Có_treo
A2: CHI NHÁNH TỔNG CÔNG TY ĐIỆN LỰC THÀNH PHỐ HỒ CHÍ MINH TNHH - CÔNG TY ĐIỆN LỰC VŨNG TÀU | L2: DIEN01 | M2: =SUMIF($J:$J,$L2,F:F) -> 0 | N2: =SUMIF($J:$J,$L2,G:G) -> 61251406929
A3: SỔ CHI TIẾT TÀI KHOẢN THEO 3 CẤP ĐỐI TƯỢNG DFF | L3: CSPK02 | M3: =SUMIF($J:$J,$L3,F:F) -> 0 | N3: =SUMIF($J:$J,$L3,G:G) -> 47724956
A4: Tài khoản 33895 - Phải trả, phải nộp khác – Thuế đầu ra chưa kê khai | M4: =SUM(M2:M3) -> 0 | N4: =SUM(N2:N3) -> 61299131885
A5: Tất cả loại hình
A6: Từ ngày 01/05/2026 đến ngày 31/05/2026
A7: Nguồn bút toán | B7: Chứng từ | E7: Diễn giải | F7: Số phát sinh Nợ | G7: Số phát sinh Có | H7: Người lập | I7: Trạng Thái
B8: Ngày | C8: Số CT Phân hệ phụ | D8: Số CT phân | H8: Chứng từ
D9: hệ GL | K9: QUYENNN.HCM.VTA
A10: 33895000000-Phải trả, phải nộp khác – Thuế đầu ra chưa kê khai
E11: Số dư đầu kỳ | G11: 56185989268
A12: Khác | G12: 56185989268
A13: Khác | G13: 56185989268
A14: Khác | G14: 56185989268
A15: GL-Manual | B15: 46163 | D15: 1356 | E15: 082900.000000.000.33895000000.0000.0000.000.000000.0000.0000 | F15: 38034227 | H15: QUYENNN.HCM.VTA | I15: Unpost | J15: =LEFT(E16,6) -> Giải t | K15: =IF(H15=$K$9,G15,0) -> 0
E16: Giải trừ thuế GTGT đầu ra từ 33895 sang 333111-30/04/2026 AR1547 | J16: =LEFT(E17,6) -> 082900 | K16: =IF(H16=$K$9,G16,0) -> 0
A17: GL-Manual | B17: 46163 | D17: 1356 | E17: 082900.000000.000.33895000000.0000.0000.000.000000.0000.0000 | H17: QUYENNN.HCM.VTA | I17: Unpost | J17: =LEFT(E18,6) -> Giải t | K17: =IF(H17=$K$9,G17,0) -> 0
E18: Giải trừ thuế GTGT đầu ra từ 33895 sang 333111-30/04/2026 AR1546 | J18: =LEFT(E19,6) -> 082900 | K18: =IF(H18=$K$9,G18,0) -> 0
A19: GL-Manual | B19: 46163 | D19: 1356 | E19: 082900.000000.000.33895000000.0000.0000.000.000000.0000.0000 | F19: 56147955041 | H19: QUYENNN.HCM.VTA | I19: Unpost | J19: =LEFT(E20,6) -> Giải t | K19: =IF(H19=$K$9,G19,0) -> 0
E20: Giải trừ thuế GTGT đầu ra từ 33895 sang 333111-30/04/2026 AR1545 | J20: =LEFT(E21,6) -> 082900 | K20: =IF(H20=$K$9,G20,0) -> 0
A21: AR-Transaction | B21: 46173 | C21: 1647 | E21: 082900.000000.000.33895000000.0000.0000.000.000000.0000.0000 | G21: 61251406929 | H21: QUYENNN.HCM.VTA | I21: Draft | J21: =LEFT(E22,6) -> DIEN01 | K21: =IF(H21=$K$9,G21,0) -> 61251406929
E22: DIEN01-DOANH THU HÓA ĐƠN TIỀN ĐIỆN PHÁT SINH T05/2026 | J22: =LEFT(E23,6) -> 082900 | K22: =IF(H22=$K$9,G22,0) -> 0
A23: AR-Transaction | B23: 46173 | C23: 1648 | E23: 082900.000000.000.33895000000.0000.0000.000.000000.0000.0000 | H23: QUYENNN.HCM.VTA | I23: Draft | J23: =LEFT(E24,6) -> DIEN00 | K23: =IF(H23=$K$9,G23,0) -> 0
E24: DIEN00-DOANH THU HÓA ĐƠN TIỀN ĐIỆN PHÁT SINH-CT TNHH NHÔM TOÀN CẦU VIỆT NAM KỲ 3/5/2026 | J24: =LEFT(E25,6) -> 082900 | K24: =IF(H24=$K$9,G24,0) -> 0
A25: AR-Transaction | B25: 46173 | C25: 1649 | E25: 082900.000000.000.33895000000.0000.0000.000.000000.0000.0000 | G25: 47724956 | H25: QUYENNN.HCM.VTA | I25: Draft | J25: =LEFT(E26,6) -> CSPK02 | K25: =IF(H25=$K$9,G25,0) -> 47724956
E26: CSPK02-DOANH THU HÓA ĐƠN TIỀN VÔ CÔNG PHÁT SINH T05/2026 | J26: =LEFT(E27,6) | K26: =IF(H26=$K$9,G26,0) -> 0
B27: Cộng phát sinh – cấp 3 | F27: 56185989268 | G27: 61299131885 | J27: =LEFT(E28,6) | K27: =IF(H27=$K$9,G27,0) -> 0
B28: Dư cuối kỳ | G28: 61299131885 | J28: =LEFT(E29,6) | K28: =IF(H28=$K$9,G28,0) -> 0
B29: Cộng phát sinh – cấp 2 | F29: 56185989268 | G29: 61299131885 | J29: =LEFT(E30,6) | K29: =IF(H29=$K$9,G29,0) -> 0
B30: Dư cuối kỳ | G30: 61299131885 | J30: =LEFT(E31,6) | K30: =IF(H30=$K$9,G30,0) -> 0
B31: Cộng phát sinh – cấp 1 | F31: 56185989268 | G31: 61299131885 | J31: =LEFT(E32,6) | K31: =IF(H31=$K$9,G31,0) -> 0
B32: Dư cuối kỳ | G32: 61299131885 | J32: =LEFT(E33,6) | K32: =IF(H32=$K$9,G32,0) -> 0
B33: Cộng phát sinh-33895000000 | F33: 56185989268 | G33: 61299131885 | J33: =LEFT(E34,6) | K33: =IF(H33=$K$9,G33,0) -> 0
B34: Dư cuối kỳ- | G34: 61299131885 | J34: =LEFT(E35,6) | K34: =IF(H34=$K$9,G34,0) -> 0
B35: Tổng Dư đầu kỳ - 33895000000 | G35: 56185989268 | J35: =LEFT(E36,6) | K35: =IF(H35=$K$9,G35,0) -> 0
B36: Tổng Cộng phát sinh | F36: 56185989268 | G36: 61299131885 | J36: =LEFT(E37,6) | K36: =IF(H36=$K$9,G36,0) -> 0
B37: Tổng Dư cuối kỳ | G37: 61299131885 | J37: =LEFT(E38,6) | K37: =IF(H37=$K$9,G37,0) -> 0
C38: Người lập biểu | D38: Kế toán trưởng | J38: =LEFT(E39,6) | K38: =IF(H38=$K$9,G38,0) -> 0
C39: (Ký, họ tên) | D39: (Ký, họ tên) | J39: =LEFT(E40,6) | K39: =IF(H39=$K$9,G39,0) -> 0
J40: =LEFT(E41,6) | K40: =IF(H40=$K$9,G40,0) -> 0
...

Sheet TA36
J1: Mẫu số : 01-2/GTGT | W1: TUAN2HM.HCM.VTA | X1: =SUMIF($R:$R,$W1,$H:$H) -> 1291995987299 | Y1: =SUMIF($R:$R,$W1,$J:$J) -> 103359678984 | Z1: =SUMIF('13311'!$G:$G,'TA36'!$W1,'13311'!$E:$E) -> 103359678984 | AA1: =Y1-Z1 -> 0
J2: (Ban hành kèm theo thông tư | W2: LINH3NTT.HCM.VTA | X2: =SUMIF($R:$R,$W2,$H:$H) -> 334094213 | Y2: =SUMIF($R:$R,$W2,$J:$J) -> 26847201 | Z2: =SUMIF('13311'!$G:$G,'TA36'!$W2,'13311'!$E:$E) -> 26847201 | AA2: =Y2-Z2 -> 0
J3: số 119/2014/TT-BTC ngày | W3: THANH5DT.HCM.VTA | X3: =SUMIF($R:$R,$W3,$H:$H) -> 19828437023 | Y3: =SUMIF($R:$R,$W3,$J:$J) -> 1586121323 | Z3: =SUMIF('13311'!$G:$G,'TA36'!$W3,'13311'!$E:$E) -> 1586121323 | AA3: =Y3-Z3 -> 0
J4: 25/08/2014 của Bộ tài chính) | W4: HIENNTK.HCM.VTA | X4: =SUMIF($R:$R,$W4,$H:$H) -> 4264271219 | Y4: =SUMIF($R:$R,$W4,$J:$J) -> 341141697 | Z4: =SUMIF('13311'!$G:$G,'TA36'!$W4,'13311'!$E:$E) -> 341141697 | AA4: =Y4-Z4 -> 0
W5: QUYENNN.HCM.VTA | X5: =SUMIF($R:$R,$W5,$H:$H) -> 17682276 | Y5: =SUMIF($R:$R,$W5,$J:$J) -> 1768229 | Z5: =SUMIF('13311'!$G:$G,'TA36'!$W5,'13311'!$E:$E) -> 1768229 | AA5: =Y5-Z5 -> 0
B6: BẢNG KÊ HÓA ĐƠN, CHỨNG TỪ HÀNG HÓA, DỊCH VỤ MUA VÀO(Kiểm soát số liệu) | W6: HUENT.HCM.VTA | X6: =SUMIF($R:$R,$W6,$H:$H) -> 1015525132 | Y6: =SUMIF($R:$R,$W6,$J:$J) -> 82569755 | Z6: =SUMIF('13311'!$G:$G,'TA36'!$W6,'13311'!$E:$E) -> 82569755 | AA6: =Y6-Z6 -> 0
B7: Kèm theo tờ kê khai thuế GTGT theo mẫu số 01/GTGT | W7: THAOPTT.HCM.VTA | X7: =SUMIF($R:$R,$W7,$H:$H) -> 26031867076 | Y7: =SUMIF($R:$R,$W7,$J:$J) -> 2082579117 | Z7: =SUMIF('13311'!$G:$G,'TA36'!$W7,'13311'!$E:$E) -> 2082579117 | AA7: =Y7-Z7 -> 0
B8: Từ ngày 01/05/2026 đến ngày 31/05/2026 | W8: CHAULTN.HCM.VTA | X8: =SUMIF($R:$R,$W8,$H:$H) -> 250000 | Y8: =SUMIF($R:$R,$W8,$J:$J) -> 25000 | Z8: =SUMIF('13311'!$G:$G,'TA36'!$W8,'13311'!$E:$E) -> 25000 | AA8: =Y8-Z8 -> 0
W9: THUTT.HCM.VTA | X9: =SUMIF($R:$R,$W9,$H:$H) -> 50000 | Y9: =SUMIF($R:$R,$W9,$J:$J) -> 5000 | Z9: =SUMIF('13311'!$G:$G,'TA36'!$W9,'13311'!$E:$E) -> 5000 | AA9: =Y9-Z9 -> 0
B10: Người nộp thuế : CHI NHÁNH TỔNG CÔNG TY ĐIỆN LỰC THÀNH PHỐ HỒ CHÍ MINH TNHH - CÔNG TY ĐIỆN LỰC VŨNG TÀU | X10: =SUM(X1:X9) -> 1343488164238 | Y10: =SUM(Y1:Y9) -> 107480736306 | Z10: =SUM(Z1:Z9) -> 107480736306 | AA10: =SUM(AA1:AA9) -> 0
B11: Mã số thuế : 0300951119-010 | X11: TAX36 | Y11: TAX36 | Z11: TA030
N12: Đơn vị tính: đồng Việt Nam | V12: ĐẦU TƯ XÂY DỰNG | X12: trước thuế | Y12: tiền thuế
H13: =SUBTOTAL(9,H18:H505) -> 26769800 | J13: =SUBTOTAL(9,J18:J505) -> 1338490 | W13: SXKD | X13: =X10-X14 -> 1321171020806 | Y13: =Y10-Y14 -> 85163592874
A14: STT | B14: Hóa đơn chứng từ bán | E14: Tên người bán | F14: Mã số thuế người bán | G14: Mặt hàng | H14: Doanh số mua chưa có thuế | I14: Thuế suất (%) | J14: Thuế GTGT | K14: Ghi chú | L14: Nguồn chứng từ | M14: Số chứng từ | N14: Ngày lập chứng từ | O14: Thời hạn thanh toán trả chậm | P14: Số tiền đã thanh toán | Q14: Loại hình SXKD | R14: Người lập chứng từ | S14: Trạng thái | T14: test | U14: test | V14: TK thuế | W14: XDCB | X14: =SUMIF($Q:$Q,$V$12,$H:$H) -> 22317143432 | Y14: =SUMIF($Q:$Q,$V$12,$H:$H) -> 22317143432
B15: Ký hiệu hóa đơn | C15: Số hóa đơn | D15: Ngày, tháng, năm phát hành | T15: MST | U15: tiền | X15: =SUM(X13:X14) -> 1343488164238 | Y15: =SUM(Y13:Y14) -> 107480736306
A16: [1] | B16: [2] | C16: [3] | D16: [4] | E16: [5] | F16: [6] | G16: [7] | H16: [8] | I16: [9] | J16: [10] | K16: [11] | L16: [12] | M16: [13] | N16: [14] | O16: [15] | P16: [16] | Q16: [17] | R16: [18] | S16: [19] | U16: thuế
A17: 1. Hàng hóa, dịch vụ dùng riêng cho SXKD chịu thuế GTGT đủ điều kiện được khấu trừ
A18: 1 | B18: 1K26TYY | C18: '23620037 | D18: 46146 | E18: Ngân Hàng TMCP Á Châu | F18: '0301452948 | G18: Phí dịch vụ ngân hàng | H18: 27273 | I18: 10 | J18: 2727 | L18: GL | M18: '1359 | N18: 46173 | O18: 46173 | P18: 30000 | Q18: ĐẦU TƯ XÂY DỰNG | R18: LINH3NTT.HCM.VTA | S18: Not Reversed | T18: =IF(OR(LEN(F18)=11,LEN(F18)=15),"Đ","SAI") -> Đ | U18: =ROUND(H18*I18%,0)-J18 -> 0 | V18: =IF(Q18=$V$12,13313,13311) -> 13313
A19: 2 | B19: 1K26TAA | C19: '00013830 | D19: 46150 | E19: Ngân Hàng TMCP Đầu Tư và Phát Triển Việt Nam -Chi nhánh Bà Rịa Vũng Tàu | F19: '0100150619-006 | G19: Dịch vụ ngân hàng | H19: 50000 | I19: 10 | J19: 5000 | L19: GL | M19: '1359 | N19: 46173 | O19: 46173 | P19: 55000 | Q19: ĐẦU TƯ XÂY DỰNG | R19: LINH3NTT.HCM.VTA | S19: Not Reversed | T19: =IF(OR(LEN(F19)=11,LEN(F19)=15),"Đ","SAI") -> Đ | U19: =ROUND(H19*I19%,0)-J19 -> 0 | V19: =IF(Q19=$V$12,13313,13311) -> 13313
A20: 3 | B20: 1K26TAA | C20: '00014137 | D20: 46156 | E20: Ngân Hàng TMCP Đầu Tư và Phát Triển Việt Nam -Chi nhánh Bà Rịa Vũng Tàu | F20: '0100150619-006 | G20: Dịch vụ ngân hàng | H20: 870075 | I20: 10 | J20: 87008 | L20: GL | M20: '1359 | N20: 46173 | O20: 46173 | P20: 957083 | Q20: ĐẦU TƯ XÂY DỰNG | R20: LINH3NTT.HCM.VTA | S20: Not Reversed | T20: =IF(OR(LEN(F20)=11,LEN(F20)=15),"Đ","SAI") -> Đ | U20: =ROUND(H20*I20%,0)-J20 -> 0 | V20: =IF(Q20=$V$12,13313,13311) -> 13313
A21: 4 | B21: 1K26TAA | C21: '00014549 | D21: 46164 | E21: Ngân Hàng TMCP Đầu Tư và Phát Triển Việt Nam -Chi nhánh Bà Rịa Vũng Tàu | F21: '0100150619-006 | G21: Dịch vụ ngân hàng | H21: 3146172 | I21: 10 | J21: 314617 | L21: GL | M21: '1359 | N21: 46173 | O21: 46173 | P21: 3460789 | Q21: ĐẦU TƯ XÂY DỰNG | R21: LINH3NTT.HCM.VTA | S21: Not Reversed | T21: =IF(OR(LEN(F21)=11,LEN(F21)=15),"Đ","SAI") -> Đ | U21: =ROUND(H21*I21%,0)-J21 -> 0 | V21: =IF(Q21=$V$12,13313,13311) -> 13313
A22: 5 | B22: 1K26TAA | C22: '00014765 | D22: 46168 | E22: Ngân Hàng TMCP Đầu Tư và Phát Triển Việt Nam -Chi nhánh Bà Rịa Vũng Tàu | F22: '0100150619-006 | G22: Dịch vụ ngân hàng | H22: 243805 | I22: 10 | J22: 24381 | L22: GL | M22: '1359 | N22: 46173 | O22: 46173 | P22: 268186 | Q22: ĐẦU TƯ XÂY DỰNG | R22: LINH3NTT.HCM.VTA | S22: Not Reversed | T22: =IF(OR(LEN(F22)=11,LEN(F22)=15),"Đ","SAI") -> Đ | U22: =ROUND(H22*I22%,0)-J22 -> 0 | V22: =IF(Q22=$V$12,13313,13311) -> 13313
A23: 6 | B23: 1K26TAA | C23: '00014855 | D23: 46170 | E23: Ngân Hàng TMCP Đầu Tư và Phát Triển Việt Nam -Chi nhánh Bà Rịa Vũng Tàu | F23: '0100150619-006 | G23: Dịch vụ ngân hàng | H23: 151244 | I23: 10 | J23: 15124 | L23: GL | M23: '1359 | N23: 46173 | O23: 46173 | P23: 166368 | Q23: ĐẦU TƯ XÂY DỰNG | R23: LINH3NTT.HCM.VTA | S23: Not Reversed | T23: =IF(OR(LEN(F23)=11,LEN(F23)=15),"Đ","SAI") -> Đ | U23: =ROUND(H23*I23%,0)-J23 -> 0 | V23: =IF(Q23=$V$12,13313,13311) -> 13313
